INFO:     Started server process [28595]
INFO:     Waiting for application startup.
INFO:     Application startup complete.
INFO:     Uvicorn running on http://0.0.0.0:8000 (Press CTRL+C to quit)
INFO:     127.0.0.1:52657 - "GET /health HTTP/1.1" 200 OK
INFO:     127.0.0.1:53549 - "GET / HTTP/1.1" 200 OK
INFO:     127.0.0.1:53551 - "GET /api/patients/ HTTP/1.1" 403 Forbidden
INFO:     127.0.0.1:53554 - "GET /api/analytics/ HTTP/1.1" 404 Not Found
INFO:     127.0.0.1:53600 - "GET /docs HTTP/1.1" 200 OK
INFO:     127.0.0.1:53750 - "OPTIONS /api/auth/login?username=demo_doctor&password=demo123 HTTP/1.1" 200 OK
(trapped) error reading bcrypt version
Traceback (most recent call last):
  File "/Users/sathishkesavan/Hackwell_AI/backend/venv/lib/python3.12/site-packages/passlib/handlers/bcrypt.py", line 620, in _load_backend_mixin
    version = _bcrypt.__about__.__version__
              ^^^^^^^^^^^^^^^^^
AttributeError: module 'bcrypt' has no attribute '__about__'
INFO:     127.0.0.1:53750 - "POST /api/auth/login?username=demo_doctor&password=demo123 HTTP/1.1" 200 OK
INFO:     127.0.0.1:53750 - "OPTIONS /api/analytics/overview HTTP/1.1" 200 OK
INFO:     127.0.0.1:53758 - "OPTIONS /api/patients?skip=0&limit=4 HTTP/1.1" 200 OK
INFO:     127.0.0.1:53759 - "OPTIONS /api/analytics/overview HTTP/1.1" 200 OK
INFO:     127.0.0.1:53760 - "OPTIONS /api/patients?skip=0&limit=4 HTTP/1.1" 200 OK
INFO:     127.0.0.1:53759 - "GET /api/patients?skip=0&limit=4 HTTP/1.1" 307 Temporary Redirect
INFO:     127.0.0.1:53760 - "GET /api/patients?skip=0&limit=4 HTTP/1.1" 307 Temporary Redirect
INFO:     127.0.0.1:53759 - "OPTIONS /api/patients/?skip=0&limit=4 HTTP/1.1" 200 OK
INFO:     127.0.0.1:53759 - "OPTIONS /api/patients/?skip=0&limit=4 HTTP/1.1" 200 OK
INFO:     127.0.0.1:53760 - "GET /api/patients/?skip=0&limit=4 HTTP/1.1" 500 Internal Server Error
ERROR:    Exception in ASGI application
Traceback (most recent call last):
  File "/Users/sathishkesavan/Hackwell_AI/backend/venv/lib/python3.12/site-packages/uvicorn/protocols/http/h11_impl.py", line 403, in run_asgi
    result = await app(  # type: ignore[func-returns-value]
             ^^^^^^^^^^^^^^^^^^^^^^^^^^^^^^^^^^^^^^^^^^^^^^
  File "/Users/sathishkesavan/Hackwell_AI/backend/venv/lib/python3.12/site-packages/uvicorn/middleware/proxy_headers.py", line 60, in __call__
    return await self.app(scope, receive, send)
           ^^^^^^^^^^^^^^^^^^^^^^^^^^^^^^^^^^^^
  File "/Users/sathishkesavan/Hackwell_AI/backend/venv/lib/python3.12/site-packages/fastapi/applications.py", line 1054, in __call__
    await super().__call__(scope, receive, send)
  File "/Users/sathishkesavan/Hackwell_AI/backend/venv/lib/python3.12/site-packages/starlette/applications.py", line 113, in __call__
    await self.middleware_stack(scope, receive, send)
  File "/Users/sathishkesavan/Hackwell_AI/backend/venv/lib/python3.12/site-packages/starlette/middleware/errors.py", line 186, in __call__
    raise exc
  File "/Users/sathishkesavan/Hackwell_AI/backend/venv/lib/python3.12/site-packages/starlette/middleware/errors.py", line 164, in __call__
    await self.app(scope, receive, _send)
  File "/Users/sathishkesavan/Hackwell_AI/backend/venv/lib/python3.12/site-packages/starlette/middleware/cors.py", line 93, in __call__
    await self.simple_response(scope, receive, send, request_headers=headers)
  File "/Users/sathishkesavan/Hackwell_AI/backend/venv/lib/python3.12/site-packages/starlette/middleware/cors.py", line 144, in simple_response
    await self.app(scope, receive, send)
  File "/Users/sathishkesavan/Hackwell_AI/backend/venv/lib/python3.12/site-packages/starlette/middleware/exceptions.py", line 63, in __call__
    await wrap_app_handling_exceptions(self.app, conn)(scope, receive, send)
  File "/Users/sathishkesavan/Hackwell_AI/backend/venv/lib/python3.12/site-packages/starlette/_exception_handler.py", line 53, in wrapped_app
    raise exc
  File "/Users/sathishkesavan/Hackwell_AI/backend/venv/lib/python3.12/site-packages/starlette/_exception_handler.py", line 42, in wrapped_app
    await app(scope, receive, sender)
  File "/Users/sathishkesavan/Hackwell_AI/backend/venv/lib/python3.12/site-packages/starlette/routing.py", line 716, in __call__
    await self.middleware_stack(scope, receive, send)
  File "/Users/sathishkesavan/Hackwell_AI/backend/venv/lib/python3.12/site-packages/starlette/routing.py", line 736, in app
    await route.handle(scope, receive, send)
  File "/Users/sathishkesavan/Hackwell_AI/backend/venv/lib/python3.12/site-packages/starlette/routing.py", line 290, in handle
    await self.app(scope, receive, send)
  File "/Users/sathishkesavan/Hackwell_AI/backend/venv/lib/python3.12/site-packages/starlette/routing.py", line 78, in app
    await wrap_app_handling_exceptions(app, request)(scope, receive, send)
  File "/Users/sathishkesavan/Hackwell_AI/backend/venv/lib/python3.12/site-packages/starlette/_exception_handler.py", line 53, in wrapped_app
    raise exc
  File "/Users/sathishkesavan/Hackwell_AI/backend/venv/lib/python3.12/site-packages/starlette/_exception_handler.py", line 42, in wrapped_app
    await app(scope, receive, sender)
  File "/Users/sathishkesavan/Hackwell_AI/backend/venv/lib/python3.12/site-packages/starlette/routing.py", line 75, in app
    response = await f(request)
               ^^^^^^^^^^^^^^^^
  File "/Users/sathishkesavan/Hackwell_AI/backend/venv/lib/python3.12/site-packages/fastapi/routing.py", line 328, in app
    content = await serialize_response(
              ^^^^^^^^^^^^^^^^^^^^^^^^^
  File "/Users/sathishkesavan/Hackwell_AI/backend/venv/lib/python3.12/site-packages/fastapi/routing.py", line 177, in serialize_response
    raise ResponseValidationError(
fastapi.exceptions.ResponseValidationError: 1 validation errors:
  {'type': 'string_type', 'loc': ('response', 3, 'date_of_birth'), 'msg': 'Input should be a valid string', 'input': None}

INFO:     127.0.0.1:53750 - "GET /api/analytics/overview HTTP/1.1" 200 OK
INFO:     127.0.0.1:53759 - "GET /api/patients/?skip=0&limit=4 HTTP/1.1" 500 Internal Server Error
ERROR:    Exception in ASGI application
Traceback (most recent call last):
  File "/Users/sathishkesavan/Hackwell_AI/backend/venv/lib/python3.12/site-packages/uvicorn/protocols/http/h11_impl.py", line 403, in run_asgi
    result = await app(  # type: ignore[func-returns-value]
             ^^^^^^^^^^^^^^^^^^^^^^^^^^^^^^^^^^^^^^^^^^^^^^
  File "/Users/sathishkesavan/Hackwell_AI/backend/venv/lib/python3.12/site-packages/uvicorn/middleware/proxy_headers.py", line 60, in __call__
    return await self.app(scope, receive, send)
           ^^^^^^^^^^^^^^^^^^^^^^^^^^^^^^^^^^^^
  File "/Users/sathishkesavan/Hackwell_AI/backend/venv/lib/python3.12/site-packages/fastapi/applications.py", line 1054, in __call__
    await super().__call__(scope, receive, send)
  File "/Users/sathishkesavan/Hackwell_AI/backend/venv/lib/python3.12/site-packages/starlette/applications.py", line 113, in __call__
    await self.middleware_stack(scope, receive, send)
  File "/Users/sathishkesavan/Hackwell_AI/backend/venv/lib/python3.12/site-packages/starlette/middleware/errors.py", line 186, in __call__
    raise exc
  File "/Users/sathishkesavan/Hackwell_AI/backend/venv/lib/python3.12/site-packages/starlette/middleware/errors.py", line 164, in __call__
    await self.app(scope, receive, _send)
  File "/Users/sathishkesavan/Hackwell_AI/backend/venv/lib/python3.12/site-packages/starlette/middleware/cors.py", line 93, in __call__
    await self.simple_response(scope, receive, send, request_headers=headers)
  File "/Users/sathishkesavan/Hackwell_AI/backend/venv/lib/python3.12/site-packages/starlette/middleware/cors.py", line 144, in simple_response
    await self.app(scope, receive, send)
  File "/Users/sathishkesavan/Hackwell_AI/backend/venv/lib/python3.12/site-packages/starlette/middleware/exceptions.py", line 63, in __call__
    await wrap_app_handling_exceptions(self.app, conn)(scope, receive, send)
  File "/Users/sathishkesavan/Hackwell_AI/backend/venv/lib/python3.12/site-packages/starlette/_exception_handler.py", line 53, in wrapped_app
    raise exc
  File "/Users/sathishkesavan/Hackwell_AI/backend/venv/lib/python3.12/site-packages/starlette/_exception_handler.py", line 42, in wrapped_app
    await app(scope, receive, sender)
  File "/Users/sathishkesavan/Hackwell_AI/backend/venv/lib/python3.12/site-packages/starlette/routing.py", line 716, in __call__
    await self.middleware_stack(scope, receive, send)
  File "/Users/sathishkesavan/Hackwell_AI/backend/venv/lib/python3.12/site-packages/starlette/routing.py", line 736, in app
    await route.handle(scope, receive, send)
  File "/Users/sathishkesavan/Hackwell_AI/backend/venv/lib/python3.12/site-packages/starlette/routing.py", line 290, in handle
    await self.app(scope, receive, send)
  File "/Users/sathishkesavan/Hackwell_AI/backend/venv/lib/python3.12/site-packages/starlette/routing.py", line 78, in app
    await wrap_app_handling_exceptions(app, request)(scope, receive, send)
  File "/Users/sathishkesavan/Hackwell_AI/backend/venv/lib/python3.12/site-packages/starlette/_exception_handler.py", line 53, in wrapped_app
    raise exc
  File "/Users/sathishkesavan/Hackwell_AI/backend/venv/lib/python3.12/site-packages/starlette/_exception_handler.py", line 42, in wrapped_app
    await app(scope, receive, sender)
  File "/Users/sathishkesavan/Hackwell_AI/backend/venv/lib/python3.12/site-packages/starlette/routing.py", line 75, in app
    response = await f(request)
               ^^^^^^^^^^^^^^^^
  File "/Users/sathishkesavan/Hackwell_AI/backend/venv/lib/python3.12/site-packages/fastapi/routing.py", line 328, in app
    content = await serialize_response(
              ^^^^^^^^^^^^^^^^^^^^^^^^^
  File "/Users/sathishkesavan/Hackwell_AI/backend/venv/lib/python3.12/site-packages/fastapi/routing.py", line 177, in serialize_response
    raise ResponseValidationError(
fastapi.exceptions.ResponseValidationError: 1 validation errors:
  {'type': 'string_type', 'loc': ('response', 3, 'date_of_birth'), 'msg': 'Input should be a valid string', 'input': None}

INFO:     127.0.0.1:53758 - "GET /api/analytics/overview HTTP/1.1" 200 OK
INFO:     127.0.0.1:53750 - "GET /api/patients/?skip=0&limit=4 HTTP/1.1" 500 Internal Server Error
ERROR:    Exception in ASGI application
Traceback (most recent call last):
  File "/Users/sathishkesavan/Hackwell_AI/backend/venv/lib/python3.12/site-packages/uvicorn/protocols/http/h11_impl.py", line 403, in run_asgi
    result = await app(  # type: ignore[func-returns-value]
             ^^^^^^^^^^^^^^^^^^^^^^^^^^^^^^^^^^^^^^^^^^^^^^
  File "/Users/sathishkesavan/Hackwell_AI/backend/venv/lib/python3.12/site-packages/uvicorn/middleware/proxy_headers.py", line 60, in __call__
    return await self.app(scope, receive, send)
           ^^^^^^^^^^^^^^^^^^^^^^^^^^^^^^^^^^^^
  File "/Users/sathishkesavan/Hackwell_AI/backend/venv/lib/python3.12/site-packages/fastapi/applications.py", line 1054, in __call__
    await super().__call__(scope, receive, send)
  File "/Users/sathishkesavan/Hackwell_AI/backend/venv/lib/python3.12/site-packages/starlette/applications.py", line 113, in __call__
    await self.middleware_stack(scope, receive, send)
  File "/Users/sathishkesavan/Hackwell_AI/backend/venv/lib/python3.12/site-packages/starlette/middleware/errors.py", line 186, in __call__
    raise exc
  File "/Users/sathishkesavan/Hackwell_AI/backend/venv/lib/python3.12/site-packages/starlette/middleware/errors.py", line 164, in __call__
    await self.app(scope, receive, _send)
  File "/Users/sathishkesavan/Hackwell_AI/backend/venv/lib/python3.12/site-packages/starlette/middleware/cors.py", line 93, in __call__
    await self.simple_response(scope, receive, send, request_headers=headers)
  File "/Users/sathishkesavan/Hackwell_AI/backend/venv/lib/python3.12/site-packages/starlette/middleware/cors.py", line 144, in simple_response
    await self.app(scope, receive, send)
  File "/Users/sathishkesavan/Hackwell_AI/backend/venv/lib/python3.12/site-packages/starlette/middleware/exceptions.py", line 63, in __call__
    await wrap_app_handling_exceptions(self.app, conn)(scope, receive, send)
  File "/Users/sathishkesavan/Hackwell_AI/backend/venv/lib/python3.12/site-packages/starlette/_exception_handler.py", line 53, in wrapped_app
    raise exc
  File "/Users/sathishkesavan/Hackwell_AI/backend/venv/lib/python3.12/site-packages/starlette/_exception_handler.py", line 42, in wrapped_app
    await app(scope, receive, sender)
  File "/Users/sathishkesavan/Hackwell_AI/backend/venv/lib/python3.12/site-packages/starlette/routing.py", line 716, in __call__
    await self.middleware_stack(scope, receive, send)
  File "/Users/sathishkesavan/Hackwell_AI/backend/venv/lib/python3.12/site-packages/starlette/routing.py", line 736, in app
    await route.handle(scope, receive, send)
  File "/Users/sathishkesavan/Hackwell_AI/backend/venv/lib/python3.12/site-packages/starlette/routing.py", line 290, in handle
    await self.app(scope, receive, send)
  File "/Users/sathishkesavan/Hackwell_AI/backend/venv/lib/python3.12/site-packages/starlette/routing.py", line 78, in app
    await wrap_app_handling_exceptions(app, request)(scope, receive, send)
  File "/Users/sathishkesavan/Hackwell_AI/backend/venv/lib/python3.12/site-packages/starlette/_exception_handler.py", line 53, in wrapped_app
    raise exc
  File "/Users/sathishkesavan/Hackwell_AI/backend/venv/lib/python3.12/site-packages/starlette/_exception_handler.py", line 42, in wrapped_app
    await app(scope, receive, sender)
  File "/Users/sathishkesavan/Hackwell_AI/backend/venv/lib/python3.12/site-packages/starlette/routing.py", line 75, in app
    response = await f(request)
               ^^^^^^^^^^^^^^^^
  File "/Users/sathishkesavan/Hackwell_AI/backend/venv/lib/python3.12/site-packages/fastapi/routing.py", line 328, in app
    content = await serialize_response(
              ^^^^^^^^^^^^^^^^^^^^^^^^^
  File "/Users/sathishkesavan/Hackwell_AI/backend/venv/lib/python3.12/site-packages/fastapi/routing.py", line 177, in serialize_response
    raise ResponseValidationError(
fastapi.exceptions.ResponseValidationError: 1 validation errors:
  {'type': 'string_type', 'loc': ('response', 3, 'date_of_birth'), 'msg': 'Input should be a valid string', 'input': None}

INFO:     127.0.0.1:53775 - "GET /api/patients?skip=0&limit=4 HTTP/1.1" 307 Temporary Redirect
INFO:     127.0.0.1:53774 - "GET /api/analytics/overview HTTP/1.1" 200 OK
INFO:     127.0.0.1:53775 - "GET /api/patients?skip=0&limit=4 HTTP/1.1" 307 Temporary Redirect
INFO:     127.0.0.1:53777 - "GET /api/patients/?skip=0&limit=4 HTTP/1.1" 500 Internal Server Error
ERROR:    Exception in ASGI application
Traceback (most recent call last):
  File "/Users/sathishkesavan/Hackwell_AI/backend/venv/lib/python3.12/site-packages/uvicorn/protocols/http/h11_impl.py", line 403, in run_asgi
    result = await app(  # type: ignore[func-returns-value]
             ^^^^^^^^^^^^^^^^^^^^^^^^^^^^^^^^^^^^^^^^^^^^^^
  File "/Users/sathishkesavan/Hackwell_AI/backend/venv/lib/python3.12/site-packages/uvicorn/middleware/proxy_headers.py", line 60, in __call__
    return await self.app(scope, receive, send)
           ^^^^^^^^^^^^^^^^^^^^^^^^^^^^^^^^^^^^
  File "/Users/sathishkesavan/Hackwell_AI/backend/venv/lib/python3.12/site-packages/fastapi/applications.py", line 1054, in __call__
    await super().__call__(scope, receive, send)
  File "/Users/sathishkesavan/Hackwell_AI/backend/venv/lib/python3.12/site-packages/starlette/applications.py", line 113, in __call__
    await self.middleware_stack(scope, receive, send)
  File "/Users/sathishkesavan/Hackwell_AI/backend/venv/lib/python3.12/site-packages/starlette/middleware/errors.py", line 186, in __call__
    raise exc
  File "/Users/sathishkesavan/Hackwell_AI/backend/venv/lib/python3.12/site-packages/starlette/middleware/errors.py", line 164, in __call__
    await self.app(scope, receive, _send)
  File "/Users/sathishkesavan/Hackwell_AI/backend/venv/lib/python3.12/site-packages/starlette/middleware/cors.py", line 93, in __call__
    await self.simple_response(scope, receive, send, request_headers=headers)
  File "/Users/sathishkesavan/Hackwell_AI/backend/venv/lib/python3.12/site-packages/starlette/middleware/cors.py", line 144, in simple_response
    await self.app(scope, receive, send)
  File "/Users/sathishkesavan/Hackwell_AI/backend/venv/lib/python3.12/site-packages/starlette/middleware/exceptions.py", line 63, in __call__
    await wrap_app_handling_exceptions(self.app, conn)(scope, receive, send)
  File "/Users/sathishkesavan/Hackwell_AI/backend/venv/lib/python3.12/site-packages/starlette/_exception_handler.py", line 53, in wrapped_app
    raise exc
  File "/Users/sathishkesavan/Hackwell_AI/backend/venv/lib/python3.12/site-packages/starlette/_exception_handler.py", line 42, in wrapped_app
    await app(scope, receive, sender)
  File "/Users/sathishkesavan/Hackwell_AI/backend/venv/lib/python3.12/site-packages/starlette/routing.py", line 716, in __call__
    await self.middleware_stack(scope, receive, send)
  File "/Users/sathishkesavan/Hackwell_AI/backend/venv/lib/python3.12/site-packages/starlette/routing.py", line 736, in app
    await route.handle(scope, receive, send)
  File "/Users/sathishkesavan/Hackwell_AI/backend/venv/lib/python3.12/site-packages/starlette/routing.py", line 290, in handle
    await self.app(scope, receive, send)
  File "/Users/sathishkesavan/Hackwell_AI/backend/venv/lib/python3.12/site-packages/starlette/routing.py", line 78, in app
    await wrap_app_handling_exceptions(app, request)(scope, receive, send)
  File "/Users/sathishkesavan/Hackwell_AI/backend/venv/lib/python3.12/site-packages/starlette/_exception_handler.py", line 53, in wrapped_app
    raise exc
  File "/Users/sathishkesavan/Hackwell_AI/backend/venv/lib/python3.12/site-packages/starlette/_exception_handler.py", line 42, in wrapped_app
    await app(scope, receive, sender)
  File "/Users/sathishkesavan/Hackwell_AI/backend/venv/lib/python3.12/site-packages/starlette/routing.py", line 75, in app
    response = await f(request)
               ^^^^^^^^^^^^^^^^
  File "/Users/sathishkesavan/Hackwell_AI/backend/venv/lib/python3.12/site-packages/fastapi/routing.py", line 328, in app
    content = await serialize_response(
              ^^^^^^^^^^^^^^^^^^^^^^^^^
  File "/Users/sathishkesavan/Hackwell_AI/backend/venv/lib/python3.12/site-packages/fastapi/routing.py", line 177, in serialize_response
    raise ResponseValidationError(
fastapi.exceptions.ResponseValidationError: 1 validation errors:
  {'type': 'string_type', 'loc': ('response', 3, 'date_of_birth'), 'msg': 'Input should be a valid string', 'input': None}

INFO:     127.0.0.1:53775 - "GET /api/patients/?skip=0&limit=4 HTTP/1.1" 500 Internal Server Error
ERROR:    Exception in ASGI application
Traceback (most recent call last):
  File "/Users/sathishkesavan/Hackwell_AI/backend/venv/lib/python3.12/site-packages/uvicorn/protocols/http/h11_impl.py", line 403, in run_asgi
    result = await app(  # type: ignore[func-returns-value]
             ^^^^^^^^^^^^^^^^^^^^^^^^^^^^^^^^^^^^^^^^^^^^^^
  File "/Users/sathishkesavan/Hackwell_AI/backend/venv/lib/python3.12/site-packages/uvicorn/middleware/proxy_headers.py", line 60, in __call__
    return await self.app(scope, receive, send)
           ^^^^^^^^^^^^^^^^^^^^^^^^^^^^^^^^^^^^
  File "/Users/sathishkesavan/Hackwell_AI/backend/venv/lib/python3.12/site-packages/fastapi/applications.py", line 1054, in __call__
    await super().__call__(scope, receive, send)
  File "/Users/sathishkesavan/Hackwell_AI/backend/venv/lib/python3.12/site-packages/starlette/applications.py", line 113, in __call__
    await self.middleware_stack(scope, receive, send)
  File "/Users/sathishkesavan/Hackwell_AI/backend/venv/lib/python3.12/site-packages/starlette/middleware/errors.py", line 186, in __call__
    raise exc
  File "/Users/sathishkesavan/Hackwell_AI/backend/venv/lib/python3.12/site-packages/starlette/middleware/errors.py", line 164, in __call__
    await self.app(scope, receive, _send)
  File "/Users/sathishkesavan/Hackwell_AI/backend/venv/lib/python3.12/site-packages/starlette/middleware/cors.py", line 93, in __call__
    await self.simple_response(scope, receive, send, request_headers=headers)
  File "/Users/sathishkesavan/Hackwell_AI/backend/venv/lib/python3.12/site-packages/starlette/middleware/cors.py", line 144, in simple_response
    await self.app(scope, receive, send)
  File "/Users/sathishkesavan/Hackwell_AI/backend/venv/lib/python3.12/site-packages/starlette/middleware/exceptions.py", line 63, in __call__
    await wrap_app_handling_exceptions(self.app, conn)(scope, receive, send)
  File "/Users/sathishkesavan/Hackwell_AI/backend/venv/lib/python3.12/site-packages/starlette/_exception_handler.py", line 53, in wrapped_app
    raise exc
  File "/Users/sathishkesavan/Hackwell_AI/backend/venv/lib/python3.12/site-packages/starlette/_exception_handler.py", line 42, in wrapped_app
    await app(scope, receive, sender)
  File "/Users/sathishkesavan/Hackwell_AI/backend/venv/lib/python3.12/site-packages/starlette/routing.py", line 716, in __call__
    await self.middleware_stack(scope, receive, send)
  File "/Users/sathishkesavan/Hackwell_AI/backend/venv/lib/python3.12/site-packages/starlette/routing.py", line 736, in app
    await route.handle(scope, receive, send)
  File "/Users/sathishkesavan/Hackwell_AI/backend/venv/lib/python3.12/site-packages/starlette/routing.py", line 290, in handle
    await self.app(scope, receive, send)
  File "/Users/sathishkesavan/Hackwell_AI/backend/venv/lib/python3.12/site-packages/starlette/routing.py", line 78, in app
    await wrap_app_handling_exceptions(app, request)(scope, receive, send)
  File "/Users/sathishkesavan/Hackwell_AI/backend/venv/lib/python3.12/site-packages/starlette/_exception_handler.py", line 53, in wrapped_app
    raise exc
  File "/Users/sathishkesavan/Hackwell_AI/backend/venv/lib/python3.12/site-packages/starlette/_exception_handler.py", line 42, in wrapped_app
    await app(scope, receive, sender)
  File "/Users/sathishkesavan/Hackwell_AI/backend/venv/lib/python3.12/site-packages/starlette/routing.py", line 75, in app
    response = await f(request)
               ^^^^^^^^^^^^^^^^
  File "/Users/sathishkesavan/Hackwell_AI/backend/venv/lib/python3.12/site-packages/fastapi/routing.py", line 328, in app
    content = await serialize_response(
              ^^^^^^^^^^^^^^^^^^^^^^^^^
  File "/Users/sathishkesavan/Hackwell_AI/backend/venv/lib/python3.12/site-packages/fastapi/routing.py", line 177, in serialize_response
    raise ResponseValidationError(
fastapi.exceptions.ResponseValidationError: 1 validation errors:
  {'type': 'string_type', 'loc': ('response', 3, 'date_of_birth'), 'msg': 'Input should be a valid string', 'input': None}

INFO:     127.0.0.1:53774 - "GET /api/analytics/overview HTTP/1.1" 200 OK
INFO:     127.0.0.1:53779 - "GET /api/patients/?skip=0&limit=4 HTTP/1.1" 500 Internal Server Error
ERROR:    Exception in ASGI application
Traceback (most recent call last):
  File "/Users/sathishkesavan/Hackwell_AI/backend/venv/lib/python3.12/site-packages/uvicorn/protocols/http/h11_impl.py", line 403, in run_asgi
    result = await app(  # type: ignore[func-returns-value]
             ^^^^^^^^^^^^^^^^^^^^^^^^^^^^^^^^^^^^^^^^^^^^^^
  File "/Users/sathishkesavan/Hackwell_AI/backend/venv/lib/python3.12/site-packages/uvicorn/middleware/proxy_headers.py", line 60, in __call__
    return await self.app(scope, receive, send)
           ^^^^^^^^^^^^^^^^^^^^^^^^^^^^^^^^^^^^
  File "/Users/sathishkesavan/Hackwell_AI/backend/venv/lib/python3.12/site-packages/fastapi/applications.py", line 1054, in __call__
    await super().__call__(scope, receive, send)
  File "/Users/sathishkesavan/Hackwell_AI/backend/venv/lib/python3.12/site-packages/starlette/applications.py", line 113, in __call__
    await self.middleware_stack(scope, receive, send)
  File "/Users/sathishkesavan/Hackwell_AI/backend/venv/lib/python3.12/site-packages/starlette/middleware/errors.py", line 186, in __call__
    raise exc
  File "/Users/sathishkesavan/Hackwell_AI/backend/venv/lib/python3.12/site-packages/starlette/middleware/errors.py", line 164, in __call__
    await self.app(scope, receive, _send)
  File "/Users/sathishkesavan/Hackwell_AI/backend/venv/lib/python3.12/site-packages/starlette/middleware/cors.py", line 93, in __call__
    await self.simple_response(scope, receive, send, request_headers=headers)
  File "/Users/sathishkesavan/Hackwell_AI/backend/venv/lib/python3.12/site-packages/starlette/middleware/cors.py", line 144, in simple_response
    await self.app(scope, receive, send)
  File "/Users/sathishkesavan/Hackwell_AI/backend/venv/lib/python3.12/site-packages/starlette/middleware/exceptions.py", line 63, in __call__
    await wrap_app_handling_exceptions(self.app, conn)(scope, receive, send)
  File "/Users/sathishkesavan/Hackwell_AI/backend/venv/lib/python3.12/site-packages/starlette/_exception_handler.py", line 53, in wrapped_app
    raise exc
  File "/Users/sathishkesavan/Hackwell_AI/backend/venv/lib/python3.12/site-packages/starlette/_exception_handler.py", line 42, in wrapped_app
    await app(scope, receive, sender)
  File "/Users/sathishkesavan/Hackwell_AI/backend/venv/lib/python3.12/site-packages/starlette/routing.py", line 716, in __call__
    await self.middleware_stack(scope, receive, send)
  File "/Users/sathishkesavan/Hackwell_AI/backend/venv/lib/python3.12/site-packages/starlette/routing.py", line 736, in app
    await route.handle(scope, receive, send)
  File "/Users/sathishkesavan/Hackwell_AI/backend/venv/lib/python3.12/site-packages/starlette/routing.py", line 290, in handle
    await self.app(scope, receive, send)
  File "/Users/sathishkesavan/Hackwell_AI/backend/venv/lib/python3.12/site-packages/starlette/routing.py", line 78, in app
    await wrap_app_handling_exceptions(app, request)(scope, receive, send)
  File "/Users/sathishkesavan/Hackwell_AI/backend/venv/lib/python3.12/site-packages/starlette/_exception_handler.py", line 53, in wrapped_app
    raise exc
  File "/Users/sathishkesavan/Hackwell_AI/backend/venv/lib/python3.12/site-packages/starlette/_exception_handler.py", line 42, in wrapped_app
    await app(scope, receive, sender)
  File "/Users/sathishkesavan/Hackwell_AI/backend/venv/lib/python3.12/site-packages/starlette/routing.py", line 75, in app
    response = await f(request)
               ^^^^^^^^^^^^^^^^
  File "/Users/sathishkesavan/Hackwell_AI/backend/venv/lib/python3.12/site-packages/fastapi/routing.py", line 328, in app
    content = await serialize_response(
              ^^^^^^^^^^^^^^^^^^^^^^^^^
  File "/Users/sathishkesavan/Hackwell_AI/backend/venv/lib/python3.12/site-packages/fastapi/routing.py", line 177, in serialize_response
    raise ResponseValidationError(
fastapi.exceptions.ResponseValidationError: 1 validation errors:
  {'type': 'string_type', 'loc': ('response', 3, 'date_of_birth'), 'msg': 'Input should be a valid string', 'input': None}

INFO:     127.0.0.1:53774 - "OPTIONS /api/patients?skip=0&limit=100 HTTP/1.1" 200 OK
INFO:     127.0.0.1:53781 - "OPTIONS /api/patients?skip=0&limit=100 HTTP/1.1" 200 OK
INFO:     127.0.0.1:53774 - "GET /api/patients?skip=0&limit=100 HTTP/1.1" 307 Temporary Redirect
INFO:     127.0.0.1:53781 - "GET /api/patients?skip=0&limit=100 HTTP/1.1" 307 Temporary Redirect
INFO:     127.0.0.1:53774 - "OPTIONS /api/patients/?skip=0&limit=100 HTTP/1.1" 200 OK
INFO:     127.0.0.1:53781 - "OPTIONS /api/patients/?skip=0&limit=100 HTTP/1.1" 200 OK
INFO:     127.0.0.1:53774 - "GET /api/patients/?skip=0&limit=100 HTTP/1.1" 500 Internal Server Error
ERROR:    Exception in ASGI application
Traceback (most recent call last):
  File "/Users/sathishkesavan/Hackwell_AI/backend/venv/lib/python3.12/site-packages/uvicorn/protocols/http/h11_impl.py", line 403, in run_asgi
    result = await app(  # type: ignore[func-returns-value]
             ^^^^^^^^^^^^^^^^^^^^^^^^^^^^^^^^^^^^^^^^^^^^^^
  File "/Users/sathishkesavan/Hackwell_AI/backend/venv/lib/python3.12/site-packages/uvicorn/middleware/proxy_headers.py", line 60, in __call__
    return await self.app(scope, receive, send)
           ^^^^^^^^^^^^^^^^^^^^^^^^^^^^^^^^^^^^
  File "/Users/sathishkesavan/Hackwell_AI/backend/venv/lib/python3.12/site-packages/fastapi/applications.py", line 1054, in __call__
    await super().__call__(scope, receive, send)
  File "/Users/sathishkesavan/Hackwell_AI/backend/venv/lib/python3.12/site-packages/starlette/applications.py", line 113, in __call__
    await self.middleware_stack(scope, receive, send)
  File "/Users/sathishkesavan/Hackwell_AI/backend/venv/lib/python3.12/site-packages/starlette/middleware/errors.py", line 186, in __call__
    raise exc
  File "/Users/sathishkesavan/Hackwell_AI/backend/venv/lib/python3.12/site-packages/starlette/middleware/errors.py", line 164, in __call__
    await self.app(scope, receive, _send)
  File "/Users/sathishkesavan/Hackwell_AI/backend/venv/lib/python3.12/site-packages/starlette/middleware/cors.py", line 93, in __call__
    await self.simple_response(scope, receive, send, request_headers=headers)
  File "/Users/sathishkesavan/Hackwell_AI/backend/venv/lib/python3.12/site-packages/starlette/middleware/cors.py", line 144, in simple_response
    await self.app(scope, receive, send)
  File "/Users/sathishkesavan/Hackwell_AI/backend/venv/lib/python3.12/site-packages/starlette/middleware/exceptions.py", line 63, in __call__
    await wrap_app_handling_exceptions(self.app, conn)(scope, receive, send)
  File "/Users/sathishkesavan/Hackwell_AI/backend/venv/lib/python3.12/site-packages/starlette/_exception_handler.py", line 53, in wrapped_app
    raise exc
  File "/Users/sathishkesavan/Hackwell_AI/backend/venv/lib/python3.12/site-packages/starlette/_exception_handler.py", line 42, in wrapped_app
    await app(scope, receive, sender)
  File "/Users/sathishkesavan/Hackwell_AI/backend/venv/lib/python3.12/site-packages/starlette/routing.py", line 716, in __call__
    await self.middleware_stack(scope, receive, send)
  File "/Users/sathishkesavan/Hackwell_AI/backend/venv/lib/python3.12/site-packages/starlette/routing.py", line 736, in app
    await route.handle(scope, receive, send)
  File "/Users/sathishkesavan/Hackwell_AI/backend/venv/lib/python3.12/site-packages/starlette/routing.py", line 290, in handle
    await self.app(scope, receive, send)
  File "/Users/sathishkesavan/Hackwell_AI/backend/venv/lib/python3.12/site-packages/starlette/routing.py", line 78, in app
    await wrap_app_handling_exceptions(app, request)(scope, receive, send)
  File "/Users/sathishkesavan/Hackwell_AI/backend/venv/lib/python3.12/site-packages/starlette/_exception_handler.py", line 53, in wrapped_app
    raise exc
  File "/Users/sathishkesavan/Hackwell_AI/backend/venv/lib/python3.12/site-packages/starlette/_exception_handler.py", line 42, in wrapped_app
    await app(scope, receive, sender)
  File "/Users/sathishkesavan/Hackwell_AI/backend/venv/lib/python3.12/site-packages/starlette/routing.py", line 75, in app
    response = await f(request)
               ^^^^^^^^^^^^^^^^
  File "/Users/sathishkesavan/Hackwell_AI/backend/venv/lib/python3.12/site-packages/fastapi/routing.py", line 328, in app
    content = await serialize_response(
              ^^^^^^^^^^^^^^^^^^^^^^^^^
  File "/Users/sathishkesavan/Hackwell_AI/backend/venv/lib/python3.12/site-packages/fastapi/routing.py", line 177, in serialize_response
    raise ResponseValidationError(
fastapi.exceptions.ResponseValidationError: 1 validation errors:
  {'type': 'string_type', 'loc': ('response', 3, 'date_of_birth'), 'msg': 'Input should be a valid string', 'input': None}

INFO:     127.0.0.1:53781 - "GET /api/patients/?skip=0&limit=100 HTTP/1.1" 500 Internal Server Error
ERROR:    Exception in ASGI application
Traceback (most recent call last):
  File "/Users/sathishkesavan/Hackwell_AI/backend/venv/lib/python3.12/site-packages/uvicorn/protocols/http/h11_impl.py", line 403, in run_asgi
    result = await app(  # type: ignore[func-returns-value]
             ^^^^^^^^^^^^^^^^^^^^^^^^^^^^^^^^^^^^^^^^^^^^^^
  File "/Users/sathishkesavan/Hackwell_AI/backend/venv/lib/python3.12/site-packages/uvicorn/middleware/proxy_headers.py", line 60, in __call__
    return await self.app(scope, receive, send)
           ^^^^^^^^^^^^^^^^^^^^^^^^^^^^^^^^^^^^
  File "/Users/sathishkesavan/Hackwell_AI/backend/venv/lib/python3.12/site-packages/fastapi/applications.py", line 1054, in __call__
    await super().__call__(scope, receive, send)
  File "/Users/sathishkesavan/Hackwell_AI/backend/venv/lib/python3.12/site-packages/starlette/applications.py", line 113, in __call__
    await self.middleware_stack(scope, receive, send)
  File "/Users/sathishkesavan/Hackwell_AI/backend/venv/lib/python3.12/site-packages/starlette/middleware/errors.py", line 186, in __call__
    raise exc
  File "/Users/sathishkesavan/Hackwell_AI/backend/venv/lib/python3.12/site-packages/starlette/middleware/errors.py", line 164, in __call__
    await self.app(scope, receive, _send)
  File "/Users/sathishkesavan/Hackwell_AI/backend/venv/lib/python3.12/site-packages/starlette/middleware/cors.py", line 93, in __call__
    await self.simple_response(scope, receive, send, request_headers=headers)
  File "/Users/sathishkesavan/Hackwell_AI/backend/venv/lib/python3.12/site-packages/starlette/middleware/cors.py", line 144, in simple_response
    await self.app(scope, receive, send)
  File "/Users/sathishkesavan/Hackwell_AI/backend/venv/lib/python3.12/site-packages/starlette/middleware/exceptions.py", line 63, in __call__
    await wrap_app_handling_exceptions(self.app, conn)(scope, receive, send)
  File "/Users/sathishkesavan/Hackwell_AI/backend/venv/lib/python3.12/site-packages/starlette/_exception_handler.py", line 53, in wrapped_app
    raise exc
  File "/Users/sathishkesavan/Hackwell_AI/backend/venv/lib/python3.12/site-packages/starlette/_exception_handler.py", line 42, in wrapped_app
    await app(scope, receive, sender)
  File "/Users/sathishkesavan/Hackwell_AI/backend/venv/lib/python3.12/site-packages/starlette/routing.py", line 716, in __call__
    await self.middleware_stack(scope, receive, send)
  File "/Users/sathishkesavan/Hackwell_AI/backend/venv/lib/python3.12/site-packages/starlette/routing.py", line 736, in app
    await route.handle(scope, receive, send)
  File "/Users/sathishkesavan/Hackwell_AI/backend/venv/lib/python3.12/site-packages/starlette/routing.py", line 290, in handle
    await self.app(scope, receive, send)
  File "/Users/sathishkesavan/Hackwell_AI/backend/venv/lib/python3.12/site-packages/starlette/routing.py", line 78, in app
    await wrap_app_handling_exceptions(app, request)(scope, receive, send)
  File "/Users/sathishkesavan/Hackwell_AI/backend/venv/lib/python3.12/site-packages/starlette/_exception_handler.py", line 53, in wrapped_app
    raise exc
  File "/Users/sathishkesavan/Hackwell_AI/backend/venv/lib/python3.12/site-packages/starlette/_exception_handler.py", line 42, in wrapped_app
    await app(scope, receive, sender)
  File "/Users/sathishkesavan/Hackwell_AI/backend/venv/lib/python3.12/site-packages/starlette/routing.py", line 75, in app
    response = await f(request)
               ^^^^^^^^^^^^^^^^
  File "/Users/sathishkesavan/Hackwell_AI/backend/venv/lib/python3.12/site-packages/fastapi/routing.py", line 328, in app
    content = await serialize_response(
              ^^^^^^^^^^^^^^^^^^^^^^^^^
  File "/Users/sathishkesavan/Hackwell_AI/backend/venv/lib/python3.12/site-packages/fastapi/routing.py", line 177, in serialize_response
    raise ResponseValidationError(
fastapi.exceptions.ResponseValidationError: 1 validation errors:
  {'type': 'string_type', 'loc': ('response', 3, 'date_of_birth'), 'msg': 'Input should be a valid string', 'input': None}

INFO:     127.0.0.1:53783 - "GET /api/patients/?skip=0&limit=100 HTTP/1.1" 500 Internal Server Error
ERROR:    Exception in ASGI application
Traceback (most recent call last):
  File "/Users/sathishkesavan/Hackwell_AI/backend/venv/lib/python3.12/site-packages/uvicorn/protocols/http/h11_impl.py", line 403, in run_asgi
    result = await app(  # type: ignore[func-returns-value]
             ^^^^^^^^^^^^^^^^^^^^^^^^^^^^^^^^^^^^^^^^^^^^^^
  File "/Users/sathishkesavan/Hackwell_AI/backend/venv/lib/python3.12/site-packages/uvicorn/middleware/proxy_headers.py", line 60, in __call__
    return await self.app(scope, receive, send)
           ^^^^^^^^^^^^^^^^^^^^^^^^^^^^^^^^^^^^
  File "/Users/sathishkesavan/Hackwell_AI/backend/venv/lib/python3.12/site-packages/fastapi/applications.py", line 1054, in __call__
    await super().__call__(scope, receive, send)
  File "/Users/sathishkesavan/Hackwell_AI/backend/venv/lib/python3.12/site-packages/starlette/applications.py", line 113, in __call__
    await self.middleware_stack(scope, receive, send)
  File "/Users/sathishkesavan/Hackwell_AI/backend/venv/lib/python3.12/site-packages/starlette/middleware/errors.py", line 186, in __call__
    raise exc
  File "/Users/sathishkesavan/Hackwell_AI/backend/venv/lib/python3.12/site-packages/starlette/middleware/errors.py", line 164, in __call__
    await self.app(scope, receive, _send)
  File "/Users/sathishkesavan/Hackwell_AI/backend/venv/lib/python3.12/site-packages/starlette/middleware/cors.py", line 93, in __call__
    await self.simple_response(scope, receive, send, request_headers=headers)
  File "/Users/sathishkesavan/Hackwell_AI/backend/venv/lib/python3.12/site-packages/starlette/middleware/cors.py", line 144, in simple_response
    await self.app(scope, receive, send)
  File "/Users/sathishkesavan/Hackwell_AI/backend/venv/lib/python3.12/site-packages/starlette/middleware/exceptions.py", line 63, in __call__
    await wrap_app_handling_exceptions(self.app, conn)(scope, receive, send)
  File "/Users/sathishkesavan/Hackwell_AI/backend/venv/lib/python3.12/site-packages/starlette/_exception_handler.py", line 53, in wrapped_app
    raise exc
  File "/Users/sathishkesavan/Hackwell_AI/backend/venv/lib/python3.12/site-packages/starlette/_exception_handler.py", line 42, in wrapped_app
    await app(scope, receive, sender)
  File "/Users/sathishkesavan/Hackwell_AI/backend/venv/lib/python3.12/site-packages/starlette/routing.py", line 716, in __call__
    await self.middleware_stack(scope, receive, send)
  File "/Users/sathishkesavan/Hackwell_AI/backend/venv/lib/python3.12/site-packages/starlette/routing.py", line 736, in app
    await route.handle(scope, receive, send)
  File "/Users/sathishkesavan/Hackwell_AI/backend/venv/lib/python3.12/site-packages/starlette/routing.py", line 290, in handle
    await self.app(scope, receive, send)
  File "/Users/sathishkesavan/Hackwell_AI/backend/venv/lib/python3.12/site-packages/starlette/routing.py", line 78, in app
    await wrap_app_handling_exceptions(app, request)(scope, receive, send)
  File "/Users/sathishkesavan/Hackwell_AI/backend/venv/lib/python3.12/site-packages/starlette/_exception_handler.py", line 53, in wrapped_app
    raise exc
  File "/Users/sathishkesavan/Hackwell_AI/backend/venv/lib/python3.12/site-packages/starlette/_exception_handler.py", line 42, in wrapped_app
    await app(scope, receive, sender)
  File "/Users/sathishkesavan/Hackwell_AI/backend/venv/lib/python3.12/site-packages/starlette/routing.py", line 75, in app
    response = await f(request)
               ^^^^^^^^^^^^^^^^
  File "/Users/sathishkesavan/Hackwell_AI/backend/venv/lib/python3.12/site-packages/fastapi/routing.py", line 328, in app
    content = await serialize_response(
              ^^^^^^^^^^^^^^^^^^^^^^^^^
  File "/Users/sathishkesavan/Hackwell_AI/backend/venv/lib/python3.12/site-packages/fastapi/routing.py", line 177, in serialize_response
    raise ResponseValidationError(
fastapi.exceptions.ResponseValidationError: 1 validation errors:
  {'type': 'string_type', 'loc': ('response', 3, 'date_of_birth'), 'msg': 'Input should be a valid string', 'input': None}

INFO:     127.0.0.1:53815 - "GET /api/patients?skip=0&limit=4 HTTP/1.1" 307 Temporary Redirect
INFO:     127.0.0.1:53815 - "GET /api/patients?skip=0&limit=4 HTTP/1.1" 307 Temporary Redirect
INFO:     127.0.0.1:53817 - "GET /api/patients/?skip=0&limit=4 HTTP/1.1" 500 Internal Server Error
ERROR:    Exception in ASGI application
Traceback (most recent call last):
  File "/Users/sathishkesavan/Hackwell_AI/backend/venv/lib/python3.12/site-packages/uvicorn/protocols/http/h11_impl.py", line 403, in run_asgi
    result = await app(  # type: ignore[func-returns-value]
             ^^^^^^^^^^^^^^^^^^^^^^^^^^^^^^^^^^^^^^^^^^^^^^
  File "/Users/sathishkesavan/Hackwell_AI/backend/venv/lib/python3.12/site-packages/uvicorn/middleware/proxy_headers.py", line 60, in __call__
    return await self.app(scope, receive, send)
           ^^^^^^^^^^^^^^^^^^^^^^^^^^^^^^^^^^^^
  File "/Users/sathishkesavan/Hackwell_AI/backend/venv/lib/python3.12/site-packages/fastapi/applications.py", line 1054, in __call__
    await super().__call__(scope, receive, send)
  File "/Users/sathishkesavan/Hackwell_AI/backend/venv/lib/python3.12/site-packages/starlette/applications.py", line 113, in __call__
    await self.middleware_stack(scope, receive, send)
  File "/Users/sathishkesavan/Hackwell_AI/backend/venv/lib/python3.12/site-packages/starlette/middleware/errors.py", line 186, in __call__
    raise exc
  File "/Users/sathishkesavan/Hackwell_AI/backend/venv/lib/python3.12/site-packages/starlette/middleware/errors.py", line 164, in __call__
    await self.app(scope, receive, _send)
  File "/Users/sathishkesavan/Hackwell_AI/backend/venv/lib/python3.12/site-packages/starlette/middleware/cors.py", line 93, in __call__
    await self.simple_response(scope, receive, send, request_headers=headers)
  File "/Users/sathishkesavan/Hackwell_AI/backend/venv/lib/python3.12/site-packages/starlette/middleware/cors.py", line 144, in simple_response
    await self.app(scope, receive, send)
  File "/Users/sathishkesavan/Hackwell_AI/backend/venv/lib/python3.12/site-packages/starlette/middleware/exceptions.py", line 63, in __call__
    await wrap_app_handling_exceptions(self.app, conn)(scope, receive, send)
  File "/Users/sathishkesavan/Hackwell_AI/backend/venv/lib/python3.12/site-packages/starlette/_exception_handler.py", line 53, in wrapped_app
    raise exc
  File "/Users/sathishkesavan/Hackwell_AI/backend/venv/lib/python3.12/site-packages/starlette/_exception_handler.py", line 42, in wrapped_app
    await app(scope, receive, sender)
  File "/Users/sathishkesavan/Hackwell_AI/backend/venv/lib/python3.12/site-packages/starlette/routing.py", line 716, in __call__
    await self.middleware_stack(scope, receive, send)
  File "/Users/sathishkesavan/Hackwell_AI/backend/venv/lib/python3.12/site-packages/starlette/routing.py", line 736, in app
    await route.handle(scope, receive, send)
  File "/Users/sathishkesavan/Hackwell_AI/backend/venv/lib/python3.12/site-packages/starlette/routing.py", line 290, in handle
    await self.app(scope, receive, send)
  File "/Users/sathishkesavan/Hackwell_AI/backend/venv/lib/python3.12/site-packages/starlette/routing.py", line 78, in app
    await wrap_app_handling_exceptions(app, request)(scope, receive, send)
  File "/Users/sathishkesavan/Hackwell_AI/backend/venv/lib/python3.12/site-packages/starlette/_exception_handler.py", line 53, in wrapped_app
    raise exc
  File "/Users/sathishkesavan/Hackwell_AI/backend/venv/lib/python3.12/site-packages/starlette/_exception_handler.py", line 42, in wrapped_app
    await app(scope, receive, sender)
  File "/Users/sathishkesavan/Hackwell_AI/backend/venv/lib/python3.12/site-packages/starlette/routing.py", line 75, in app
    response = await f(request)
               ^^^^^^^^^^^^^^^^
  File "/Users/sathishkesavan/Hackwell_AI/backend/venv/lib/python3.12/site-packages/fastapi/routing.py", line 328, in app
    content = await serialize_response(
              ^^^^^^^^^^^^^^^^^^^^^^^^^
  File "/Users/sathishkesavan/Hackwell_AI/backend/venv/lib/python3.12/site-packages/fastapi/routing.py", line 177, in serialize_response
    raise ResponseValidationError(
fastapi.exceptions.ResponseValidationError: 1 validation errors:
  {'type': 'string_type', 'loc': ('response', 3, 'date_of_birth'), 'msg': 'Input should be a valid string', 'input': None}

INFO:     127.0.0.1:53813 - "GET /api/analytics/overview HTTP/1.1" 200 OK
INFO:     127.0.0.1:53815 - "GET /api/patients/?skip=0&limit=4 HTTP/1.1" 500 Internal Server Error
ERROR:    Exception in ASGI application
Traceback (most recent call last):
  File "/Users/sathishkesavan/Hackwell_AI/backend/venv/lib/python3.12/site-packages/uvicorn/protocols/http/h11_impl.py", line 403, in run_asgi
    result = await app(  # type: ignore[func-returns-value]
             ^^^^^^^^^^^^^^^^^^^^^^^^^^^^^^^^^^^^^^^^^^^^^^
  File "/Users/sathishkesavan/Hackwell_AI/backend/venv/lib/python3.12/site-packages/uvicorn/middleware/proxy_headers.py", line 60, in __call__
    return await self.app(scope, receive, send)
           ^^^^^^^^^^^^^^^^^^^^^^^^^^^^^^^^^^^^
  File "/Users/sathishkesavan/Hackwell_AI/backend/venv/lib/python3.12/site-packages/fastapi/applications.py", line 1054, in __call__
    await super().__call__(scope, receive, send)
  File "/Users/sathishkesavan/Hackwell_AI/backend/venv/lib/python3.12/site-packages/starlette/applications.py", line 113, in __call__
    await self.middleware_stack(scope, receive, send)
  File "/Users/sathishkesavan/Hackwell_AI/backend/venv/lib/python3.12/site-packages/starlette/middleware/errors.py", line 186, in __call__
    raise exc
  File "/Users/sathishkesavan/Hackwell_AI/backend/venv/lib/python3.12/site-packages/starlette/middleware/errors.py", line 164, in __call__
    await self.app(scope, receive, _send)
  File "/Users/sathishkesavan/Hackwell_AI/backend/venv/lib/python3.12/site-packages/starlette/middleware/cors.py", line 93, in __call__
    await self.simple_response(scope, receive, send, request_headers=headers)
  File "/Users/sathishkesavan/Hackwell_AI/backend/venv/lib/python3.12/site-packages/starlette/middleware/cors.py", line 144, in simple_response
    await self.app(scope, receive, send)
  File "/Users/sathishkesavan/Hackwell_AI/backend/venv/lib/python3.12/site-packages/starlette/middleware/exceptions.py", line 63, in __call__
    await wrap_app_handling_exceptions(self.app, conn)(scope, receive, send)
  File "/Users/sathishkesavan/Hackwell_AI/backend/venv/lib/python3.12/site-packages/starlette/_exception_handler.py", line 53, in wrapped_app
    raise exc
  File "/Users/sathishkesavan/Hackwell_AI/backend/venv/lib/python3.12/site-packages/starlette/_exception_handler.py", line 42, in wrapped_app
    await app(scope, receive, sender)
  File "/Users/sathishkesavan/Hackwell_AI/backend/venv/lib/python3.12/site-packages/starlette/routing.py", line 716, in __call__
    await self.middleware_stack(scope, receive, send)
  File "/Users/sathishkesavan/Hackwell_AI/backend/venv/lib/python3.12/site-packages/starlette/routing.py", line 736, in app
    await route.handle(scope, receive, send)
  File "/Users/sathishkesavan/Hackwell_AI/backend/venv/lib/python3.12/site-packages/starlette/routing.py", line 290, in handle
    await self.app(scope, receive, send)
  File "/Users/sathishkesavan/Hackwell_AI/backend/venv/lib/python3.12/site-packages/starlette/routing.py", line 78, in app
    await wrap_app_handling_exceptions(app, request)(scope, receive, send)
  File "/Users/sathishkesavan/Hackwell_AI/backend/venv/lib/python3.12/site-packages/starlette/_exception_handler.py", line 53, in wrapped_app
    raise exc
  File "/Users/sathishkesavan/Hackwell_AI/backend/venv/lib/python3.12/site-packages/starlette/_exception_handler.py", line 42, in wrapped_app
    await app(scope, receive, sender)
  File "/Users/sathishkesavan/Hackwell_AI/backend/venv/lib/python3.12/site-packages/starlette/routing.py", line 75, in app
    response = await f(request)
               ^^^^^^^^^^^^^^^^
  File "/Users/sathishkesavan/Hackwell_AI/backend/venv/lib/python3.12/site-packages/fastapi/routing.py", line 328, in app
    content = await serialize_response(
              ^^^^^^^^^^^^^^^^^^^^^^^^^
  File "/Users/sathishkesavan/Hackwell_AI/backend/venv/lib/python3.12/site-packages/fastapi/routing.py", line 177, in serialize_response
    raise ResponseValidationError(
fastapi.exceptions.ResponseValidationError: 1 validation errors:
  {'type': 'string_type', 'loc': ('response', 3, 'date_of_birth'), 'msg': 'Input should be a valid string', 'input': None}

INFO:     127.0.0.1:53813 - "GET /api/analytics/overview HTTP/1.1" 200 OK
INFO:     127.0.0.1:53819 - "GET /api/patients/?skip=0&limit=4 HTTP/1.1" 500 Internal Server Error
ERROR:    Exception in ASGI application
Traceback (most recent call last):
  File "/Users/sathishkesavan/Hackwell_AI/backend/venv/lib/python3.12/site-packages/uvicorn/protocols/http/h11_impl.py", line 403, in run_asgi
    result = await app(  # type: ignore[func-returns-value]
             ^^^^^^^^^^^^^^^^^^^^^^^^^^^^^^^^^^^^^^^^^^^^^^
  File "/Users/sathishkesavan/Hackwell_AI/backend/venv/lib/python3.12/site-packages/uvicorn/middleware/proxy_headers.py", line 60, in __call__
    return await self.app(scope, receive, send)
           ^^^^^^^^^^^^^^^^^^^^^^^^^^^^^^^^^^^^
  File "/Users/sathishkesavan/Hackwell_AI/backend/venv/lib/python3.12/site-packages/fastapi/applications.py", line 1054, in __call__
    await super().__call__(scope, receive, send)
  File "/Users/sathishkesavan/Hackwell_AI/backend/venv/lib/python3.12/site-packages/starlette/applications.py", line 113, in __call__
    await self.middleware_stack(scope, receive, send)
  File "/Users/sathishkesavan/Hackwell_AI/backend/venv/lib/python3.12/site-packages/starlette/middleware/errors.py", line 186, in __call__
    raise exc
  File "/Users/sathishkesavan/Hackwell_AI/backend/venv/lib/python3.12/site-packages/starlette/middleware/errors.py", line 164, in __call__
    await self.app(scope, receive, _send)
  File "/Users/sathishkesavan/Hackwell_AI/backend/venv/lib/python3.12/site-packages/starlette/middleware/cors.py", line 93, in __call__
    await self.simple_response(scope, receive, send, request_headers=headers)
  File "/Users/sathishkesavan/Hackwell_AI/backend/venv/lib/python3.12/site-packages/starlette/middleware/cors.py", line 144, in simple_response
    await self.app(scope, receive, send)
  File "/Users/sathishkesavan/Hackwell_AI/backend/venv/lib/python3.12/site-packages/starlette/middleware/exceptions.py", line 63, in __call__
    await wrap_app_handling_exceptions(self.app, conn)(scope, receive, send)
  File "/Users/sathishkesavan/Hackwell_AI/backend/venv/lib/python3.12/site-packages/starlette/_exception_handler.py", line 53, in wrapped_app
    raise exc
  File "/Users/sathishkesavan/Hackwell_AI/backend/venv/lib/python3.12/site-packages/starlette/_exception_handler.py", line 42, in wrapped_app
    await app(scope, receive, sender)
  File "/Users/sathishkesavan/Hackwell_AI/backend/venv/lib/python3.12/site-packages/starlette/routing.py", line 716, in __call__
    await self.middleware_stack(scope, receive, send)
  File "/Users/sathishkesavan/Hackwell_AI/backend/venv/lib/python3.12/site-packages/starlette/routing.py", line 736, in app
    await route.handle(scope, receive, send)
  File "/Users/sathishkesavan/Hackwell_AI/backend/venv/lib/python3.12/site-packages/starlette/routing.py", line 290, in handle
    await self.app(scope, receive, send)
  File "/Users/sathishkesavan/Hackwell_AI/backend/venv/lib/python3.12/site-packages/starlette/routing.py", line 78, in app
    await wrap_app_handling_exceptions(app, request)(scope, receive, send)
  File "/Users/sathishkesavan/Hackwell_AI/backend/venv/lib/python3.12/site-packages/starlette/_exception_handler.py", line 53, in wrapped_app
    raise exc
  File "/Users/sathishkesavan/Hackwell_AI/backend/venv/lib/python3.12/site-packages/starlette/_exception_handler.py", line 42, in wrapped_app
    await app(scope, receive, sender)
  File "/Users/sathishkesavan/Hackwell_AI/backend/venv/lib/python3.12/site-packages/starlette/routing.py", line 75, in app
    response = await f(request)
               ^^^^^^^^^^^^^^^^
  File "/Users/sathishkesavan/Hackwell_AI/backend/venv/lib/python3.12/site-packages/fastapi/routing.py", line 328, in app
    content = await serialize_response(
              ^^^^^^^^^^^^^^^^^^^^^^^^^
  File "/Users/sathishkesavan/Hackwell_AI/backend/venv/lib/python3.12/site-packages/fastapi/routing.py", line 177, in serialize_response
    raise ResponseValidationError(
fastapi.exceptions.ResponseValidationError: 1 validation errors:
  {'type': 'string_type', 'loc': ('response', 3, 'date_of_birth'), 'msg': 'Input should be a valid string', 'input': None}

INFO:     127.0.0.1:53828 - "GET /api/patients?skip=0&limit=4 HTTP/1.1" 307 Temporary Redirect
INFO:     127.0.0.1:53828 - "GET /api/patients?skip=0&limit=4 HTTP/1.1" 307 Temporary Redirect
INFO:     127.0.0.1:53813 - "GET /api/analytics/overview HTTP/1.1" 200 OK
INFO:     127.0.0.1:53830 - "GET /api/patients/?skip=0&limit=4 HTTP/1.1" 500 Internal Server Error
ERROR:    Exception in ASGI application
Traceback (most recent call last):
  File "/Users/sathishkesavan/Hackwell_AI/backend/venv/lib/python3.12/site-packages/uvicorn/protocols/http/h11_impl.py", line 403, in run_asgi
    result = await app(  # type: ignore[func-returns-value]
             ^^^^^^^^^^^^^^^^^^^^^^^^^^^^^^^^^^^^^^^^^^^^^^
  File "/Users/sathishkesavan/Hackwell_AI/backend/venv/lib/python3.12/site-packages/uvicorn/middleware/proxy_headers.py", line 60, in __call__
    return await self.app(scope, receive, send)
           ^^^^^^^^^^^^^^^^^^^^^^^^^^^^^^^^^^^^
  File "/Users/sathishkesavan/Hackwell_AI/backend/venv/lib/python3.12/site-packages/fastapi/applications.py", line 1054, in __call__
    await super().__call__(scope, receive, send)
  File "/Users/sathishkesavan/Hackwell_AI/backend/venv/lib/python3.12/site-packages/starlette/applications.py", line 113, in __call__
    await self.middleware_stack(scope, receive, send)
  File "/Users/sathishkesavan/Hackwell_AI/backend/venv/lib/python3.12/site-packages/starlette/middleware/errors.py", line 186, in __call__
    raise exc
  File "/Users/sathishkesavan/Hackwell_AI/backend/venv/lib/python3.12/site-packages/starlette/middleware/errors.py", line 164, in __call__
    await self.app(scope, receive, _send)
  File "/Users/sathishkesavan/Hackwell_AI/backend/venv/lib/python3.12/site-packages/starlette/middleware/cors.py", line 93, in __call__
    await self.simple_response(scope, receive, send, request_headers=headers)
  File "/Users/sathishkesavan/Hackwell_AI/backend/venv/lib/python3.12/site-packages/starlette/middleware/cors.py", line 144, in simple_response
    await self.app(scope, receive, send)
  File "/Users/sathishkesavan/Hackwell_AI/backend/venv/lib/python3.12/site-packages/starlette/middleware/exceptions.py", line 63, in __call__
    await wrap_app_handling_exceptions(self.app, conn)(scope, receive, send)
  File "/Users/sathishkesavan/Hackwell_AI/backend/venv/lib/python3.12/site-packages/starlette/_exception_handler.py", line 53, in wrapped_app
    raise exc
  File "/Users/sathishkesavan/Hackwell_AI/backend/venv/lib/python3.12/site-packages/starlette/_exception_handler.py", line 42, in wrapped_app
    await app(scope, receive, sender)
  File "/Users/sathishkesavan/Hackwell_AI/backend/venv/lib/python3.12/site-packages/starlette/routing.py", line 716, in __call__
    await self.middleware_stack(scope, receive, send)
  File "/Users/sathishkesavan/Hackwell_AI/backend/venv/lib/python3.12/site-packages/starlette/routing.py", line 736, in app
    await route.handle(scope, receive, send)
  File "/Users/sathishkesavan/Hackwell_AI/backend/venv/lib/python3.12/site-packages/starlette/routing.py", line 290, in handle
    await self.app(scope, receive, send)
  File "/Users/sathishkesavan/Hackwell_AI/backend/venv/lib/python3.12/site-packages/starlette/routing.py", line 78, in app
    await wrap_app_handling_exceptions(app, request)(scope, receive, send)
  File "/Users/sathishkesavan/Hackwell_AI/backend/venv/lib/python3.12/site-packages/starlette/_exception_handler.py", line 53, in wrapped_app
    raise exc
  File "/Users/sathishkesavan/Hackwell_AI/backend/venv/lib/python3.12/site-packages/starlette/_exception_handler.py", line 42, in wrapped_app
    await app(scope, receive, sender)
  File "/Users/sathishkesavan/Hackwell_AI/backend/venv/lib/python3.12/site-packages/starlette/routing.py", line 75, in app
    response = await f(request)
               ^^^^^^^^^^^^^^^^
  File "/Users/sathishkesavan/Hackwell_AI/backend/venv/lib/python3.12/site-packages/fastapi/routing.py", line 328, in app
    content = await serialize_response(
              ^^^^^^^^^^^^^^^^^^^^^^^^^
  File "/Users/sathishkesavan/Hackwell_AI/backend/venv/lib/python3.12/site-packages/fastapi/routing.py", line 177, in serialize_response
    raise ResponseValidationError(
fastapi.exceptions.ResponseValidationError: 1 validation errors:
  {'type': 'string_type', 'loc': ('response', 3, 'date_of_birth'), 'msg': 'Input should be a valid string', 'input': None}

INFO:     127.0.0.1:53828 - "GET /api/analytics/overview HTTP/1.1" 200 OK
INFO:     127.0.0.1:53832 - "GET /api/patients/?skip=0&limit=4 HTTP/1.1" 500 Internal Server Error
ERROR:    Exception in ASGI application
Traceback (most recent call last):
  File "/Users/sathishkesavan/Hackwell_AI/backend/venv/lib/python3.12/site-packages/uvicorn/protocols/http/h11_impl.py", line 403, in run_asgi
    result = await app(  # type: ignore[func-returns-value]
             ^^^^^^^^^^^^^^^^^^^^^^^^^^^^^^^^^^^^^^^^^^^^^^
  File "/Users/sathishkesavan/Hackwell_AI/backend/venv/lib/python3.12/site-packages/uvicorn/middleware/proxy_headers.py", line 60, in __call__
    return await self.app(scope, receive, send)
           ^^^^^^^^^^^^^^^^^^^^^^^^^^^^^^^^^^^^
  File "/Users/sathishkesavan/Hackwell_AI/backend/venv/lib/python3.12/site-packages/fastapi/applications.py", line 1054, in __call__
    await super().__call__(scope, receive, send)
  File "/Users/sathishkesavan/Hackwell_AI/backend/venv/lib/python3.12/site-packages/starlette/applications.py", line 113, in __call__
    await self.middleware_stack(scope, receive, send)
  File "/Users/sathishkesavan/Hackwell_AI/backend/venv/lib/python3.12/site-packages/starlette/middleware/errors.py", line 186, in __call__
    raise exc
  File "/Users/sathishkesavan/Hackwell_AI/backend/venv/lib/python3.12/site-packages/starlette/middleware/errors.py", line 164, in __call__
    await self.app(scope, receive, _send)
  File "/Users/sathishkesavan/Hackwell_AI/backend/venv/lib/python3.12/site-packages/starlette/middleware/cors.py", line 93, in __call__
    await self.simple_response(scope, receive, send, request_headers=headers)
  File "/Users/sathishkesavan/Hackwell_AI/backend/venv/lib/python3.12/site-packages/starlette/middleware/cors.py", line 144, in simple_response
    await self.app(scope, receive, send)
  File "/Users/sathishkesavan/Hackwell_AI/backend/venv/lib/python3.12/site-packages/starlette/middleware/exceptions.py", line 63, in __call__
    await wrap_app_handling_exceptions(self.app, conn)(scope, receive, send)
  File "/Users/sathishkesavan/Hackwell_AI/backend/venv/lib/python3.12/site-packages/starlette/_exception_handler.py", line 53, in wrapped_app
    raise exc
  File "/Users/sathishkesavan/Hackwell_AI/backend/venv/lib/python3.12/site-packages/starlette/_exception_handler.py", line 42, in wrapped_app
    await app(scope, receive, sender)
  File "/Users/sathishkesavan/Hackwell_AI/backend/venv/lib/python3.12/site-packages/starlette/routing.py", line 716, in __call__
    await self.middleware_stack(scope, receive, send)
  File "/Users/sathishkesavan/Hackwell_AI/backend/venv/lib/python3.12/site-packages/starlette/routing.py", line 736, in app
    await route.handle(scope, receive, send)
  File "/Users/sathishkesavan/Hackwell_AI/backend/venv/lib/python3.12/site-packages/starlette/routing.py", line 290, in handle
    await self.app(scope, receive, send)
  File "/Users/sathishkesavan/Hackwell_AI/backend/venv/lib/python3.12/site-packages/starlette/routing.py", line 78, in app
    await wrap_app_handling_exceptions(app, request)(scope, receive, send)
  File "/Users/sathishkesavan/Hackwell_AI/backend/venv/lib/python3.12/site-packages/starlette/_exception_handler.py", line 53, in wrapped_app
    raise exc
  File "/Users/sathishkesavan/Hackwell_AI/backend/venv/lib/python3.12/site-packages/starlette/_exception_handler.py", line 42, in wrapped_app
    await app(scope, receive, sender)
  File "/Users/sathishkesavan/Hackwell_AI/backend/venv/lib/python3.12/site-packages/starlette/routing.py", line 75, in app
    response = await f(request)
               ^^^^^^^^^^^^^^^^
  File "/Users/sathishkesavan/Hackwell_AI/backend/venv/lib/python3.12/site-packages/fastapi/routing.py", line 328, in app
    content = await serialize_response(
              ^^^^^^^^^^^^^^^^^^^^^^^^^
  File "/Users/sathishkesavan/Hackwell_AI/backend/venv/lib/python3.12/site-packages/fastapi/routing.py", line 177, in serialize_response
    raise ResponseValidationError(
fastapi.exceptions.ResponseValidationError: 1 validation errors:
  {'type': 'string_type', 'loc': ('response', 3, 'date_of_birth'), 'msg': 'Input should be a valid string', 'input': None}

INFO:     127.0.0.1:53828 - "GET /api/patients/?skip=0&limit=4 HTTP/1.1" 500 Internal Server Error
ERROR:    Exception in ASGI application
Traceback (most recent call last):
  File "/Users/sathishkesavan/Hackwell_AI/backend/venv/lib/python3.12/site-packages/uvicorn/protocols/http/h11_impl.py", line 403, in run_asgi
    result = await app(  # type: ignore[func-returns-value]
             ^^^^^^^^^^^^^^^^^^^^^^^^^^^^^^^^^^^^^^^^^^^^^^
  File "/Users/sathishkesavan/Hackwell_AI/backend/venv/lib/python3.12/site-packages/uvicorn/middleware/proxy_headers.py", line 60, in __call__
    return await self.app(scope, receive, send)
           ^^^^^^^^^^^^^^^^^^^^^^^^^^^^^^^^^^^^
  File "/Users/sathishkesavan/Hackwell_AI/backend/venv/lib/python3.12/site-packages/fastapi/applications.py", line 1054, in __call__
    await super().__call__(scope, receive, send)
  File "/Users/sathishkesavan/Hackwell_AI/backend/venv/lib/python3.12/site-packages/starlette/applications.py", line 113, in __call__
    await self.middleware_stack(scope, receive, send)
  File "/Users/sathishkesavan/Hackwell_AI/backend/venv/lib/python3.12/site-packages/starlette/middleware/errors.py", line 186, in __call__
    raise exc
  File "/Users/sathishkesavan/Hackwell_AI/backend/venv/lib/python3.12/site-packages/starlette/middleware/errors.py", line 164, in __call__
    await self.app(scope, receive, _send)
  File "/Users/sathishkesavan/Hackwell_AI/backend/venv/lib/python3.12/site-packages/starlette/middleware/cors.py", line 93, in __call__
    await self.simple_response(scope, receive, send, request_headers=headers)
  File "/Users/sathishkesavan/Hackwell_AI/backend/venv/lib/python3.12/site-packages/starlette/middleware/cors.py", line 144, in simple_response
    await self.app(scope, receive, send)
  File "/Users/sathishkesavan/Hackwell_AI/backend/venv/lib/python3.12/site-packages/starlette/middleware/exceptions.py", line 63, in __call__
    await wrap_app_handling_exceptions(self.app, conn)(scope, receive, send)
  File "/Users/sathishkesavan/Hackwell_AI/backend/venv/lib/python3.12/site-packages/starlette/_exception_handler.py", line 53, in wrapped_app
    raise exc
  File "/Users/sathishkesavan/Hackwell_AI/backend/venv/lib/python3.12/site-packages/starlette/_exception_handler.py", line 42, in wrapped_app
    await app(scope, receive, sender)
  File "/Users/sathishkesavan/Hackwell_AI/backend/venv/lib/python3.12/site-packages/starlette/routing.py", line 716, in __call__
    await self.middleware_stack(scope, receive, send)
  File "/Users/sathishkesavan/Hackwell_AI/backend/venv/lib/python3.12/site-packages/starlette/routing.py", line 736, in app
    await route.handle(scope, receive, send)
  File "/Users/sathishkesavan/Hackwell_AI/backend/venv/lib/python3.12/site-packages/starlette/routing.py", line 290, in handle
    await self.app(scope, receive, send)
  File "/Users/sathishkesavan/Hackwell_AI/backend/venv/lib/python3.12/site-packages/starlette/routing.py", line 78, in app
    await wrap_app_handling_exceptions(app, request)(scope, receive, send)
  File "/Users/sathishkesavan/Hackwell_AI/backend/venv/lib/python3.12/site-packages/starlette/_exception_handler.py", line 53, in wrapped_app
    raise exc
  File "/Users/sathishkesavan/Hackwell_AI/backend/venv/lib/python3.12/site-packages/starlette/_exception_handler.py", line 42, in wrapped_app
    await app(scope, receive, sender)
  File "/Users/sathishkesavan/Hackwell_AI/backend/venv/lib/python3.12/site-packages/starlette/routing.py", line 75, in app
    response = await f(request)
               ^^^^^^^^^^^^^^^^
  File "/Users/sathishkesavan/Hackwell_AI/backend/venv/lib/python3.12/site-packages/fastapi/routing.py", line 328, in app
    content = await serialize_response(
              ^^^^^^^^^^^^^^^^^^^^^^^^^
  File "/Users/sathishkesavan/Hackwell_AI/backend/venv/lib/python3.12/site-packages/fastapi/routing.py", line 177, in serialize_response
    raise ResponseValidationError(
fastapi.exceptions.ResponseValidationError: 1 validation errors:
  {'type': 'string_type', 'loc': ('response', 3, 'date_of_birth'), 'msg': 'Input should be a valid string', 'input': None}

INFO:     127.0.0.1:54053 - "POST /api/auth/login?username=demo_doctor&password=demo123 HTTP/1.1" 200 OK
INFO:     127.0.0.1:54142 - "OPTIONS /api/auth/login HTTP/1.1" 200 OK
INFO:     127.0.0.1:54165 - "GET /health HTTP/1.1" 200 OK
INFO:     127.0.0.1:54322 - "POST /auth/login HTTP/1.1" 404 Not Found
INFO:     127.0.0.1:54330 - "GET /health HTTP/1.1" 200 OK
INFO:     127.0.0.1:54345 - "POST /login HTTP/1.1" 404 Not Found
INFO:     127.0.0.1:54353 - "GET /docs HTTP/1.1" 200 OK
INFO:     127.0.0.1:54364 - "GET /openapi.json HTTP/1.1" 200 OK
INFO:     127.0.0.1:54384 - "POST /api/auth/login?username=demo_doctor&password=demo123 HTTP/1.1" 200 OK
INFO:     127.0.0.1:54402 - "POST /api/auth/login?username=demo_user&password=demo123 HTTP/1.1" 200 OK
INFO:     127.0.0.1:54407 - "POST /api/auth/login?username=demo@hackwell.ai&password=demo123 HTTP/1.1" 401 Unauthorized
INFO:     127.0.0.1:54437 - "POST /api/auth/login?username=doctor@hackwell.ai&password=demo123 HTTP/1.1" 401 Unauthorized
