INFO:     Started server process [48141]
INFO:     Waiting for application startup.
INFO:     Application startup complete.
INFO:     Uvicorn running on http://0.0.0.0:8000 (Press CTRL+C to quit)
(trapped) error reading bcrypt version
Traceback (most recent call last):
  File "/Users/sathishkesavan/Hackwell_AI/backend/venv/lib/python3.12/site-packages/passlib/handlers/bcrypt.py", line 620, in _load_backend_mixin
    version = _bcrypt.__about__.__version__
              ^^^^^^^^^^^^^^^^^
AttributeError: module 'bcrypt' has no attribute '__about__'
INFO:     127.0.0.1:54801 - "POST /api/auth/login?username=demo_doctor&password=demo123 HTTP/1.1" 200 OK
INFO:     127.0.0.1:54810 - "POST /api/auth/login?username=demo_user&password=demo123 HTTP/1.1" 200 OK
INFO:     127.0.0.1:54818 - "POST /api/auth/login?username=doctor@hackwell.ai&password=demo123 HTTP/1.1" 200 OK
INFO:     127.0.0.1:54843 - "POST /api/auth/login?username=demo@hackwell.ai&password=demo123 HTTP/1.1" 200 OK
INFO:     127.0.0.1:54895 - "OPTIONS /api/analytics/overview HTTP/1.1" 200 OK
INFO:     127.0.0.1:54897 - "OPTIONS /api/patients?skip=0&limit=4 HTTP/1.1" 200 OK
INFO:     127.0.0.1:54898 - "OPTIONS /api/analytics/overview HTTP/1.1" 200 OK
INFO:     127.0.0.1:54899 - "OPTIONS /api/patients?skip=0&limit=4 HTTP/1.1" 200 OK
INFO:     127.0.0.1:54898 - "GET /api/patients?skip=0&limit=4 HTTP/1.1" 307 Temporary Redirect
INFO:     127.0.0.1:54897 - "GET /api/patients?skip=0&limit=4 HTTP/1.1" 307 Temporary Redirect
INFO:     127.0.0.1:54898 - "OPTIONS /api/patients/?skip=0&limit=4 HTTP/1.1" 200 OK
INFO:     127.0.0.1:54899 - "GET /api/analytics/overview HTTP/1.1" 200 OK
INFO:     127.0.0.1:54898 - "GET /api/patients/?skip=0&limit=4 HTTP/1.1" 500 Internal Server Error
ERROR:    Exception in ASGI application
Traceback (most recent call last):
  File "/Users/sathishkesavan/Hackwell_AI/backend/venv/lib/python3.12/site-packages/uvicorn/protocols/http/h11_impl.py", line 403, in run_asgi
    result = await app(  # type: ignore[func-returns-value]
             ^^^^^^^^^^^^^^^^^^^^^^^^^^^^^^^^^^^^^^^^^^^^^^
  File "/Users/sathishkesavan/Hackwell_AI/backend/venv/lib/python3.12/site-packages/uvicorn/middleware/proxy_headers.py", line 60, in __call__
    return await self.app(scope, receive, send)
           ^^^^^^^^^^^^^^^^^^^^^^^^^^^^^^^^^^^^
  File "/Users/sathishkesavan/Hackwell_AI/backend/venv/lib/python3.12/site-packages/fastapi/applications.py", line 1054, in __call__
    await super().__call__(scope, receive, send)
  File "/Users/sathishkesavan/Hackwell_AI/backend/venv/lib/python3.12/site-packages/starlette/applications.py", line 113, in __call__
    await self.middleware_stack(scope, receive, send)
  File "/Users/sathishkesavan/Hackwell_AI/backend/venv/lib/python3.12/site-packages/starlette/middleware/errors.py", line 186, in __call__
    raise exc
  File "/Users/sathishkesavan/Hackwell_AI/backend/venv/lib/python3.12/site-packages/starlette/middleware/errors.py", line 164, in __call__
    await self.app(scope, receive, _send)
  File "/Users/sathishkesavan/Hackwell_AI/backend/venv/lib/python3.12/site-packages/starlette/middleware/cors.py", line 93, in __call__
    await self.simple_response(scope, receive, send, request_headers=headers)
  File "/Users/sathishkesavan/Hackwell_AI/backend/venv/lib/python3.12/site-packages/starlette/middleware/cors.py", line 144, in simple_response
    await self.app(scope, receive, send)
  File "/Users/sathishkesavan/Hackwell_AI/backend/venv/lib/python3.12/site-packages/starlette/middleware/exceptions.py", line 63, in __call__
    await wrap_app_handling_exceptions(self.app, conn)(scope, receive, send)
  File "/Users/sathishkesavan/Hackwell_AI/backend/venv/lib/python3.12/site-packages/starlette/_exception_handler.py", line 53, in wrapped_app
    raise exc
  File "/Users/sathishkesavan/Hackwell_AI/backend/venv/lib/python3.12/site-packages/starlette/_exception_handler.py", line 42, in wrapped_app
    await app(scope, receive, sender)
  File "/Users/sathishkesavan/Hackwell_AI/backend/venv/lib/python3.12/site-packages/starlette/routing.py", line 716, in __call__
    await self.middleware_stack(scope, receive, send)
  File "/Users/sathishkesavan/Hackwell_AI/backend/venv/lib/python3.12/site-packages/starlette/routing.py", line 736, in app
    await route.handle(scope, receive, send)
  File "/Users/sathishkesavan/Hackwell_AI/backend/venv/lib/python3.12/site-packages/starlette/routing.py", line 290, in handle
    await self.app(scope, receive, send)
  File "/Users/sathishkesavan/Hackwell_AI/backend/venv/lib/python3.12/site-packages/starlette/routing.py", line 78, in app
    await wrap_app_handling_exceptions(app, request)(scope, receive, send)
  File "/Users/sathishkesavan/Hackwell_AI/backend/venv/lib/python3.12/site-packages/starlette/_exception_handler.py", line 53, in wrapped_app
    raise exc
  File "/Users/sathishkesavan/Hackwell_AI/backend/venv/lib/python3.12/site-packages/starlette/_exception_handler.py", line 42, in wrapped_app
    await app(scope, receive, sender)
  File "/Users/sathishkesavan/Hackwell_AI/backend/venv/lib/python3.12/site-packages/starlette/routing.py", line 75, in app
    response = await f(request)
               ^^^^^^^^^^^^^^^^
  File "/Users/sathishkesavan/Hackwell_AI/backend/venv/lib/python3.12/site-packages/fastapi/routing.py", line 328, in app
    content = await serialize_response(
              ^^^^^^^^^^^^^^^^^^^^^^^^^
  File "/Users/sathishkesavan/Hackwell_AI/backend/venv/lib/python3.12/site-packages/fastapi/routing.py", line 177, in serialize_response
    raise ResponseValidationError(
fastapi.exceptions.ResponseValidationError: 1 validation errors:
  {'type': 'string_type', 'loc': ('response', 3, 'date_of_birth'), 'msg': 'Input should be a valid string', 'input': None}

INFO:     127.0.0.1:54899 - "GET /api/patients/?skip=0&limit=4 HTTP/1.1" 500 Internal Server Error
ERROR:    Exception in ASGI application
Traceback (most recent call last):
  File "/Users/sathishkesavan/Hackwell_AI/backend/venv/lib/python3.12/site-packages/uvicorn/protocols/http/h11_impl.py", line 403, in run_asgi
    result = await app(  # type: ignore[func-returns-value]
             ^^^^^^^^^^^^^^^^^^^^^^^^^^^^^^^^^^^^^^^^^^^^^^
  File "/Users/sathishkesavan/Hackwell_AI/backend/venv/lib/python3.12/site-packages/uvicorn/middleware/proxy_headers.py", line 60, in __call__
    return await self.app(scope, receive, send)
           ^^^^^^^^^^^^^^^^^^^^^^^^^^^^^^^^^^^^
  File "/Users/sathishkesavan/Hackwell_AI/backend/venv/lib/python3.12/site-packages/fastapi/applications.py", line 1054, in __call__
    await super().__call__(scope, receive, send)
  File "/Users/sathishkesavan/Hackwell_AI/backend/venv/lib/python3.12/site-packages/starlette/applications.py", line 113, in __call__
    await self.middleware_stack(scope, receive, send)
  File "/Users/sathishkesavan/Hackwell_AI/backend/venv/lib/python3.12/site-packages/starlette/middleware/errors.py", line 186, in __call__
    raise exc
  File "/Users/sathishkesavan/Hackwell_AI/backend/venv/lib/python3.12/site-packages/starlette/middleware/errors.py", line 164, in __call__
    await self.app(scope, receive, _send)
  File "/Users/sathishkesavan/Hackwell_AI/backend/venv/lib/python3.12/site-packages/starlette/middleware/cors.py", line 93, in __call__
    await self.simple_response(scope, receive, send, request_headers=headers)
  File "/Users/sathishkesavan/Hackwell_AI/backend/venv/lib/python3.12/site-packages/starlette/middleware/cors.py", line 144, in simple_response
    await self.app(scope, receive, send)
  File "/Users/sathishkesavan/Hackwell_AI/backend/venv/lib/python3.12/site-packages/starlette/middleware/exceptions.py", line 63, in __call__
    await wrap_app_handling_exceptions(self.app, conn)(scope, receive, send)
  File "/Users/sathishkesavan/Hackwell_AI/backend/venv/lib/python3.12/site-packages/starlette/_exception_handler.py", line 53, in wrapped_app
    raise exc
  File "/Users/sathishkesavan/Hackwell_AI/backend/venv/lib/python3.12/site-packages/starlette/_exception_handler.py", line 42, in wrapped_app
    await app(scope, receive, sender)
  File "/Users/sathishkesavan/Hackwell_AI/backend/venv/lib/python3.12/site-packages/starlette/routing.py", line 716, in __call__
    await self.middleware_stack(scope, receive, send)
  File "/Users/sathishkesavan/Hackwell_AI/backend/venv/lib/python3.12/site-packages/starlette/routing.py", line 736, in app
    await route.handle(scope, receive, send)
  File "/Users/sathishkesavan/Hackwell_AI/backend/venv/lib/python3.12/site-packages/starlette/routing.py", line 290, in handle
    await self.app(scope, receive, send)
  File "/Users/sathishkesavan/Hackwell_AI/backend/venv/lib/python3.12/site-packages/starlette/routing.py", line 78, in app
    await wrap_app_handling_exceptions(app, request)(scope, receive, send)
  File "/Users/sathishkesavan/Hackwell_AI/backend/venv/lib/python3.12/site-packages/starlette/_exception_handler.py", line 53, in wrapped_app
    raise exc
  File "/Users/sathishkesavan/Hackwell_AI/backend/venv/lib/python3.12/site-packages/starlette/_exception_handler.py", line 42, in wrapped_app
    await app(scope, receive, sender)
  File "/Users/sathishkesavan/Hackwell_AI/backend/venv/lib/python3.12/site-packages/starlette/routing.py", line 75, in app
    response = await f(request)
               ^^^^^^^^^^^^^^^^
  File "/Users/sathishkesavan/Hackwell_AI/backend/venv/lib/python3.12/site-packages/fastapi/routing.py", line 328, in app
    content = await serialize_response(
              ^^^^^^^^^^^^^^^^^^^^^^^^^
  File "/Users/sathishkesavan/Hackwell_AI/backend/venv/lib/python3.12/site-packages/fastapi/routing.py", line 177, in serialize_response
    raise ResponseValidationError(
fastapi.exceptions.ResponseValidationError: 1 validation errors:
  {'type': 'string_type', 'loc': ('response', 3, 'date_of_birth'), 'msg': 'Input should be a valid string', 'input': None}

INFO:     127.0.0.1:54897 - "GET /api/analytics/overview HTTP/1.1" 200 OK
INFO:     127.0.0.1:54998 - "GET /api/patients?skip=0&limit=4 HTTP/1.1" 307 Temporary Redirect
INFO:     127.0.0.1:54998 - "GET /api/patients?skip=0&limit=4 HTTP/1.1" 307 Temporary Redirect
INFO:     127.0.0.1:55000 - "GET /api/patients/?skip=0&limit=4 HTTP/1.1" 500 Internal Server Error
ERROR:    Exception in ASGI application
Traceback (most recent call last):
  File "/Users/sathishkesavan/Hackwell_AI/backend/venv/lib/python3.12/site-packages/uvicorn/protocols/http/h11_impl.py", line 403, in run_asgi
    result = await app(  # type: ignore[func-returns-value]
             ^^^^^^^^^^^^^^^^^^^^^^^^^^^^^^^^^^^^^^^^^^^^^^
  File "/Users/sathishkesavan/Hackwell_AI/backend/venv/lib/python3.12/site-packages/uvicorn/middleware/proxy_headers.py", line 60, in __call__
    return await self.app(scope, receive, send)
           ^^^^^^^^^^^^^^^^^^^^^^^^^^^^^^^^^^^^
  File "/Users/sathishkesavan/Hackwell_AI/backend/venv/lib/python3.12/site-packages/fastapi/applications.py", line 1054, in __call__
    await super().__call__(scope, receive, send)
  File "/Users/sathishkesavan/Hackwell_AI/backend/venv/lib/python3.12/site-packages/starlette/applications.py", line 113, in __call__
    await self.middleware_stack(scope, receive, send)
  File "/Users/sathishkesavan/Hackwell_AI/backend/venv/lib/python3.12/site-packages/starlette/middleware/errors.py", line 186, in __call__
    raise exc
  File "/Users/sathishkesavan/Hackwell_AI/backend/venv/lib/python3.12/site-packages/starlette/middleware/errors.py", line 164, in __call__
    await self.app(scope, receive, _send)
  File "/Users/sathishkesavan/Hackwell_AI/backend/venv/lib/python3.12/site-packages/starlette/middleware/cors.py", line 93, in __call__
    await self.simple_response(scope, receive, send, request_headers=headers)
  File "/Users/sathishkesavan/Hackwell_AI/backend/venv/lib/python3.12/site-packages/starlette/middleware/cors.py", line 144, in simple_response
    await self.app(scope, receive, send)
  File "/Users/sathishkesavan/Hackwell_AI/backend/venv/lib/python3.12/site-packages/starlette/middleware/exceptions.py", line 63, in __call__
    await wrap_app_handling_exceptions(self.app, conn)(scope, receive, send)
  File "/Users/sathishkesavan/Hackwell_AI/backend/venv/lib/python3.12/site-packages/starlette/_exception_handler.py", line 53, in wrapped_app
    raise exc
  File "/Users/sathishkesavan/Hackwell_AI/backend/venv/lib/python3.12/site-packages/starlette/_exception_handler.py", line 42, in wrapped_app
    await app(scope, receive, sender)
  File "/Users/sathishkesavan/Hackwell_AI/backend/venv/lib/python3.12/site-packages/starlette/routing.py", line 716, in __call__
    await self.middleware_stack(scope, receive, send)
  File "/Users/sathishkesavan/Hackwell_AI/backend/venv/lib/python3.12/site-packages/starlette/routing.py", line 736, in app
    await route.handle(scope, receive, send)
  File "/Users/sathishkesavan/Hackwell_AI/backend/venv/lib/python3.12/site-packages/starlette/routing.py", line 290, in handle
    await self.app(scope, receive, send)
  File "/Users/sathishkesavan/Hackwell_AI/backend/venv/lib/python3.12/site-packages/starlette/routing.py", line 78, in app
    await wrap_app_handling_exceptions(app, request)(scope, receive, send)
  File "/Users/sathishkesavan/Hackwell_AI/backend/venv/lib/python3.12/site-packages/starlette/_exception_handler.py", line 53, in wrapped_app
    raise exc
  File "/Users/sathishkesavan/Hackwell_AI/backend/venv/lib/python3.12/site-packages/starlette/_exception_handler.py", line 42, in wrapped_app
    await app(scope, receive, sender)
  File "/Users/sathishkesavan/Hackwell_AI/backend/venv/lib/python3.12/site-packages/starlette/routing.py", line 75, in app
    response = await f(request)
               ^^^^^^^^^^^^^^^^
  File "/Users/sathishkesavan/Hackwell_AI/backend/venv/lib/python3.12/site-packages/fastapi/routing.py", line 328, in app
    content = await serialize_response(
              ^^^^^^^^^^^^^^^^^^^^^^^^^
  File "/Users/sathishkesavan/Hackwell_AI/backend/venv/lib/python3.12/site-packages/fastapi/routing.py", line 177, in serialize_response
    raise ResponseValidationError(
fastapi.exceptions.ResponseValidationError: 1 validation errors:
  {'type': 'string_type', 'loc': ('response', 3, 'date_of_birth'), 'msg': 'Input should be a valid string', 'input': None}

INFO:     127.0.0.1:54996 - "GET /api/analytics/overview HTTP/1.1" 200 OK
INFO:     127.0.0.1:54998 - "GET /api/patients/?skip=0&limit=4 HTTP/1.1" 500 Internal Server Error
ERROR:    Exception in ASGI application
Traceback (most recent call last):
  File "/Users/sathishkesavan/Hackwell_AI/backend/venv/lib/python3.12/site-packages/uvicorn/protocols/http/h11_impl.py", line 403, in run_asgi
    result = await app(  # type: ignore[func-returns-value]
             ^^^^^^^^^^^^^^^^^^^^^^^^^^^^^^^^^^^^^^^^^^^^^^
  File "/Users/sathishkesavan/Hackwell_AI/backend/venv/lib/python3.12/site-packages/uvicorn/middleware/proxy_headers.py", line 60, in __call__
    return await self.app(scope, receive, send)
           ^^^^^^^^^^^^^^^^^^^^^^^^^^^^^^^^^^^^
  File "/Users/sathishkesavan/Hackwell_AI/backend/venv/lib/python3.12/site-packages/fastapi/applications.py", line 1054, in __call__
    await super().__call__(scope, receive, send)
  File "/Users/sathishkesavan/Hackwell_AI/backend/venv/lib/python3.12/site-packages/starlette/applications.py", line 113, in __call__
    await self.middleware_stack(scope, receive, send)
  File "/Users/sathishkesavan/Hackwell_AI/backend/venv/lib/python3.12/site-packages/starlette/middleware/errors.py", line 186, in __call__
    raise exc
  File "/Users/sathishkesavan/Hackwell_AI/backend/venv/lib/python3.12/site-packages/starlette/middleware/errors.py", line 164, in __call__
    await self.app(scope, receive, _send)
  File "/Users/sathishkesavan/Hackwell_AI/backend/venv/lib/python3.12/site-packages/starlette/middleware/cors.py", line 93, in __call__
    await self.simple_response(scope, receive, send, request_headers=headers)
  File "/Users/sathishkesavan/Hackwell_AI/backend/venv/lib/python3.12/site-packages/starlette/middleware/cors.py", line 144, in simple_response
    await self.app(scope, receive, send)
  File "/Users/sathishkesavan/Hackwell_AI/backend/venv/lib/python3.12/site-packages/starlette/middleware/exceptions.py", line 63, in __call__
    await wrap_app_handling_exceptions(self.app, conn)(scope, receive, send)
  File "/Users/sathishkesavan/Hackwell_AI/backend/venv/lib/python3.12/site-packages/starlette/_exception_handler.py", line 53, in wrapped_app
    raise exc
  File "/Users/sathishkesavan/Hackwell_AI/backend/venv/lib/python3.12/site-packages/starlette/_exception_handler.py", line 42, in wrapped_app
    await app(scope, receive, sender)
  File "/Users/sathishkesavan/Hackwell_AI/backend/venv/lib/python3.12/site-packages/starlette/routing.py", line 716, in __call__
    await self.middleware_stack(scope, receive, send)
  File "/Users/sathishkesavan/Hackwell_AI/backend/venv/lib/python3.12/site-packages/starlette/routing.py", line 736, in app
    await route.handle(scope, receive, send)
  File "/Users/sathishkesavan/Hackwell_AI/backend/venv/lib/python3.12/site-packages/starlette/routing.py", line 290, in handle
    await self.app(scope, receive, send)
  File "/Users/sathishkesavan/Hackwell_AI/backend/venv/lib/python3.12/site-packages/starlette/routing.py", line 78, in app
    await wrap_app_handling_exceptions(app, request)(scope, receive, send)
  File "/Users/sathishkesavan/Hackwell_AI/backend/venv/lib/python3.12/site-packages/starlette/_exception_handler.py", line 53, in wrapped_app
    raise exc
  File "/Users/sathishkesavan/Hackwell_AI/backend/venv/lib/python3.12/site-packages/starlette/_exception_handler.py", line 42, in wrapped_app
    await app(scope, receive, sender)
  File "/Users/sathishkesavan/Hackwell_AI/backend/venv/lib/python3.12/site-packages/starlette/routing.py", line 75, in app
    response = await f(request)
               ^^^^^^^^^^^^^^^^
  File "/Users/sathishkesavan/Hackwell_AI/backend/venv/lib/python3.12/site-packages/fastapi/routing.py", line 328, in app
    content = await serialize_response(
              ^^^^^^^^^^^^^^^^^^^^^^^^^
  File "/Users/sathishkesavan/Hackwell_AI/backend/venv/lib/python3.12/site-packages/fastapi/routing.py", line 177, in serialize_response
    raise ResponseValidationError(
fastapi.exceptions.ResponseValidationError: 1 validation errors:
  {'type': 'string_type', 'loc': ('response', 3, 'date_of_birth'), 'msg': 'Input should be a valid string', 'input': None}

INFO:     127.0.0.1:54996 - "GET /api/analytics/overview HTTP/1.1" 200 OK
INFO:     127.0.0.1:55003 - "GET /api/patients/?skip=0&limit=4 HTTP/1.1" 500 Internal Server Error
ERROR:    Exception in ASGI application
Traceback (most recent call last):
  File "/Users/sathishkesavan/Hackwell_AI/backend/venv/lib/python3.12/site-packages/uvicorn/protocols/http/h11_impl.py", line 403, in run_asgi
    result = await app(  # type: ignore[func-returns-value]
             ^^^^^^^^^^^^^^^^^^^^^^^^^^^^^^^^^^^^^^^^^^^^^^
  File "/Users/sathishkesavan/Hackwell_AI/backend/venv/lib/python3.12/site-packages/uvicorn/middleware/proxy_headers.py", line 60, in __call__
    return await self.app(scope, receive, send)
           ^^^^^^^^^^^^^^^^^^^^^^^^^^^^^^^^^^^^
  File "/Users/sathishkesavan/Hackwell_AI/backend/venv/lib/python3.12/site-packages/fastapi/applications.py", line 1054, in __call__
    await super().__call__(scope, receive, send)
  File "/Users/sathishkesavan/Hackwell_AI/backend/venv/lib/python3.12/site-packages/starlette/applications.py", line 113, in __call__
    await self.middleware_stack(scope, receive, send)
  File "/Users/sathishkesavan/Hackwell_AI/backend/venv/lib/python3.12/site-packages/starlette/middleware/errors.py", line 186, in __call__
    raise exc
  File "/Users/sathishkesavan/Hackwell_AI/backend/venv/lib/python3.12/site-packages/starlette/middleware/errors.py", line 164, in __call__
    await self.app(scope, receive, _send)
  File "/Users/sathishkesavan/Hackwell_AI/backend/venv/lib/python3.12/site-packages/starlette/middleware/cors.py", line 93, in __call__
    await self.simple_response(scope, receive, send, request_headers=headers)
  File "/Users/sathishkesavan/Hackwell_AI/backend/venv/lib/python3.12/site-packages/starlette/middleware/cors.py", line 144, in simple_response
    await self.app(scope, receive, send)
  File "/Users/sathishkesavan/Hackwell_AI/backend/venv/lib/python3.12/site-packages/starlette/middleware/exceptions.py", line 63, in __call__
    await wrap_app_handling_exceptions(self.app, conn)(scope, receive, send)
  File "/Users/sathishkesavan/Hackwell_AI/backend/venv/lib/python3.12/site-packages/starlette/_exception_handler.py", line 53, in wrapped_app
    raise exc
  File "/Users/sathishkesavan/Hackwell_AI/backend/venv/lib/python3.12/site-packages/starlette/_exception_handler.py", line 42, in wrapped_app
    await app(scope, receive, sender)
  File "/Users/sathishkesavan/Hackwell_AI/backend/venv/lib/python3.12/site-packages/starlette/routing.py", line 716, in __call__
    await self.middleware_stack(scope, receive, send)
  File "/Users/sathishkesavan/Hackwell_AI/backend/venv/lib/python3.12/site-packages/starlette/routing.py", line 736, in app
    await route.handle(scope, receive, send)
  File "/Users/sathishkesavan/Hackwell_AI/backend/venv/lib/python3.12/site-packages/starlette/routing.py", line 290, in handle
    await self.app(scope, receive, send)
  File "/Users/sathishkesavan/Hackwell_AI/backend/venv/lib/python3.12/site-packages/starlette/routing.py", line 78, in app
    await wrap_app_handling_exceptions(app, request)(scope, receive, send)
  File "/Users/sathishkesavan/Hackwell_AI/backend/venv/lib/python3.12/site-packages/starlette/_exception_handler.py", line 53, in wrapped_app
    raise exc
  File "/Users/sathishkesavan/Hackwell_AI/backend/venv/lib/python3.12/site-packages/starlette/_exception_handler.py", line 42, in wrapped_app
    await app(scope, receive, sender)
  File "/Users/sathishkesavan/Hackwell_AI/backend/venv/lib/python3.12/site-packages/starlette/routing.py", line 75, in app
    response = await f(request)
               ^^^^^^^^^^^^^^^^
  File "/Users/sathishkesavan/Hackwell_AI/backend/venv/lib/python3.12/site-packages/fastapi/routing.py", line 328, in app
    content = await serialize_response(
              ^^^^^^^^^^^^^^^^^^^^^^^^^
  File "/Users/sathishkesavan/Hackwell_AI/backend/venv/lib/python3.12/site-packages/fastapi/routing.py", line 177, in serialize_response
    raise ResponseValidationError(
fastapi.exceptions.ResponseValidationError: 1 validation errors:
  {'type': 'string_type', 'loc': ('response', 3, 'date_of_birth'), 'msg': 'Input should be a valid string', 'input': None}

INFO:     127.0.0.1:55226 - "GET /health HTTP/1.1" 200 OK
INFO:     127.0.0.1:55310 - "OPTIONS /api/auth/login?username=doctor%40hackwell.ai&password=demo123 HTTP/1.1" 200 OK
INFO:     127.0.0.1:55310 - "POST /api/auth/login?username=doctor%40hackwell.ai&password=demo123 HTTP/1.1" 200 OK
INFO:     127.0.0.1:55314 - "GET /api/patients?skip=0&limit=4 HTTP/1.1" 307 Temporary Redirect
INFO:     127.0.0.1:55314 - "GET /api/patients?skip=0&limit=4 HTTP/1.1" 307 Temporary Redirect
INFO:     127.0.0.1:55316 - "GET /api/patients/?skip=0&limit=4 HTTP/1.1" 500 Internal Server Error
ERROR:    Exception in ASGI application
Traceback (most recent call last):
  File "/Users/sathishkesavan/Hackwell_AI/backend/venv/lib/python3.12/site-packages/uvicorn/protocols/http/h11_impl.py", line 403, in run_asgi
    result = await app(  # type: ignore[func-returns-value]
             ^^^^^^^^^^^^^^^^^^^^^^^^^^^^^^^^^^^^^^^^^^^^^^
  File "/Users/sathishkesavan/Hackwell_AI/backend/venv/lib/python3.12/site-packages/uvicorn/middleware/proxy_headers.py", line 60, in __call__
    return await self.app(scope, receive, send)
           ^^^^^^^^^^^^^^^^^^^^^^^^^^^^^^^^^^^^
  File "/Users/sathishkesavan/Hackwell_AI/backend/venv/lib/python3.12/site-packages/fastapi/applications.py", line 1054, in __call__
    await super().__call__(scope, receive, send)
  File "/Users/sathishkesavan/Hackwell_AI/backend/venv/lib/python3.12/site-packages/starlette/applications.py", line 113, in __call__
    await self.middleware_stack(scope, receive, send)
  File "/Users/sathishkesavan/Hackwell_AI/backend/venv/lib/python3.12/site-packages/starlette/middleware/errors.py", line 186, in __call__
    raise exc
  File "/Users/sathishkesavan/Hackwell_AI/backend/venv/lib/python3.12/site-packages/starlette/middleware/errors.py", line 164, in __call__
    await self.app(scope, receive, _send)
  File "/Users/sathishkesavan/Hackwell_AI/backend/venv/lib/python3.12/site-packages/starlette/middleware/cors.py", line 93, in __call__
    await self.simple_response(scope, receive, send, request_headers=headers)
  File "/Users/sathishkesavan/Hackwell_AI/backend/venv/lib/python3.12/site-packages/starlette/middleware/cors.py", line 144, in simple_response
    await self.app(scope, receive, send)
  File "/Users/sathishkesavan/Hackwell_AI/backend/venv/lib/python3.12/site-packages/starlette/middleware/exceptions.py", line 63, in __call__
    await wrap_app_handling_exceptions(self.app, conn)(scope, receive, send)
  File "/Users/sathishkesavan/Hackwell_AI/backend/venv/lib/python3.12/site-packages/starlette/_exception_handler.py", line 53, in wrapped_app
    raise exc
  File "/Users/sathishkesavan/Hackwell_AI/backend/venv/lib/python3.12/site-packages/starlette/_exception_handler.py", line 42, in wrapped_app
    await app(scope, receive, sender)
  File "/Users/sathishkesavan/Hackwell_AI/backend/venv/lib/python3.12/site-packages/starlette/routing.py", line 716, in __call__
    await self.middleware_stack(scope, receive, send)
  File "/Users/sathishkesavan/Hackwell_AI/backend/venv/lib/python3.12/site-packages/starlette/routing.py", line 736, in app
    await route.handle(scope, receive, send)
  File "/Users/sathishkesavan/Hackwell_AI/backend/venv/lib/python3.12/site-packages/starlette/routing.py", line 290, in handle
    await self.app(scope, receive, send)
  File "/Users/sathishkesavan/Hackwell_AI/backend/venv/lib/python3.12/site-packages/starlette/routing.py", line 78, in app
    await wrap_app_handling_exceptions(app, request)(scope, receive, send)
  File "/Users/sathishkesavan/Hackwell_AI/backend/venv/lib/python3.12/site-packages/starlette/_exception_handler.py", line 53, in wrapped_app
    raise exc
  File "/Users/sathishkesavan/Hackwell_AI/backend/venv/lib/python3.12/site-packages/starlette/_exception_handler.py", line 42, in wrapped_app
    await app(scope, receive, sender)
  File "/Users/sathishkesavan/Hackwell_AI/backend/venv/lib/python3.12/site-packages/starlette/routing.py", line 75, in app
    response = await f(request)
               ^^^^^^^^^^^^^^^^
  File "/Users/sathishkesavan/Hackwell_AI/backend/venv/lib/python3.12/site-packages/fastapi/routing.py", line 328, in app
    content = await serialize_response(
              ^^^^^^^^^^^^^^^^^^^^^^^^^
  File "/Users/sathishkesavan/Hackwell_AI/backend/venv/lib/python3.12/site-packages/fastapi/routing.py", line 177, in serialize_response
    raise ResponseValidationError(
fastapi.exceptions.ResponseValidationError: 1 validation errors:
  {'type': 'string_type', 'loc': ('response', 3, 'date_of_birth'), 'msg': 'Input should be a valid string', 'input': None}

INFO:     127.0.0.1:55310 - "GET /api/analytics/overview HTTP/1.1" 200 OK
INFO:     127.0.0.1:55314 - "GET /api/patients/?skip=0&limit=4 HTTP/1.1" 500 Internal Server Error
ERROR:    Exception in ASGI application
Traceback (most recent call last):
  File "/Users/sathishkesavan/Hackwell_AI/backend/venv/lib/python3.12/site-packages/uvicorn/protocols/http/h11_impl.py", line 403, in run_asgi
    result = await app(  # type: ignore[func-returns-value]
             ^^^^^^^^^^^^^^^^^^^^^^^^^^^^^^^^^^^^^^^^^^^^^^
  File "/Users/sathishkesavan/Hackwell_AI/backend/venv/lib/python3.12/site-packages/uvicorn/middleware/proxy_headers.py", line 60, in __call__
    return await self.app(scope, receive, send)
           ^^^^^^^^^^^^^^^^^^^^^^^^^^^^^^^^^^^^
  File "/Users/sathishkesavan/Hackwell_AI/backend/venv/lib/python3.12/site-packages/fastapi/applications.py", line 1054, in __call__
    await super().__call__(scope, receive, send)
  File "/Users/sathishkesavan/Hackwell_AI/backend/venv/lib/python3.12/site-packages/starlette/applications.py", line 113, in __call__
    await self.middleware_stack(scope, receive, send)
  File "/Users/sathishkesavan/Hackwell_AI/backend/venv/lib/python3.12/site-packages/starlette/middleware/errors.py", line 186, in __call__
    raise exc
  File "/Users/sathishkesavan/Hackwell_AI/backend/venv/lib/python3.12/site-packages/starlette/middleware/errors.py", line 164, in __call__
    await self.app(scope, receive, _send)
  File "/Users/sathishkesavan/Hackwell_AI/backend/venv/lib/python3.12/site-packages/starlette/middleware/cors.py", line 93, in __call__
    await self.simple_response(scope, receive, send, request_headers=headers)
  File "/Users/sathishkesavan/Hackwell_AI/backend/venv/lib/python3.12/site-packages/starlette/middleware/cors.py", line 144, in simple_response
    await self.app(scope, receive, send)
  File "/Users/sathishkesavan/Hackwell_AI/backend/venv/lib/python3.12/site-packages/starlette/middleware/exceptions.py", line 63, in __call__
    await wrap_app_handling_exceptions(self.app, conn)(scope, receive, send)
  File "/Users/sathishkesavan/Hackwell_AI/backend/venv/lib/python3.12/site-packages/starlette/_exception_handler.py", line 53, in wrapped_app
    raise exc
  File "/Users/sathishkesavan/Hackwell_AI/backend/venv/lib/python3.12/site-packages/starlette/_exception_handler.py", line 42, in wrapped_app
    await app(scope, receive, sender)
  File "/Users/sathishkesavan/Hackwell_AI/backend/venv/lib/python3.12/site-packages/starlette/routing.py", line 716, in __call__
    await self.middleware_stack(scope, receive, send)
  File "/Users/sathishkesavan/Hackwell_AI/backend/venv/lib/python3.12/site-packages/starlette/routing.py", line 736, in app
    await route.handle(scope, receive, send)
  File "/Users/sathishkesavan/Hackwell_AI/backend/venv/lib/python3.12/site-packages/starlette/routing.py", line 290, in handle
    await self.app(scope, receive, send)
  File "/Users/sathishkesavan/Hackwell_AI/backend/venv/lib/python3.12/site-packages/starlette/routing.py", line 78, in app
    await wrap_app_handling_exceptions(app, request)(scope, receive, send)
  File "/Users/sathishkesavan/Hackwell_AI/backend/venv/lib/python3.12/site-packages/starlette/_exception_handler.py", line 53, in wrapped_app
    raise exc
  File "/Users/sathishkesavan/Hackwell_AI/backend/venv/lib/python3.12/site-packages/starlette/_exception_handler.py", line 42, in wrapped_app
    await app(scope, receive, sender)
  File "/Users/sathishkesavan/Hackwell_AI/backend/venv/lib/python3.12/site-packages/starlette/routing.py", line 75, in app
    response = await f(request)
               ^^^^^^^^^^^^^^^^
  File "/Users/sathishkesavan/Hackwell_AI/backend/venv/lib/python3.12/site-packages/fastapi/routing.py", line 328, in app
    content = await serialize_response(
              ^^^^^^^^^^^^^^^^^^^^^^^^^
  File "/Users/sathishkesavan/Hackwell_AI/backend/venv/lib/python3.12/site-packages/fastapi/routing.py", line 177, in serialize_response
    raise ResponseValidationError(
fastapi.exceptions.ResponseValidationError: 1 validation errors:
  {'type': 'string_type', 'loc': ('response', 3, 'date_of_birth'), 'msg': 'Input should be a valid string', 'input': None}

INFO:     127.0.0.1:55310 - "GET /api/analytics/overview HTTP/1.1" 200 OK
INFO:     127.0.0.1:55318 - "GET /api/patients/?skip=0&limit=4 HTTP/1.1" 500 Internal Server Error
ERROR:    Exception in ASGI application
Traceback (most recent call last):
  File "/Users/sathishkesavan/Hackwell_AI/backend/venv/lib/python3.12/site-packages/uvicorn/protocols/http/h11_impl.py", line 403, in run_asgi
    result = await app(  # type: ignore[func-returns-value]
             ^^^^^^^^^^^^^^^^^^^^^^^^^^^^^^^^^^^^^^^^^^^^^^
  File "/Users/sathishkesavan/Hackwell_AI/backend/venv/lib/python3.12/site-packages/uvicorn/middleware/proxy_headers.py", line 60, in __call__
    return await self.app(scope, receive, send)
           ^^^^^^^^^^^^^^^^^^^^^^^^^^^^^^^^^^^^
  File "/Users/sathishkesavan/Hackwell_AI/backend/venv/lib/python3.12/site-packages/fastapi/applications.py", line 1054, in __call__
    await super().__call__(scope, receive, send)
  File "/Users/sathishkesavan/Hackwell_AI/backend/venv/lib/python3.12/site-packages/starlette/applications.py", line 113, in __call__
    await self.middleware_stack(scope, receive, send)
  File "/Users/sathishkesavan/Hackwell_AI/backend/venv/lib/python3.12/site-packages/starlette/middleware/errors.py", line 186, in __call__
    raise exc
  File "/Users/sathishkesavan/Hackwell_AI/backend/venv/lib/python3.12/site-packages/starlette/middleware/errors.py", line 164, in __call__
    await self.app(scope, receive, _send)
  File "/Users/sathishkesavan/Hackwell_AI/backend/venv/lib/python3.12/site-packages/starlette/middleware/cors.py", line 93, in __call__
    await self.simple_response(scope, receive, send, request_headers=headers)
  File "/Users/sathishkesavan/Hackwell_AI/backend/venv/lib/python3.12/site-packages/starlette/middleware/cors.py", line 144, in simple_response
    await self.app(scope, receive, send)
  File "/Users/sathishkesavan/Hackwell_AI/backend/venv/lib/python3.12/site-packages/starlette/middleware/exceptions.py", line 63, in __call__
    await wrap_app_handling_exceptions(self.app, conn)(scope, receive, send)
  File "/Users/sathishkesavan/Hackwell_AI/backend/venv/lib/python3.12/site-packages/starlette/_exception_handler.py", line 53, in wrapped_app
    raise exc
  File "/Users/sathishkesavan/Hackwell_AI/backend/venv/lib/python3.12/site-packages/starlette/_exception_handler.py", line 42, in wrapped_app
    await app(scope, receive, sender)
  File "/Users/sathishkesavan/Hackwell_AI/backend/venv/lib/python3.12/site-packages/starlette/routing.py", line 716, in __call__
    await self.middleware_stack(scope, receive, send)
  File "/Users/sathishkesavan/Hackwell_AI/backend/venv/lib/python3.12/site-packages/starlette/routing.py", line 736, in app
    await route.handle(scope, receive, send)
  File "/Users/sathishkesavan/Hackwell_AI/backend/venv/lib/python3.12/site-packages/starlette/routing.py", line 290, in handle
    await self.app(scope, receive, send)
  File "/Users/sathishkesavan/Hackwell_AI/backend/venv/lib/python3.12/site-packages/starlette/routing.py", line 78, in app
    await wrap_app_handling_exceptions(app, request)(scope, receive, send)
  File "/Users/sathishkesavan/Hackwell_AI/backend/venv/lib/python3.12/site-packages/starlette/_exception_handler.py", line 53, in wrapped_app
    raise exc
  File "/Users/sathishkesavan/Hackwell_AI/backend/venv/lib/python3.12/site-packages/starlette/_exception_handler.py", line 42, in wrapped_app
    await app(scope, receive, sender)
  File "/Users/sathishkesavan/Hackwell_AI/backend/venv/lib/python3.12/site-packages/starlette/routing.py", line 75, in app
    response = await f(request)
               ^^^^^^^^^^^^^^^^
  File "/Users/sathishkesavan/Hackwell_AI/backend/venv/lib/python3.12/site-packages/fastapi/routing.py", line 328, in app
    content = await serialize_response(
              ^^^^^^^^^^^^^^^^^^^^^^^^^
  File "/Users/sathishkesavan/Hackwell_AI/backend/venv/lib/python3.12/site-packages/fastapi/routing.py", line 177, in serialize_response
    raise ResponseValidationError(
fastapi.exceptions.ResponseValidationError: 1 validation errors:
  {'type': 'string_type', 'loc': ('response', 3, 'date_of_birth'), 'msg': 'Input should be a valid string', 'input': None}

INFO:     127.0.0.1:55341 - "OPTIONS /api/patients?skip=0&limit=100 HTTP/1.1" 200 OK
INFO:     127.0.0.1:55343 - "OPTIONS /api/patients?skip=0&limit=100 HTTP/1.1" 200 OK
INFO:     127.0.0.1:55341 - "GET /api/patients?skip=0&limit=100 HTTP/1.1" 307 Temporary Redirect
INFO:     127.0.0.1:55343 - "GET /api/patients?skip=0&limit=100 HTTP/1.1" 307 Temporary Redirect
INFO:     127.0.0.1:55341 - "OPTIONS /api/patients/?skip=0&limit=100 HTTP/1.1" 200 OK
INFO:     127.0.0.1:55343 - "OPTIONS /api/patients/?skip=0&limit=100 HTTP/1.1" 200 OK
INFO:     127.0.0.1:55341 - "GET /api/patients/?skip=0&limit=100 HTTP/1.1" 500 Internal Server Error
ERROR:    Exception in ASGI application
Traceback (most recent call last):
  File "/Users/sathishkesavan/Hackwell_AI/backend/venv/lib/python3.12/site-packages/uvicorn/protocols/http/h11_impl.py", line 403, in run_asgi
    result = await app(  # type: ignore[func-returns-value]
             ^^^^^^^^^^^^^^^^^^^^^^^^^^^^^^^^^^^^^^^^^^^^^^
  File "/Users/sathishkesavan/Hackwell_AI/backend/venv/lib/python3.12/site-packages/uvicorn/middleware/proxy_headers.py", line 60, in __call__
    return await self.app(scope, receive, send)
           ^^^^^^^^^^^^^^^^^^^^^^^^^^^^^^^^^^^^
  File "/Users/sathishkesavan/Hackwell_AI/backend/venv/lib/python3.12/site-packages/fastapi/applications.py", line 1054, in __call__
    await super().__call__(scope, receive, send)
  File "/Users/sathishkesavan/Hackwell_AI/backend/venv/lib/python3.12/site-packages/starlette/applications.py", line 113, in __call__
    await self.middleware_stack(scope, receive, send)
  File "/Users/sathishkesavan/Hackwell_AI/backend/venv/lib/python3.12/site-packages/starlette/middleware/errors.py", line 186, in __call__
    raise exc
  File "/Users/sathishkesavan/Hackwell_AI/backend/venv/lib/python3.12/site-packages/starlette/middleware/errors.py", line 164, in __call__
    await self.app(scope, receive, _send)
  File "/Users/sathishkesavan/Hackwell_AI/backend/venv/lib/python3.12/site-packages/starlette/middleware/cors.py", line 93, in __call__
    await self.simple_response(scope, receive, send, request_headers=headers)
  File "/Users/sathishkesavan/Hackwell_AI/backend/venv/lib/python3.12/site-packages/starlette/middleware/cors.py", line 144, in simple_response
    await self.app(scope, receive, send)
  File "/Users/sathishkesavan/Hackwell_AI/backend/venv/lib/python3.12/site-packages/starlette/middleware/exceptions.py", line 63, in __call__
    await wrap_app_handling_exceptions(self.app, conn)(scope, receive, send)
  File "/Users/sathishkesavan/Hackwell_AI/backend/venv/lib/python3.12/site-packages/starlette/_exception_handler.py", line 53, in wrapped_app
    raise exc
  File "/Users/sathishkesavan/Hackwell_AI/backend/venv/lib/python3.12/site-packages/starlette/_exception_handler.py", line 42, in wrapped_app
    await app(scope, receive, sender)
  File "/Users/sathishkesavan/Hackwell_AI/backend/venv/lib/python3.12/site-packages/starlette/routing.py", line 716, in __call__
    await self.middleware_stack(scope, receive, send)
  File "/Users/sathishkesavan/Hackwell_AI/backend/venv/lib/python3.12/site-packages/starlette/routing.py", line 736, in app
    await route.handle(scope, receive, send)
  File "/Users/sathishkesavan/Hackwell_AI/backend/venv/lib/python3.12/site-packages/starlette/routing.py", line 290, in handle
    await self.app(scope, receive, send)
  File "/Users/sathishkesavan/Hackwell_AI/backend/venv/lib/python3.12/site-packages/starlette/routing.py", line 78, in app
    await wrap_app_handling_exceptions(app, request)(scope, receive, send)
  File "/Users/sathishkesavan/Hackwell_AI/backend/venv/lib/python3.12/site-packages/starlette/_exception_handler.py", line 53, in wrapped_app
    raise exc
  File "/Users/sathishkesavan/Hackwell_AI/backend/venv/lib/python3.12/site-packages/starlette/_exception_handler.py", line 42, in wrapped_app
    await app(scope, receive, sender)
  File "/Users/sathishkesavan/Hackwell_AI/backend/venv/lib/python3.12/site-packages/starlette/routing.py", line 75, in app
    response = await f(request)
               ^^^^^^^^^^^^^^^^
  File "/Users/sathishkesavan/Hackwell_AI/backend/venv/lib/python3.12/site-packages/fastapi/routing.py", line 328, in app
    content = await serialize_response(
              ^^^^^^^^^^^^^^^^^^^^^^^^^
  File "/Users/sathishkesavan/Hackwell_AI/backend/venv/lib/python3.12/site-packages/fastapi/routing.py", line 177, in serialize_response
    raise ResponseValidationError(
fastapi.exceptions.ResponseValidationError: 1 validation errors:
  {'type': 'string_type', 'loc': ('response', 3, 'date_of_birth'), 'msg': 'Input should be a valid string', 'input': None}

INFO:     127.0.0.1:55343 - "GET /api/patients/?skip=0&limit=100 HTTP/1.1" 500 Internal Server Error
ERROR:    Exception in ASGI application
Traceback (most recent call last):
  File "/Users/sathishkesavan/Hackwell_AI/backend/venv/lib/python3.12/site-packages/uvicorn/protocols/http/h11_impl.py", line 403, in run_asgi
    result = await app(  # type: ignore[func-returns-value]
             ^^^^^^^^^^^^^^^^^^^^^^^^^^^^^^^^^^^^^^^^^^^^^^
  File "/Users/sathishkesavan/Hackwell_AI/backend/venv/lib/python3.12/site-packages/uvicorn/middleware/proxy_headers.py", line 60, in __call__
    return await self.app(scope, receive, send)
           ^^^^^^^^^^^^^^^^^^^^^^^^^^^^^^^^^^^^
  File "/Users/sathishkesavan/Hackwell_AI/backend/venv/lib/python3.12/site-packages/fastapi/applications.py", line 1054, in __call__
    await super().__call__(scope, receive, send)
  File "/Users/sathishkesavan/Hackwell_AI/backend/venv/lib/python3.12/site-packages/starlette/applications.py", line 113, in __call__
    await self.middleware_stack(scope, receive, send)
  File "/Users/sathishkesavan/Hackwell_AI/backend/venv/lib/python3.12/site-packages/starlette/middleware/errors.py", line 186, in __call__
    raise exc
  File "/Users/sathishkesavan/Hackwell_AI/backend/venv/lib/python3.12/site-packages/starlette/middleware/errors.py", line 164, in __call__
    await self.app(scope, receive, _send)
  File "/Users/sathishkesavan/Hackwell_AI/backend/venv/lib/python3.12/site-packages/starlette/middleware/cors.py", line 93, in __call__
    await self.simple_response(scope, receive, send, request_headers=headers)
  File "/Users/sathishkesavan/Hackwell_AI/backend/venv/lib/python3.12/site-packages/starlette/middleware/cors.py", line 144, in simple_response
    await self.app(scope, receive, send)
  File "/Users/sathishkesavan/Hackwell_AI/backend/venv/lib/python3.12/site-packages/starlette/middleware/exceptions.py", line 63, in __call__
    await wrap_app_handling_exceptions(self.app, conn)(scope, receive, send)
  File "/Users/sathishkesavan/Hackwell_AI/backend/venv/lib/python3.12/site-packages/starlette/_exception_handler.py", line 53, in wrapped_app
    raise exc
  File "/Users/sathishkesavan/Hackwell_AI/backend/venv/lib/python3.12/site-packages/starlette/_exception_handler.py", line 42, in wrapped_app
    await app(scope, receive, sender)
  File "/Users/sathishkesavan/Hackwell_AI/backend/venv/lib/python3.12/site-packages/starlette/routing.py", line 716, in __call__
    await self.middleware_stack(scope, receive, send)
  File "/Users/sathishkesavan/Hackwell_AI/backend/venv/lib/python3.12/site-packages/starlette/routing.py", line 736, in app
    await route.handle(scope, receive, send)
  File "/Users/sathishkesavan/Hackwell_AI/backend/venv/lib/python3.12/site-packages/starlette/routing.py", line 290, in handle
    await self.app(scope, receive, send)
  File "/Users/sathishkesavan/Hackwell_AI/backend/venv/lib/python3.12/site-packages/starlette/routing.py", line 78, in app
    await wrap_app_handling_exceptions(app, request)(scope, receive, send)
  File "/Users/sathishkesavan/Hackwell_AI/backend/venv/lib/python3.12/site-packages/starlette/_exception_handler.py", line 53, in wrapped_app
    raise exc
  File "/Users/sathishkesavan/Hackwell_AI/backend/venv/lib/python3.12/site-packages/starlette/_exception_handler.py", line 42, in wrapped_app
    await app(scope, receive, sender)
  File "/Users/sathishkesavan/Hackwell_AI/backend/venv/lib/python3.12/site-packages/starlette/routing.py", line 75, in app
    response = await f(request)
               ^^^^^^^^^^^^^^^^
  File "/Users/sathishkesavan/Hackwell_AI/backend/venv/lib/python3.12/site-packages/fastapi/routing.py", line 328, in app
    content = await serialize_response(
              ^^^^^^^^^^^^^^^^^^^^^^^^^
  File "/Users/sathishkesavan/Hackwell_AI/backend/venv/lib/python3.12/site-packages/fastapi/routing.py", line 177, in serialize_response
    raise ResponseValidationError(
fastapi.exceptions.ResponseValidationError: 1 validation errors:
  {'type': 'string_type', 'loc': ('response', 3, 'date_of_birth'), 'msg': 'Input should be a valid string', 'input': None}

INFO:     127.0.0.1:55345 - "GET /api/patients/?skip=0&limit=100 HTTP/1.1" 500 Internal Server Error
ERROR:    Exception in ASGI application
Traceback (most recent call last):
  File "/Users/sathishkesavan/Hackwell_AI/backend/venv/lib/python3.12/site-packages/uvicorn/protocols/http/h11_impl.py", line 403, in run_asgi
    result = await app(  # type: ignore[func-returns-value]
             ^^^^^^^^^^^^^^^^^^^^^^^^^^^^^^^^^^^^^^^^^^^^^^
  File "/Users/sathishkesavan/Hackwell_AI/backend/venv/lib/python3.12/site-packages/uvicorn/middleware/proxy_headers.py", line 60, in __call__
    return await self.app(scope, receive, send)
           ^^^^^^^^^^^^^^^^^^^^^^^^^^^^^^^^^^^^
  File "/Users/sathishkesavan/Hackwell_AI/backend/venv/lib/python3.12/site-packages/fastapi/applications.py", line 1054, in __call__
    await super().__call__(scope, receive, send)
  File "/Users/sathishkesavan/Hackwell_AI/backend/venv/lib/python3.12/site-packages/starlette/applications.py", line 113, in __call__
    await self.middleware_stack(scope, receive, send)
  File "/Users/sathishkesavan/Hackwell_AI/backend/venv/lib/python3.12/site-packages/starlette/middleware/errors.py", line 186, in __call__
    raise exc
  File "/Users/sathishkesavan/Hackwell_AI/backend/venv/lib/python3.12/site-packages/starlette/middleware/errors.py", line 164, in __call__
    await self.app(scope, receive, _send)
  File "/Users/sathishkesavan/Hackwell_AI/backend/venv/lib/python3.12/site-packages/starlette/middleware/cors.py", line 93, in __call__
    await self.simple_response(scope, receive, send, request_headers=headers)
  File "/Users/sathishkesavan/Hackwell_AI/backend/venv/lib/python3.12/site-packages/starlette/middleware/cors.py", line 144, in simple_response
    await self.app(scope, receive, send)
  File "/Users/sathishkesavan/Hackwell_AI/backend/venv/lib/python3.12/site-packages/starlette/middleware/exceptions.py", line 63, in __call__
    await wrap_app_handling_exceptions(self.app, conn)(scope, receive, send)
  File "/Users/sathishkesavan/Hackwell_AI/backend/venv/lib/python3.12/site-packages/starlette/_exception_handler.py", line 53, in wrapped_app
    raise exc
  File "/Users/sathishkesavan/Hackwell_AI/backend/venv/lib/python3.12/site-packages/starlette/_exception_handler.py", line 42, in wrapped_app
    await app(scope, receive, sender)
  File "/Users/sathishkesavan/Hackwell_AI/backend/venv/lib/python3.12/site-packages/starlette/routing.py", line 716, in __call__
    await self.middleware_stack(scope, receive, send)
  File "/Users/sathishkesavan/Hackwell_AI/backend/venv/lib/python3.12/site-packages/starlette/routing.py", line 736, in app
    await route.handle(scope, receive, send)
  File "/Users/sathishkesavan/Hackwell_AI/backend/venv/lib/python3.12/site-packages/starlette/routing.py", line 290, in handle
    await self.app(scope, receive, send)
  File "/Users/sathishkesavan/Hackwell_AI/backend/venv/lib/python3.12/site-packages/starlette/routing.py", line 78, in app
    await wrap_app_handling_exceptions(app, request)(scope, receive, send)
  File "/Users/sathishkesavan/Hackwell_AI/backend/venv/lib/python3.12/site-packages/starlette/_exception_handler.py", line 53, in wrapped_app
    raise exc
  File "/Users/sathishkesavan/Hackwell_AI/backend/venv/lib/python3.12/site-packages/starlette/_exception_handler.py", line 42, in wrapped_app
    await app(scope, receive, sender)
  File "/Users/sathishkesavan/Hackwell_AI/backend/venv/lib/python3.12/site-packages/starlette/routing.py", line 75, in app
    response = await f(request)
               ^^^^^^^^^^^^^^^^
  File "/Users/sathishkesavan/Hackwell_AI/backend/venv/lib/python3.12/site-packages/fastapi/routing.py", line 328, in app
    content = await serialize_response(
              ^^^^^^^^^^^^^^^^^^^^^^^^^
  File "/Users/sathishkesavan/Hackwell_AI/backend/venv/lib/python3.12/site-packages/fastapi/routing.py", line 177, in serialize_response
    raise ResponseValidationError(
fastapi.exceptions.ResponseValidationError: 1 validation errors:
  {'type': 'string_type', 'loc': ('response', 3, 'date_of_birth'), 'msg': 'Input should be a valid string', 'input': None}

INFO:     127.0.0.1:55358 - "GET /api/patients?skip=0&limit=100 HTTP/1.1" 307 Temporary Redirect
INFO:     127.0.0.1:55358 - "GET /api/patients?skip=0&limit=100 HTTP/1.1" 307 Temporary Redirect
INFO:     127.0.0.1:55360 - "GET /api/patients/?skip=0&limit=100 HTTP/1.1" 500 Internal Server Error
ERROR:    Exception in ASGI application
Traceback (most recent call last):
  File "/Users/sathishkesavan/Hackwell_AI/backend/venv/lib/python3.12/site-packages/uvicorn/protocols/http/h11_impl.py", line 403, in run_asgi
    result = await app(  # type: ignore[func-returns-value]
             ^^^^^^^^^^^^^^^^^^^^^^^^^^^^^^^^^^^^^^^^^^^^^^
  File "/Users/sathishkesavan/Hackwell_AI/backend/venv/lib/python3.12/site-packages/uvicorn/middleware/proxy_headers.py", line 60, in __call__
    return await self.app(scope, receive, send)
           ^^^^^^^^^^^^^^^^^^^^^^^^^^^^^^^^^^^^
  File "/Users/sathishkesavan/Hackwell_AI/backend/venv/lib/python3.12/site-packages/fastapi/applications.py", line 1054, in __call__
    await super().__call__(scope, receive, send)
  File "/Users/sathishkesavan/Hackwell_AI/backend/venv/lib/python3.12/site-packages/starlette/applications.py", line 113, in __call__
    await self.middleware_stack(scope, receive, send)
  File "/Users/sathishkesavan/Hackwell_AI/backend/venv/lib/python3.12/site-packages/starlette/middleware/errors.py", line 186, in __call__
    raise exc
  File "/Users/sathishkesavan/Hackwell_AI/backend/venv/lib/python3.12/site-packages/starlette/middleware/errors.py", line 164, in __call__
    await self.app(scope, receive, _send)
  File "/Users/sathishkesavan/Hackwell_AI/backend/venv/lib/python3.12/site-packages/starlette/middleware/cors.py", line 93, in __call__
    await self.simple_response(scope, receive, send, request_headers=headers)
  File "/Users/sathishkesavan/Hackwell_AI/backend/venv/lib/python3.12/site-packages/starlette/middleware/cors.py", line 144, in simple_response
    await self.app(scope, receive, send)
  File "/Users/sathishkesavan/Hackwell_AI/backend/venv/lib/python3.12/site-packages/starlette/middleware/exceptions.py", line 63, in __call__
    await wrap_app_handling_exceptions(self.app, conn)(scope, receive, send)
  File "/Users/sathishkesavan/Hackwell_AI/backend/venv/lib/python3.12/site-packages/starlette/_exception_handler.py", line 53, in wrapped_app
    raise exc
  File "/Users/sathishkesavan/Hackwell_AI/backend/venv/lib/python3.12/site-packages/starlette/_exception_handler.py", line 42, in wrapped_app
    await app(scope, receive, sender)
  File "/Users/sathishkesavan/Hackwell_AI/backend/venv/lib/python3.12/site-packages/starlette/routing.py", line 716, in __call__
    await self.middleware_stack(scope, receive, send)
  File "/Users/sathishkesavan/Hackwell_AI/backend/venv/lib/python3.12/site-packages/starlette/routing.py", line 736, in app
    await route.handle(scope, receive, send)
  File "/Users/sathishkesavan/Hackwell_AI/backend/venv/lib/python3.12/site-packages/starlette/routing.py", line 290, in handle
    await self.app(scope, receive, send)
  File "/Users/sathishkesavan/Hackwell_AI/backend/venv/lib/python3.12/site-packages/starlette/routing.py", line 78, in app
    await wrap_app_handling_exceptions(app, request)(scope, receive, send)
  File "/Users/sathishkesavan/Hackwell_AI/backend/venv/lib/python3.12/site-packages/starlette/_exception_handler.py", line 53, in wrapped_app
    raise exc
  File "/Users/sathishkesavan/Hackwell_AI/backend/venv/lib/python3.12/site-packages/starlette/_exception_handler.py", line 42, in wrapped_app
    await app(scope, receive, sender)
  File "/Users/sathishkesavan/Hackwell_AI/backend/venv/lib/python3.12/site-packages/starlette/routing.py", line 75, in app
    response = await f(request)
               ^^^^^^^^^^^^^^^^
  File "/Users/sathishkesavan/Hackwell_AI/backend/venv/lib/python3.12/site-packages/fastapi/routing.py", line 328, in app
    content = await serialize_response(
              ^^^^^^^^^^^^^^^^^^^^^^^^^
  File "/Users/sathishkesavan/Hackwell_AI/backend/venv/lib/python3.12/site-packages/fastapi/routing.py", line 177, in serialize_response
    raise ResponseValidationError(
fastapi.exceptions.ResponseValidationError: 1 validation errors:
  {'type': 'string_type', 'loc': ('response', 3, 'date_of_birth'), 'msg': 'Input should be a valid string', 'input': None}

INFO:     127.0.0.1:55358 - "GET /api/patients/?skip=0&limit=100 HTTP/1.1" 500 Internal Server Error
ERROR:    Exception in ASGI application
Traceback (most recent call last):
  File "/Users/sathishkesavan/Hackwell_AI/backend/venv/lib/python3.12/site-packages/uvicorn/protocols/http/h11_impl.py", line 403, in run_asgi
    result = await app(  # type: ignore[func-returns-value]
             ^^^^^^^^^^^^^^^^^^^^^^^^^^^^^^^^^^^^^^^^^^^^^^
  File "/Users/sathishkesavan/Hackwell_AI/backend/venv/lib/python3.12/site-packages/uvicorn/middleware/proxy_headers.py", line 60, in __call__
    return await self.app(scope, receive, send)
           ^^^^^^^^^^^^^^^^^^^^^^^^^^^^^^^^^^^^
  File "/Users/sathishkesavan/Hackwell_AI/backend/venv/lib/python3.12/site-packages/fastapi/applications.py", line 1054, in __call__
    await super().__call__(scope, receive, send)
  File "/Users/sathishkesavan/Hackwell_AI/backend/venv/lib/python3.12/site-packages/starlette/applications.py", line 113, in __call__
    await self.middleware_stack(scope, receive, send)
  File "/Users/sathishkesavan/Hackwell_AI/backend/venv/lib/python3.12/site-packages/starlette/middleware/errors.py", line 186, in __call__
    raise exc
  File "/Users/sathishkesavan/Hackwell_AI/backend/venv/lib/python3.12/site-packages/starlette/middleware/errors.py", line 164, in __call__
    await self.app(scope, receive, _send)
  File "/Users/sathishkesavan/Hackwell_AI/backend/venv/lib/python3.12/site-packages/starlette/middleware/cors.py", line 93, in __call__
    await self.simple_response(scope, receive, send, request_headers=headers)
  File "/Users/sathishkesavan/Hackwell_AI/backend/venv/lib/python3.12/site-packages/starlette/middleware/cors.py", line 144, in simple_response
    await self.app(scope, receive, send)
  File "/Users/sathishkesavan/Hackwell_AI/backend/venv/lib/python3.12/site-packages/starlette/middleware/exceptions.py", line 63, in __call__
    await wrap_app_handling_exceptions(self.app, conn)(scope, receive, send)
  File "/Users/sathishkesavan/Hackwell_AI/backend/venv/lib/python3.12/site-packages/starlette/_exception_handler.py", line 53, in wrapped_app
    raise exc
  File "/Users/sathishkesavan/Hackwell_AI/backend/venv/lib/python3.12/site-packages/starlette/_exception_handler.py", line 42, in wrapped_app
    await app(scope, receive, sender)
  File "/Users/sathishkesavan/Hackwell_AI/backend/venv/lib/python3.12/site-packages/starlette/routing.py", line 716, in __call__
    await self.middleware_stack(scope, receive, send)
  File "/Users/sathishkesavan/Hackwell_AI/backend/venv/lib/python3.12/site-packages/starlette/routing.py", line 736, in app
    await route.handle(scope, receive, send)
  File "/Users/sathishkesavan/Hackwell_AI/backend/venv/lib/python3.12/site-packages/starlette/routing.py", line 290, in handle
    await self.app(scope, receive, send)
  File "/Users/sathishkesavan/Hackwell_AI/backend/venv/lib/python3.12/site-packages/starlette/routing.py", line 78, in app
    await wrap_app_handling_exceptions(app, request)(scope, receive, send)
  File "/Users/sathishkesavan/Hackwell_AI/backend/venv/lib/python3.12/site-packages/starlette/_exception_handler.py", line 53, in wrapped_app
    raise exc
  File "/Users/sathishkesavan/Hackwell_AI/backend/venv/lib/python3.12/site-packages/starlette/_exception_handler.py", line 42, in wrapped_app
    await app(scope, receive, sender)
  File "/Users/sathishkesavan/Hackwell_AI/backend/venv/lib/python3.12/site-packages/starlette/routing.py", line 75, in app
    response = await f(request)
               ^^^^^^^^^^^^^^^^
  File "/Users/sathishkesavan/Hackwell_AI/backend/venv/lib/python3.12/site-packages/fastapi/routing.py", line 328, in app
    content = await serialize_response(
              ^^^^^^^^^^^^^^^^^^^^^^^^^
  File "/Users/sathishkesavan/Hackwell_AI/backend/venv/lib/python3.12/site-packages/fastapi/routing.py", line 177, in serialize_response
    raise ResponseValidationError(
fastapi.exceptions.ResponseValidationError: 1 validation errors:
  {'type': 'string_type', 'loc': ('response', 3, 'date_of_birth'), 'msg': 'Input should be a valid string', 'input': None}

INFO:     127.0.0.1:55362 - "GET /api/patients/?skip=0&limit=100 HTTP/1.1" 500 Internal Server Error
ERROR:    Exception in ASGI application
Traceback (most recent call last):
  File "/Users/sathishkesavan/Hackwell_AI/backend/venv/lib/python3.12/site-packages/uvicorn/protocols/http/h11_impl.py", line 403, in run_asgi
    result = await app(  # type: ignore[func-returns-value]
             ^^^^^^^^^^^^^^^^^^^^^^^^^^^^^^^^^^^^^^^^^^^^^^
  File "/Users/sathishkesavan/Hackwell_AI/backend/venv/lib/python3.12/site-packages/uvicorn/middleware/proxy_headers.py", line 60, in __call__
    return await self.app(scope, receive, send)
           ^^^^^^^^^^^^^^^^^^^^^^^^^^^^^^^^^^^^
  File "/Users/sathishkesavan/Hackwell_AI/backend/venv/lib/python3.12/site-packages/fastapi/applications.py", line 1054, in __call__
    await super().__call__(scope, receive, send)
  File "/Users/sathishkesavan/Hackwell_AI/backend/venv/lib/python3.12/site-packages/starlette/applications.py", line 113, in __call__
    await self.middleware_stack(scope, receive, send)
  File "/Users/sathishkesavan/Hackwell_AI/backend/venv/lib/python3.12/site-packages/starlette/middleware/errors.py", line 186, in __call__
    raise exc
  File "/Users/sathishkesavan/Hackwell_AI/backend/venv/lib/python3.12/site-packages/starlette/middleware/errors.py", line 164, in __call__
    await self.app(scope, receive, _send)
  File "/Users/sathishkesavan/Hackwell_AI/backend/venv/lib/python3.12/site-packages/starlette/middleware/cors.py", line 93, in __call__
    await self.simple_response(scope, receive, send, request_headers=headers)
  File "/Users/sathishkesavan/Hackwell_AI/backend/venv/lib/python3.12/site-packages/starlette/middleware/cors.py", line 144, in simple_response
    await self.app(scope, receive, send)
  File "/Users/sathishkesavan/Hackwell_AI/backend/venv/lib/python3.12/site-packages/starlette/middleware/exceptions.py", line 63, in __call__
    await wrap_app_handling_exceptions(self.app, conn)(scope, receive, send)
  File "/Users/sathishkesavan/Hackwell_AI/backend/venv/lib/python3.12/site-packages/starlette/_exception_handler.py", line 53, in wrapped_app
    raise exc
  File "/Users/sathishkesavan/Hackwell_AI/backend/venv/lib/python3.12/site-packages/starlette/_exception_handler.py", line 42, in wrapped_app
    await app(scope, receive, sender)
  File "/Users/sathishkesavan/Hackwell_AI/backend/venv/lib/python3.12/site-packages/starlette/routing.py", line 716, in __call__
    await self.middleware_stack(scope, receive, send)
  File "/Users/sathishkesavan/Hackwell_AI/backend/venv/lib/python3.12/site-packages/starlette/routing.py", line 736, in app
    await route.handle(scope, receive, send)
  File "/Users/sathishkesavan/Hackwell_AI/backend/venv/lib/python3.12/site-packages/starlette/routing.py", line 290, in handle
    await self.app(scope, receive, send)
  File "/Users/sathishkesavan/Hackwell_AI/backend/venv/lib/python3.12/site-packages/starlette/routing.py", line 78, in app
    await wrap_app_handling_exceptions(app, request)(scope, receive, send)
  File "/Users/sathishkesavan/Hackwell_AI/backend/venv/lib/python3.12/site-packages/starlette/_exception_handler.py", line 53, in wrapped_app
    raise exc
  File "/Users/sathishkesavan/Hackwell_AI/backend/venv/lib/python3.12/site-packages/starlette/_exception_handler.py", line 42, in wrapped_app
    await app(scope, receive, sender)
  File "/Users/sathishkesavan/Hackwell_AI/backend/venv/lib/python3.12/site-packages/starlette/routing.py", line 75, in app
    response = await f(request)
               ^^^^^^^^^^^^^^^^
  File "/Users/sathishkesavan/Hackwell_AI/backend/venv/lib/python3.12/site-packages/fastapi/routing.py", line 328, in app
    content = await serialize_response(
              ^^^^^^^^^^^^^^^^^^^^^^^^^
  File "/Users/sathishkesavan/Hackwell_AI/backend/venv/lib/python3.12/site-packages/fastapi/routing.py", line 177, in serialize_response
    raise ResponseValidationError(
fastapi.exceptions.ResponseValidationError: 1 validation errors:
  {'type': 'string_type', 'loc': ('response', 3, 'date_of_birth'), 'msg': 'Input should be a valid string', 'input': None}

INFO:     127.0.0.1:55368 - "GET /api/patients?skip=0&limit=4 HTTP/1.1" 307 Temporary Redirect
INFO:     127.0.0.1:55368 - "GET /api/patients?skip=0&limit=4 HTTP/1.1" 307 Temporary Redirect
INFO:     127.0.0.1:55366 - "GET /api/analytics/overview HTTP/1.1" 200 OK
INFO:     127.0.0.1:55370 - "GET /api/patients/?skip=0&limit=4 HTTP/1.1" 500 Internal Server Error
ERROR:    Exception in ASGI application
Traceback (most recent call last):
  File "/Users/sathishkesavan/Hackwell_AI/backend/venv/lib/python3.12/site-packages/uvicorn/protocols/http/h11_impl.py", line 403, in run_asgi
    result = await app(  # type: ignore[func-returns-value]
             ^^^^^^^^^^^^^^^^^^^^^^^^^^^^^^^^^^^^^^^^^^^^^^
  File "/Users/sathishkesavan/Hackwell_AI/backend/venv/lib/python3.12/site-packages/uvicorn/middleware/proxy_headers.py", line 60, in __call__
    return await self.app(scope, receive, send)
           ^^^^^^^^^^^^^^^^^^^^^^^^^^^^^^^^^^^^
  File "/Users/sathishkesavan/Hackwell_AI/backend/venv/lib/python3.12/site-packages/fastapi/applications.py", line 1054, in __call__
    await super().__call__(scope, receive, send)
  File "/Users/sathishkesavan/Hackwell_AI/backend/venv/lib/python3.12/site-packages/starlette/applications.py", line 113, in __call__
    await self.middleware_stack(scope, receive, send)
  File "/Users/sathishkesavan/Hackwell_AI/backend/venv/lib/python3.12/site-packages/starlette/middleware/errors.py", line 186, in __call__
    raise exc
  File "/Users/sathishkesavan/Hackwell_AI/backend/venv/lib/python3.12/site-packages/starlette/middleware/errors.py", line 164, in __call__
    await self.app(scope, receive, _send)
  File "/Users/sathishkesavan/Hackwell_AI/backend/venv/lib/python3.12/site-packages/starlette/middleware/cors.py", line 93, in __call__
    await self.simple_response(scope, receive, send, request_headers=headers)
  File "/Users/sathishkesavan/Hackwell_AI/backend/venv/lib/python3.12/site-packages/starlette/middleware/cors.py", line 144, in simple_response
    await self.app(scope, receive, send)
  File "/Users/sathishkesavan/Hackwell_AI/backend/venv/lib/python3.12/site-packages/starlette/middleware/exceptions.py", line 63, in __call__
    await wrap_app_handling_exceptions(self.app, conn)(scope, receive, send)
  File "/Users/sathishkesavan/Hackwell_AI/backend/venv/lib/python3.12/site-packages/starlette/_exception_handler.py", line 53, in wrapped_app
    raise exc
  File "/Users/sathishkesavan/Hackwell_AI/backend/venv/lib/python3.12/site-packages/starlette/_exception_handler.py", line 42, in wrapped_app
    await app(scope, receive, sender)
  File "/Users/sathishkesavan/Hackwell_AI/backend/venv/lib/python3.12/site-packages/starlette/routing.py", line 716, in __call__
    await self.middleware_stack(scope, receive, send)
  File "/Users/sathishkesavan/Hackwell_AI/backend/venv/lib/python3.12/site-packages/starlette/routing.py", line 736, in app
    await route.handle(scope, receive, send)
  File "/Users/sathishkesavan/Hackwell_AI/backend/venv/lib/python3.12/site-packages/starlette/routing.py", line 290, in handle
    await self.app(scope, receive, send)
  File "/Users/sathishkesavan/Hackwell_AI/backend/venv/lib/python3.12/site-packages/starlette/routing.py", line 78, in app
    await wrap_app_handling_exceptions(app, request)(scope, receive, send)
  File "/Users/sathishkesavan/Hackwell_AI/backend/venv/lib/python3.12/site-packages/starlette/_exception_handler.py", line 53, in wrapped_app
    raise exc
  File "/Users/sathishkesavan/Hackwell_AI/backend/venv/lib/python3.12/site-packages/starlette/_exception_handler.py", line 42, in wrapped_app
    await app(scope, receive, sender)
  File "/Users/sathishkesavan/Hackwell_AI/backend/venv/lib/python3.12/site-packages/starlette/routing.py", line 75, in app
    response = await f(request)
               ^^^^^^^^^^^^^^^^
  File "/Users/sathishkesavan/Hackwell_AI/backend/venv/lib/python3.12/site-packages/fastapi/routing.py", line 328, in app
    content = await serialize_response(
              ^^^^^^^^^^^^^^^^^^^^^^^^^
  File "/Users/sathishkesavan/Hackwell_AI/backend/venv/lib/python3.12/site-packages/fastapi/routing.py", line 177, in serialize_response
    raise ResponseValidationError(
fastapi.exceptions.ResponseValidationError: 1 validation errors:
  {'type': 'string_type', 'loc': ('response', 3, 'date_of_birth'), 'msg': 'Input should be a valid string', 'input': None}

INFO:     127.0.0.1:55368 - "GET /api/analytics/overview HTTP/1.1" 200 OK
INFO:     127.0.0.1:55366 - "GET /api/patients/?skip=0&limit=4 HTTP/1.1" 500 Internal Server Error
ERROR:    Exception in ASGI application
Traceback (most recent call last):
  File "/Users/sathishkesavan/Hackwell_AI/backend/venv/lib/python3.12/site-packages/uvicorn/protocols/http/h11_impl.py", line 403, in run_asgi
    result = await app(  # type: ignore[func-returns-value]
             ^^^^^^^^^^^^^^^^^^^^^^^^^^^^^^^^^^^^^^^^^^^^^^
  File "/Users/sathishkesavan/Hackwell_AI/backend/venv/lib/python3.12/site-packages/uvicorn/middleware/proxy_headers.py", line 60, in __call__
    return await self.app(scope, receive, send)
           ^^^^^^^^^^^^^^^^^^^^^^^^^^^^^^^^^^^^
  File "/Users/sathishkesavan/Hackwell_AI/backend/venv/lib/python3.12/site-packages/fastapi/applications.py", line 1054, in __call__
    await super().__call__(scope, receive, send)
  File "/Users/sathishkesavan/Hackwell_AI/backend/venv/lib/python3.12/site-packages/starlette/applications.py", line 113, in __call__
    await self.middleware_stack(scope, receive, send)
  File "/Users/sathishkesavan/Hackwell_AI/backend/venv/lib/python3.12/site-packages/starlette/middleware/errors.py", line 186, in __call__
    raise exc
  File "/Users/sathishkesavan/Hackwell_AI/backend/venv/lib/python3.12/site-packages/starlette/middleware/errors.py", line 164, in __call__
    await self.app(scope, receive, _send)
  File "/Users/sathishkesavan/Hackwell_AI/backend/venv/lib/python3.12/site-packages/starlette/middleware/cors.py", line 93, in __call__
    await self.simple_response(scope, receive, send, request_headers=headers)
  File "/Users/sathishkesavan/Hackwell_AI/backend/venv/lib/python3.12/site-packages/starlette/middleware/cors.py", line 144, in simple_response
    await self.app(scope, receive, send)
  File "/Users/sathishkesavan/Hackwell_AI/backend/venv/lib/python3.12/site-packages/starlette/middleware/exceptions.py", line 63, in __call__
    await wrap_app_handling_exceptions(self.app, conn)(scope, receive, send)
  File "/Users/sathishkesavan/Hackwell_AI/backend/venv/lib/python3.12/site-packages/starlette/_exception_handler.py", line 53, in wrapped_app
    raise exc
  File "/Users/sathishkesavan/Hackwell_AI/backend/venv/lib/python3.12/site-packages/starlette/_exception_handler.py", line 42, in wrapped_app
    await app(scope, receive, sender)
  File "/Users/sathishkesavan/Hackwell_AI/backend/venv/lib/python3.12/site-packages/starlette/routing.py", line 716, in __call__
    await self.middleware_stack(scope, receive, send)
  File "/Users/sathishkesavan/Hackwell_AI/backend/venv/lib/python3.12/site-packages/starlette/routing.py", line 736, in app
    await route.handle(scope, receive, send)
  File "/Users/sathishkesavan/Hackwell_AI/backend/venv/lib/python3.12/site-packages/starlette/routing.py", line 290, in handle
    await self.app(scope, receive, send)
  File "/Users/sathishkesavan/Hackwell_AI/backend/venv/lib/python3.12/site-packages/starlette/routing.py", line 78, in app
    await wrap_app_handling_exceptions(app, request)(scope, receive, send)
  File "/Users/sathishkesavan/Hackwell_AI/backend/venv/lib/python3.12/site-packages/starlette/_exception_handler.py", line 53, in wrapped_app
    raise exc
  File "/Users/sathishkesavan/Hackwell_AI/backend/venv/lib/python3.12/site-packages/starlette/_exception_handler.py", line 42, in wrapped_app
    await app(scope, receive, sender)
  File "/Users/sathishkesavan/Hackwell_AI/backend/venv/lib/python3.12/site-packages/starlette/routing.py", line 75, in app
    response = await f(request)
               ^^^^^^^^^^^^^^^^
  File "/Users/sathishkesavan/Hackwell_AI/backend/venv/lib/python3.12/site-packages/fastapi/routing.py", line 328, in app
    content = await serialize_response(
              ^^^^^^^^^^^^^^^^^^^^^^^^^
  File "/Users/sathishkesavan/Hackwell_AI/backend/venv/lib/python3.12/site-packages/fastapi/routing.py", line 177, in serialize_response
    raise ResponseValidationError(
fastapi.exceptions.ResponseValidationError: 1 validation errors:
  {'type': 'string_type', 'loc': ('response', 3, 'date_of_birth'), 'msg': 'Input should be a valid string', 'input': None}

INFO:     127.0.0.1:55368 - "GET /api/patients/?skip=0&limit=4 HTTP/1.1" 500 Internal Server Error
ERROR:    Exception in ASGI application
Traceback (most recent call last):
  File "/Users/sathishkesavan/Hackwell_AI/backend/venv/lib/python3.12/site-packages/uvicorn/protocols/http/h11_impl.py", line 403, in run_asgi
    result = await app(  # type: ignore[func-returns-value]
             ^^^^^^^^^^^^^^^^^^^^^^^^^^^^^^^^^^^^^^^^^^^^^^
  File "/Users/sathishkesavan/Hackwell_AI/backend/venv/lib/python3.12/site-packages/uvicorn/middleware/proxy_headers.py", line 60, in __call__
    return await self.app(scope, receive, send)
           ^^^^^^^^^^^^^^^^^^^^^^^^^^^^^^^^^^^^
  File "/Users/sathishkesavan/Hackwell_AI/backend/venv/lib/python3.12/site-packages/fastapi/applications.py", line 1054, in __call__
    await super().__call__(scope, receive, send)
  File "/Users/sathishkesavan/Hackwell_AI/backend/venv/lib/python3.12/site-packages/starlette/applications.py", line 113, in __call__
    await self.middleware_stack(scope, receive, send)
  File "/Users/sathishkesavan/Hackwell_AI/backend/venv/lib/python3.12/site-packages/starlette/middleware/errors.py", line 186, in __call__
    raise exc
  File "/Users/sathishkesavan/Hackwell_AI/backend/venv/lib/python3.12/site-packages/starlette/middleware/errors.py", line 164, in __call__
    await self.app(scope, receive, _send)
  File "/Users/sathishkesavan/Hackwell_AI/backend/venv/lib/python3.12/site-packages/starlette/middleware/cors.py", line 93, in __call__
    await self.simple_response(scope, receive, send, request_headers=headers)
  File "/Users/sathishkesavan/Hackwell_AI/backend/venv/lib/python3.12/site-packages/starlette/middleware/cors.py", line 144, in simple_response
    await self.app(scope, receive, send)
  File "/Users/sathishkesavan/Hackwell_AI/backend/venv/lib/python3.12/site-packages/starlette/middleware/exceptions.py", line 63, in __call__
    await wrap_app_handling_exceptions(self.app, conn)(scope, receive, send)
  File "/Users/sathishkesavan/Hackwell_AI/backend/venv/lib/python3.12/site-packages/starlette/_exception_handler.py", line 53, in wrapped_app
    raise exc
  File "/Users/sathishkesavan/Hackwell_AI/backend/venv/lib/python3.12/site-packages/starlette/_exception_handler.py", line 42, in wrapped_app
    await app(scope, receive, sender)
  File "/Users/sathishkesavan/Hackwell_AI/backend/venv/lib/python3.12/site-packages/starlette/routing.py", line 716, in __call__
    await self.middleware_stack(scope, receive, send)
  File "/Users/sathishkesavan/Hackwell_AI/backend/venv/lib/python3.12/site-packages/starlette/routing.py", line 736, in app
    await route.handle(scope, receive, send)
  File "/Users/sathishkesavan/Hackwell_AI/backend/venv/lib/python3.12/site-packages/starlette/routing.py", line 290, in handle
    await self.app(scope, receive, send)
  File "/Users/sathishkesavan/Hackwell_AI/backend/venv/lib/python3.12/site-packages/starlette/routing.py", line 78, in app
    await wrap_app_handling_exceptions(app, request)(scope, receive, send)
  File "/Users/sathishkesavan/Hackwell_AI/backend/venv/lib/python3.12/site-packages/starlette/_exception_handler.py", line 53, in wrapped_app
    raise exc
  File "/Users/sathishkesavan/Hackwell_AI/backend/venv/lib/python3.12/site-packages/starlette/_exception_handler.py", line 42, in wrapped_app
    await app(scope, receive, sender)
  File "/Users/sathishkesavan/Hackwell_AI/backend/venv/lib/python3.12/site-packages/starlette/routing.py", line 75, in app
    response = await f(request)
               ^^^^^^^^^^^^^^^^
  File "/Users/sathishkesavan/Hackwell_AI/backend/venv/lib/python3.12/site-packages/fastapi/routing.py", line 328, in app
    content = await serialize_response(
              ^^^^^^^^^^^^^^^^^^^^^^^^^
  File "/Users/sathishkesavan/Hackwell_AI/backend/venv/lib/python3.12/site-packages/fastapi/routing.py", line 177, in serialize_response
    raise ResponseValidationError(
fastapi.exceptions.ResponseValidationError: 1 validation errors:
  {'type': 'string_type', 'loc': ('response', 3, 'date_of_birth'), 'msg': 'Input should be a valid string', 'input': None}

INFO:     127.0.0.1:55372 - "GET /api/patients?skip=0&limit=100 HTTP/1.1" 307 Temporary Redirect
INFO:     127.0.0.1:55372 - "GET /api/patients?skip=0&limit=100 HTTP/1.1" 307 Temporary Redirect
INFO:     127.0.0.1:55374 - "GET /api/patients/?skip=0&limit=100 HTTP/1.1" 500 Internal Server Error
ERROR:    Exception in ASGI application
Traceback (most recent call last):
  File "/Users/sathishkesavan/Hackwell_AI/backend/venv/lib/python3.12/site-packages/uvicorn/protocols/http/h11_impl.py", line 403, in run_asgi
    result = await app(  # type: ignore[func-returns-value]
             ^^^^^^^^^^^^^^^^^^^^^^^^^^^^^^^^^^^^^^^^^^^^^^
  File "/Users/sathishkesavan/Hackwell_AI/backend/venv/lib/python3.12/site-packages/uvicorn/middleware/proxy_headers.py", line 60, in __call__
    return await self.app(scope, receive, send)
           ^^^^^^^^^^^^^^^^^^^^^^^^^^^^^^^^^^^^
  File "/Users/sathishkesavan/Hackwell_AI/backend/venv/lib/python3.12/site-packages/fastapi/applications.py", line 1054, in __call__
    await super().__call__(scope, receive, send)
  File "/Users/sathishkesavan/Hackwell_AI/backend/venv/lib/python3.12/site-packages/starlette/applications.py", line 113, in __call__
    await self.middleware_stack(scope, receive, send)
  File "/Users/sathishkesavan/Hackwell_AI/backend/venv/lib/python3.12/site-packages/starlette/middleware/errors.py", line 186, in __call__
    raise exc
  File "/Users/sathishkesavan/Hackwell_AI/backend/venv/lib/python3.12/site-packages/starlette/middleware/errors.py", line 164, in __call__
    await self.app(scope, receive, _send)
  File "/Users/sathishkesavan/Hackwell_AI/backend/venv/lib/python3.12/site-packages/starlette/middleware/cors.py", line 93, in __call__
    await self.simple_response(scope, receive, send, request_headers=headers)
  File "/Users/sathishkesavan/Hackwell_AI/backend/venv/lib/python3.12/site-packages/starlette/middleware/cors.py", line 144, in simple_response
    await self.app(scope, receive, send)
  File "/Users/sathishkesavan/Hackwell_AI/backend/venv/lib/python3.12/site-packages/starlette/middleware/exceptions.py", line 63, in __call__
    await wrap_app_handling_exceptions(self.app, conn)(scope, receive, send)
  File "/Users/sathishkesavan/Hackwell_AI/backend/venv/lib/python3.12/site-packages/starlette/_exception_handler.py", line 53, in wrapped_app
    raise exc
  File "/Users/sathishkesavan/Hackwell_AI/backend/venv/lib/python3.12/site-packages/starlette/_exception_handler.py", line 42, in wrapped_app
    await app(scope, receive, sender)
  File "/Users/sathishkesavan/Hackwell_AI/backend/venv/lib/python3.12/site-packages/starlette/routing.py", line 716, in __call__
    await self.middleware_stack(scope, receive, send)
  File "/Users/sathishkesavan/Hackwell_AI/backend/venv/lib/python3.12/site-packages/starlette/routing.py", line 736, in app
    await route.handle(scope, receive, send)
  File "/Users/sathishkesavan/Hackwell_AI/backend/venv/lib/python3.12/site-packages/starlette/routing.py", line 290, in handle
    await self.app(scope, receive, send)
  File "/Users/sathishkesavan/Hackwell_AI/backend/venv/lib/python3.12/site-packages/starlette/routing.py", line 78, in app
    await wrap_app_handling_exceptions(app, request)(scope, receive, send)
  File "/Users/sathishkesavan/Hackwell_AI/backend/venv/lib/python3.12/site-packages/starlette/_exception_handler.py", line 53, in wrapped_app
    raise exc
  File "/Users/sathishkesavan/Hackwell_AI/backend/venv/lib/python3.12/site-packages/starlette/_exception_handler.py", line 42, in wrapped_app
    await app(scope, receive, sender)
  File "/Users/sathishkesavan/Hackwell_AI/backend/venv/lib/python3.12/site-packages/starlette/routing.py", line 75, in app
    response = await f(request)
               ^^^^^^^^^^^^^^^^
  File "/Users/sathishkesavan/Hackwell_AI/backend/venv/lib/python3.12/site-packages/fastapi/routing.py", line 328, in app
    content = await serialize_response(
              ^^^^^^^^^^^^^^^^^^^^^^^^^
  File "/Users/sathishkesavan/Hackwell_AI/backend/venv/lib/python3.12/site-packages/fastapi/routing.py", line 177, in serialize_response
    raise ResponseValidationError(
fastapi.exceptions.ResponseValidationError: 1 validation errors:
  {'type': 'string_type', 'loc': ('response', 3, 'date_of_birth'), 'msg': 'Input should be a valid string', 'input': None}

INFO:     127.0.0.1:55372 - "GET /api/patients/?skip=0&limit=100 HTTP/1.1" 500 Internal Server Error
ERROR:    Exception in ASGI application
Traceback (most recent call last):
  File "/Users/sathishkesavan/Hackwell_AI/backend/venv/lib/python3.12/site-packages/uvicorn/protocols/http/h11_impl.py", line 403, in run_asgi
    result = await app(  # type: ignore[func-returns-value]
             ^^^^^^^^^^^^^^^^^^^^^^^^^^^^^^^^^^^^^^^^^^^^^^
  File "/Users/sathishkesavan/Hackwell_AI/backend/venv/lib/python3.12/site-packages/uvicorn/middleware/proxy_headers.py", line 60, in __call__
    return await self.app(scope, receive, send)
           ^^^^^^^^^^^^^^^^^^^^^^^^^^^^^^^^^^^^
  File "/Users/sathishkesavan/Hackwell_AI/backend/venv/lib/python3.12/site-packages/fastapi/applications.py", line 1054, in __call__
    await super().__call__(scope, receive, send)
  File "/Users/sathishkesavan/Hackwell_AI/backend/venv/lib/python3.12/site-packages/starlette/applications.py", line 113, in __call__
    await self.middleware_stack(scope, receive, send)
  File "/Users/sathishkesavan/Hackwell_AI/backend/venv/lib/python3.12/site-packages/starlette/middleware/errors.py", line 186, in __call__
    raise exc
  File "/Users/sathishkesavan/Hackwell_AI/backend/venv/lib/python3.12/site-packages/starlette/middleware/errors.py", line 164, in __call__
    await self.app(scope, receive, _send)
  File "/Users/sathishkesavan/Hackwell_AI/backend/venv/lib/python3.12/site-packages/starlette/middleware/cors.py", line 93, in __call__
    await self.simple_response(scope, receive, send, request_headers=headers)
  File "/Users/sathishkesavan/Hackwell_AI/backend/venv/lib/python3.12/site-packages/starlette/middleware/cors.py", line 144, in simple_response
    await self.app(scope, receive, send)
  File "/Users/sathishkesavan/Hackwell_AI/backend/venv/lib/python3.12/site-packages/starlette/middleware/exceptions.py", line 63, in __call__
    await wrap_app_handling_exceptions(self.app, conn)(scope, receive, send)
  File "/Users/sathishkesavan/Hackwell_AI/backend/venv/lib/python3.12/site-packages/starlette/_exception_handler.py", line 53, in wrapped_app
    raise exc
  File "/Users/sathishkesavan/Hackwell_AI/backend/venv/lib/python3.12/site-packages/starlette/_exception_handler.py", line 42, in wrapped_app
    await app(scope, receive, sender)
  File "/Users/sathishkesavan/Hackwell_AI/backend/venv/lib/python3.12/site-packages/starlette/routing.py", line 716, in __call__
    await self.middleware_stack(scope, receive, send)
  File "/Users/sathishkesavan/Hackwell_AI/backend/venv/lib/python3.12/site-packages/starlette/routing.py", line 736, in app
    await route.handle(scope, receive, send)
  File "/Users/sathishkesavan/Hackwell_AI/backend/venv/lib/python3.12/site-packages/starlette/routing.py", line 290, in handle
    await self.app(scope, receive, send)
  File "/Users/sathishkesavan/Hackwell_AI/backend/venv/lib/python3.12/site-packages/starlette/routing.py", line 78, in app
    await wrap_app_handling_exceptions(app, request)(scope, receive, send)
  File "/Users/sathishkesavan/Hackwell_AI/backend/venv/lib/python3.12/site-packages/starlette/_exception_handler.py", line 53, in wrapped_app
    raise exc
  File "/Users/sathishkesavan/Hackwell_AI/backend/venv/lib/python3.12/site-packages/starlette/_exception_handler.py", line 42, in wrapped_app
    await app(scope, receive, sender)
  File "/Users/sathishkesavan/Hackwell_AI/backend/venv/lib/python3.12/site-packages/starlette/routing.py", line 75, in app
    response = await f(request)
               ^^^^^^^^^^^^^^^^
  File "/Users/sathishkesavan/Hackwell_AI/backend/venv/lib/python3.12/site-packages/fastapi/routing.py", line 328, in app
    content = await serialize_response(
              ^^^^^^^^^^^^^^^^^^^^^^^^^
  File "/Users/sathishkesavan/Hackwell_AI/backend/venv/lib/python3.12/site-packages/fastapi/routing.py", line 177, in serialize_response
    raise ResponseValidationError(
fastapi.exceptions.ResponseValidationError: 1 validation errors:
  {'type': 'string_type', 'loc': ('response', 3, 'date_of_birth'), 'msg': 'Input should be a valid string', 'input': None}

INFO:     127.0.0.1:55376 - "GET /api/patients/?skip=0&limit=100 HTTP/1.1" 500 Internal Server Error
ERROR:    Exception in ASGI application
Traceback (most recent call last):
  File "/Users/sathishkesavan/Hackwell_AI/backend/venv/lib/python3.12/site-packages/uvicorn/protocols/http/h11_impl.py", line 403, in run_asgi
    result = await app(  # type: ignore[func-returns-value]
             ^^^^^^^^^^^^^^^^^^^^^^^^^^^^^^^^^^^^^^^^^^^^^^
  File "/Users/sathishkesavan/Hackwell_AI/backend/venv/lib/python3.12/site-packages/uvicorn/middleware/proxy_headers.py", line 60, in __call__
    return await self.app(scope, receive, send)
           ^^^^^^^^^^^^^^^^^^^^^^^^^^^^^^^^^^^^
  File "/Users/sathishkesavan/Hackwell_AI/backend/venv/lib/python3.12/site-packages/fastapi/applications.py", line 1054, in __call__
    await super().__call__(scope, receive, send)
  File "/Users/sathishkesavan/Hackwell_AI/backend/venv/lib/python3.12/site-packages/starlette/applications.py", line 113, in __call__
    await self.middleware_stack(scope, receive, send)
  File "/Users/sathishkesavan/Hackwell_AI/backend/venv/lib/python3.12/site-packages/starlette/middleware/errors.py", line 186, in __call__
    raise exc
  File "/Users/sathishkesavan/Hackwell_AI/backend/venv/lib/python3.12/site-packages/starlette/middleware/errors.py", line 164, in __call__
    await self.app(scope, receive, _send)
  File "/Users/sathishkesavan/Hackwell_AI/backend/venv/lib/python3.12/site-packages/starlette/middleware/cors.py", line 93, in __call__
    await self.simple_response(scope, receive, send, request_headers=headers)
  File "/Users/sathishkesavan/Hackwell_AI/backend/venv/lib/python3.12/site-packages/starlette/middleware/cors.py", line 144, in simple_response
    await self.app(scope, receive, send)
  File "/Users/sathishkesavan/Hackwell_AI/backend/venv/lib/python3.12/site-packages/starlette/middleware/exceptions.py", line 63, in __call__
    await wrap_app_handling_exceptions(self.app, conn)(scope, receive, send)
  File "/Users/sathishkesavan/Hackwell_AI/backend/venv/lib/python3.12/site-packages/starlette/_exception_handler.py", line 53, in wrapped_app
    raise exc
  File "/Users/sathishkesavan/Hackwell_AI/backend/venv/lib/python3.12/site-packages/starlette/_exception_handler.py", line 42, in wrapped_app
    await app(scope, receive, sender)
  File "/Users/sathishkesavan/Hackwell_AI/backend/venv/lib/python3.12/site-packages/starlette/routing.py", line 716, in __call__
    await self.middleware_stack(scope, receive, send)
  File "/Users/sathishkesavan/Hackwell_AI/backend/venv/lib/python3.12/site-packages/starlette/routing.py", line 736, in app
    await route.handle(scope, receive, send)
  File "/Users/sathishkesavan/Hackwell_AI/backend/venv/lib/python3.12/site-packages/starlette/routing.py", line 290, in handle
    await self.app(scope, receive, send)
  File "/Users/sathishkesavan/Hackwell_AI/backend/venv/lib/python3.12/site-packages/starlette/routing.py", line 78, in app
    await wrap_app_handling_exceptions(app, request)(scope, receive, send)
  File "/Users/sathishkesavan/Hackwell_AI/backend/venv/lib/python3.12/site-packages/starlette/_exception_handler.py", line 53, in wrapped_app
    raise exc
  File "/Users/sathishkesavan/Hackwell_AI/backend/venv/lib/python3.12/site-packages/starlette/_exception_handler.py", line 42, in wrapped_app
    await app(scope, receive, sender)
  File "/Users/sathishkesavan/Hackwell_AI/backend/venv/lib/python3.12/site-packages/starlette/routing.py", line 75, in app
    response = await f(request)
               ^^^^^^^^^^^^^^^^
  File "/Users/sathishkesavan/Hackwell_AI/backend/venv/lib/python3.12/site-packages/fastapi/routing.py", line 328, in app
    content = await serialize_response(
              ^^^^^^^^^^^^^^^^^^^^^^^^^
  File "/Users/sathishkesavan/Hackwell_AI/backend/venv/lib/python3.12/site-packages/fastapi/routing.py", line 177, in serialize_response
    raise ResponseValidationError(
fastapi.exceptions.ResponseValidationError: 1 validation errors:
  {'type': 'string_type', 'loc': ('response', 3, 'date_of_birth'), 'msg': 'Input should be a valid string', 'input': None}

INFO:     127.0.0.1:55380 - "GET /api/patients?skip=0&limit=4 HTTP/1.1" 307 Temporary Redirect
INFO:     127.0.0.1:55380 - "GET /api/patients?skip=0&limit=4 HTTP/1.1" 307 Temporary Redirect
INFO:     127.0.0.1:55378 - "GET /api/analytics/overview HTTP/1.1" 200 OK
INFO:     127.0.0.1:55382 - "GET /api/patients/?skip=0&limit=4 HTTP/1.1" 500 Internal Server Error
ERROR:    Exception in ASGI application
Traceback (most recent call last):
  File "/Users/sathishkesavan/Hackwell_AI/backend/venv/lib/python3.12/site-packages/uvicorn/protocols/http/h11_impl.py", line 403, in run_asgi
    result = await app(  # type: ignore[func-returns-value]
             ^^^^^^^^^^^^^^^^^^^^^^^^^^^^^^^^^^^^^^^^^^^^^^
  File "/Users/sathishkesavan/Hackwell_AI/backend/venv/lib/python3.12/site-packages/uvicorn/middleware/proxy_headers.py", line 60, in __call__
    return await self.app(scope, receive, send)
           ^^^^^^^^^^^^^^^^^^^^^^^^^^^^^^^^^^^^
  File "/Users/sathishkesavan/Hackwell_AI/backend/venv/lib/python3.12/site-packages/fastapi/applications.py", line 1054, in __call__
    await super().__call__(scope, receive, send)
  File "/Users/sathishkesavan/Hackwell_AI/backend/venv/lib/python3.12/site-packages/starlette/applications.py", line 113, in __call__
    await self.middleware_stack(scope, receive, send)
  File "/Users/sathishkesavan/Hackwell_AI/backend/venv/lib/python3.12/site-packages/starlette/middleware/errors.py", line 186, in __call__
    raise exc
  File "/Users/sathishkesavan/Hackwell_AI/backend/venv/lib/python3.12/site-packages/starlette/middleware/errors.py", line 164, in __call__
    await self.app(scope, receive, _send)
  File "/Users/sathishkesavan/Hackwell_AI/backend/venv/lib/python3.12/site-packages/starlette/middleware/cors.py", line 93, in __call__
    await self.simple_response(scope, receive, send, request_headers=headers)
  File "/Users/sathishkesavan/Hackwell_AI/backend/venv/lib/python3.12/site-packages/starlette/middleware/cors.py", line 144, in simple_response
    await self.app(scope, receive, send)
  File "/Users/sathishkesavan/Hackwell_AI/backend/venv/lib/python3.12/site-packages/starlette/middleware/exceptions.py", line 63, in __call__
    await wrap_app_handling_exceptions(self.app, conn)(scope, receive, send)
  File "/Users/sathishkesavan/Hackwell_AI/backend/venv/lib/python3.12/site-packages/starlette/_exception_handler.py", line 53, in wrapped_app
    raise exc
  File "/Users/sathishkesavan/Hackwell_AI/backend/venv/lib/python3.12/site-packages/starlette/_exception_handler.py", line 42, in wrapped_app
    await app(scope, receive, sender)
  File "/Users/sathishkesavan/Hackwell_AI/backend/venv/lib/python3.12/site-packages/starlette/routing.py", line 716, in __call__
    await self.middleware_stack(scope, receive, send)
  File "/Users/sathishkesavan/Hackwell_AI/backend/venv/lib/python3.12/site-packages/starlette/routing.py", line 736, in app
    await route.handle(scope, receive, send)
  File "/Users/sathishkesavan/Hackwell_AI/backend/venv/lib/python3.12/site-packages/starlette/routing.py", line 290, in handle
    await self.app(scope, receive, send)
  File "/Users/sathishkesavan/Hackwell_AI/backend/venv/lib/python3.12/site-packages/starlette/routing.py", line 78, in app
    await wrap_app_handling_exceptions(app, request)(scope, receive, send)
  File "/Users/sathishkesavan/Hackwell_AI/backend/venv/lib/python3.12/site-packages/starlette/_exception_handler.py", line 53, in wrapped_app
    raise exc
  File "/Users/sathishkesavan/Hackwell_AI/backend/venv/lib/python3.12/site-packages/starlette/_exception_handler.py", line 42, in wrapped_app
    await app(scope, receive, sender)
  File "/Users/sathishkesavan/Hackwell_AI/backend/venv/lib/python3.12/site-packages/starlette/routing.py", line 75, in app
    response = await f(request)
               ^^^^^^^^^^^^^^^^
  File "/Users/sathishkesavan/Hackwell_AI/backend/venv/lib/python3.12/site-packages/fastapi/routing.py", line 328, in app
    content = await serialize_response(
              ^^^^^^^^^^^^^^^^^^^^^^^^^
  File "/Users/sathishkesavan/Hackwell_AI/backend/venv/lib/python3.12/site-packages/fastapi/routing.py", line 177, in serialize_response
    raise ResponseValidationError(
fastapi.exceptions.ResponseValidationError: 1 validation errors:
  {'type': 'string_type', 'loc': ('response', 3, 'date_of_birth'), 'msg': 'Input should be a valid string', 'input': None}

INFO:     127.0.0.1:55378 - "GET /api/patients/?skip=0&limit=4 HTTP/1.1" 500 Internal Server Error
ERROR:    Exception in ASGI application
Traceback (most recent call last):
  File "/Users/sathishkesavan/Hackwell_AI/backend/venv/lib/python3.12/site-packages/uvicorn/protocols/http/h11_impl.py", line 403, in run_asgi
    result = await app(  # type: ignore[func-returns-value]
             ^^^^^^^^^^^^^^^^^^^^^^^^^^^^^^^^^^^^^^^^^^^^^^
  File "/Users/sathishkesavan/Hackwell_AI/backend/venv/lib/python3.12/site-packages/uvicorn/middleware/proxy_headers.py", line 60, in __call__
    return await self.app(scope, receive, send)
           ^^^^^^^^^^^^^^^^^^^^^^^^^^^^^^^^^^^^
  File "/Users/sathishkesavan/Hackwell_AI/backend/venv/lib/python3.12/site-packages/fastapi/applications.py", line 1054, in __call__
    await super().__call__(scope, receive, send)
  File "/Users/sathishkesavan/Hackwell_AI/backend/venv/lib/python3.12/site-packages/starlette/applications.py", line 113, in __call__
    await self.middleware_stack(scope, receive, send)
  File "/Users/sathishkesavan/Hackwell_AI/backend/venv/lib/python3.12/site-packages/starlette/middleware/errors.py", line 186, in __call__
    raise exc
  File "/Users/sathishkesavan/Hackwell_AI/backend/venv/lib/python3.12/site-packages/starlette/middleware/errors.py", line 164, in __call__
    await self.app(scope, receive, _send)
  File "/Users/sathishkesavan/Hackwell_AI/backend/venv/lib/python3.12/site-packages/starlette/middleware/cors.py", line 93, in __call__
    await self.simple_response(scope, receive, send, request_headers=headers)
  File "/Users/sathishkesavan/Hackwell_AI/backend/venv/lib/python3.12/site-packages/starlette/middleware/cors.py", line 144, in simple_response
    await self.app(scope, receive, send)
  File "/Users/sathishkesavan/Hackwell_AI/backend/venv/lib/python3.12/site-packages/starlette/middleware/exceptions.py", line 63, in __call__
    await wrap_app_handling_exceptions(self.app, conn)(scope, receive, send)
  File "/Users/sathishkesavan/Hackwell_AI/backend/venv/lib/python3.12/site-packages/starlette/_exception_handler.py", line 53, in wrapped_app
    raise exc
  File "/Users/sathishkesavan/Hackwell_AI/backend/venv/lib/python3.12/site-packages/starlette/_exception_handler.py", line 42, in wrapped_app
    await app(scope, receive, sender)
  File "/Users/sathishkesavan/Hackwell_AI/backend/venv/lib/python3.12/site-packages/starlette/routing.py", line 716, in __call__
    await self.middleware_stack(scope, receive, send)
  File "/Users/sathishkesavan/Hackwell_AI/backend/venv/lib/python3.12/site-packages/starlette/routing.py", line 736, in app
    await route.handle(scope, receive, send)
  File "/Users/sathishkesavan/Hackwell_AI/backend/venv/lib/python3.12/site-packages/starlette/routing.py", line 290, in handle
    await self.app(scope, receive, send)
  File "/Users/sathishkesavan/Hackwell_AI/backend/venv/lib/python3.12/site-packages/starlette/routing.py", line 78, in app
    await wrap_app_handling_exceptions(app, request)(scope, receive, send)
  File "/Users/sathishkesavan/Hackwell_AI/backend/venv/lib/python3.12/site-packages/starlette/_exception_handler.py", line 53, in wrapped_app
    raise exc
  File "/Users/sathishkesavan/Hackwell_AI/backend/venv/lib/python3.12/site-packages/starlette/_exception_handler.py", line 42, in wrapped_app
    await app(scope, receive, sender)
  File "/Users/sathishkesavan/Hackwell_AI/backend/venv/lib/python3.12/site-packages/starlette/routing.py", line 75, in app
    response = await f(request)
               ^^^^^^^^^^^^^^^^
  File "/Users/sathishkesavan/Hackwell_AI/backend/venv/lib/python3.12/site-packages/fastapi/routing.py", line 328, in app
    content = await serialize_response(
              ^^^^^^^^^^^^^^^^^^^^^^^^^
  File "/Users/sathishkesavan/Hackwell_AI/backend/venv/lib/python3.12/site-packages/fastapi/routing.py", line 177, in serialize_response
    raise ResponseValidationError(
fastapi.exceptions.ResponseValidationError: 1 validation errors:
  {'type': 'string_type', 'loc': ('response', 3, 'date_of_birth'), 'msg': 'Input should be a valid string', 'input': None}

INFO:     127.0.0.1:55380 - "GET /api/analytics/overview HTTP/1.1" 200 OK
INFO:     127.0.0.1:55384 - "GET /api/patients/?skip=0&limit=4 HTTP/1.1" 500 Internal Server Error
ERROR:    Exception in ASGI application
Traceback (most recent call last):
  File "/Users/sathishkesavan/Hackwell_AI/backend/venv/lib/python3.12/site-packages/uvicorn/protocols/http/h11_impl.py", line 403, in run_asgi
    result = await app(  # type: ignore[func-returns-value]
             ^^^^^^^^^^^^^^^^^^^^^^^^^^^^^^^^^^^^^^^^^^^^^^
  File "/Users/sathishkesavan/Hackwell_AI/backend/venv/lib/python3.12/site-packages/uvicorn/middleware/proxy_headers.py", line 60, in __call__
    return await self.app(scope, receive, send)
           ^^^^^^^^^^^^^^^^^^^^^^^^^^^^^^^^^^^^
  File "/Users/sathishkesavan/Hackwell_AI/backend/venv/lib/python3.12/site-packages/fastapi/applications.py", line 1054, in __call__
    await super().__call__(scope, receive, send)
  File "/Users/sathishkesavan/Hackwell_AI/backend/venv/lib/python3.12/site-packages/starlette/applications.py", line 113, in __call__
    await self.middleware_stack(scope, receive, send)
  File "/Users/sathishkesavan/Hackwell_AI/backend/venv/lib/python3.12/site-packages/starlette/middleware/errors.py", line 186, in __call__
    raise exc
  File "/Users/sathishkesavan/Hackwell_AI/backend/venv/lib/python3.12/site-packages/starlette/middleware/errors.py", line 164, in __call__
    await self.app(scope, receive, _send)
  File "/Users/sathishkesavan/Hackwell_AI/backend/venv/lib/python3.12/site-packages/starlette/middleware/cors.py", line 93, in __call__
    await self.simple_response(scope, receive, send, request_headers=headers)
  File "/Users/sathishkesavan/Hackwell_AI/backend/venv/lib/python3.12/site-packages/starlette/middleware/cors.py", line 144, in simple_response
    await self.app(scope, receive, send)
  File "/Users/sathishkesavan/Hackwell_AI/backend/venv/lib/python3.12/site-packages/starlette/middleware/exceptions.py", line 63, in __call__
    await wrap_app_handling_exceptions(self.app, conn)(scope, receive, send)
  File "/Users/sathishkesavan/Hackwell_AI/backend/venv/lib/python3.12/site-packages/starlette/_exception_handler.py", line 53, in wrapped_app
    raise exc
  File "/Users/sathishkesavan/Hackwell_AI/backend/venv/lib/python3.12/site-packages/starlette/_exception_handler.py", line 42, in wrapped_app
    await app(scope, receive, sender)
  File "/Users/sathishkesavan/Hackwell_AI/backend/venv/lib/python3.12/site-packages/starlette/routing.py", line 716, in __call__
    await self.middleware_stack(scope, receive, send)
  File "/Users/sathishkesavan/Hackwell_AI/backend/venv/lib/python3.12/site-packages/starlette/routing.py", line 736, in app
    await route.handle(scope, receive, send)
  File "/Users/sathishkesavan/Hackwell_AI/backend/venv/lib/python3.12/site-packages/starlette/routing.py", line 290, in handle
    await self.app(scope, receive, send)
  File "/Users/sathishkesavan/Hackwell_AI/backend/venv/lib/python3.12/site-packages/starlette/routing.py", line 78, in app
    await wrap_app_handling_exceptions(app, request)(scope, receive, send)
  File "/Users/sathishkesavan/Hackwell_AI/backend/venv/lib/python3.12/site-packages/starlette/_exception_handler.py", line 53, in wrapped_app
    raise exc
  File "/Users/sathishkesavan/Hackwell_AI/backend/venv/lib/python3.12/site-packages/starlette/_exception_handler.py", line 42, in wrapped_app
    await app(scope, receive, sender)
  File "/Users/sathishkesavan/Hackwell_AI/backend/venv/lib/python3.12/site-packages/starlette/routing.py", line 75, in app
    response = await f(request)
               ^^^^^^^^^^^^^^^^
  File "/Users/sathishkesavan/Hackwell_AI/backend/venv/lib/python3.12/site-packages/fastapi/routing.py", line 328, in app
    content = await serialize_response(
              ^^^^^^^^^^^^^^^^^^^^^^^^^
  File "/Users/sathishkesavan/Hackwell_AI/backend/venv/lib/python3.12/site-packages/fastapi/routing.py", line 177, in serialize_response
    raise ResponseValidationError(
fastapi.exceptions.ResponseValidationError: 1 validation errors:
  {'type': 'string_type', 'loc': ('response', 3, 'date_of_birth'), 'msg': 'Input should be a valid string', 'input': None}

INFO:     127.0.0.1:55403 - "GET /api/patients?skip=0&limit=4 HTTP/1.1" 307 Temporary Redirect
INFO:     127.0.0.1:55403 - "GET /api/patients?skip=0&limit=4 HTTP/1.1" 307 Temporary Redirect
INFO:     127.0.0.1:55405 - "GET /api/patients/?skip=0&limit=4 HTTP/1.1" 500 Internal Server Error
ERROR:    Exception in ASGI application
Traceback (most recent call last):
  File "/Users/sathishkesavan/Hackwell_AI/backend/venv/lib/python3.12/site-packages/uvicorn/protocols/http/h11_impl.py", line 403, in run_asgi
    result = await app(  # type: ignore[func-returns-value]
             ^^^^^^^^^^^^^^^^^^^^^^^^^^^^^^^^^^^^^^^^^^^^^^
  File "/Users/sathishkesavan/Hackwell_AI/backend/venv/lib/python3.12/site-packages/uvicorn/middleware/proxy_headers.py", line 60, in __call__
    return await self.app(scope, receive, send)
           ^^^^^^^^^^^^^^^^^^^^^^^^^^^^^^^^^^^^
  File "/Users/sathishkesavan/Hackwell_AI/backend/venv/lib/python3.12/site-packages/fastapi/applications.py", line 1054, in __call__
    await super().__call__(scope, receive, send)
  File "/Users/sathishkesavan/Hackwell_AI/backend/venv/lib/python3.12/site-packages/starlette/applications.py", line 113, in __call__
    await self.middleware_stack(scope, receive, send)
  File "/Users/sathishkesavan/Hackwell_AI/backend/venv/lib/python3.12/site-packages/starlette/middleware/errors.py", line 186, in __call__
    raise exc
  File "/Users/sathishkesavan/Hackwell_AI/backend/venv/lib/python3.12/site-packages/starlette/middleware/errors.py", line 164, in __call__
    await self.app(scope, receive, _send)
  File "/Users/sathishkesavan/Hackwell_AI/backend/venv/lib/python3.12/site-packages/starlette/middleware/cors.py", line 93, in __call__
    await self.simple_response(scope, receive, send, request_headers=headers)
  File "/Users/sathishkesavan/Hackwell_AI/backend/venv/lib/python3.12/site-packages/starlette/middleware/cors.py", line 144, in simple_response
    await self.app(scope, receive, send)
  File "/Users/sathishkesavan/Hackwell_AI/backend/venv/lib/python3.12/site-packages/starlette/middleware/exceptions.py", line 63, in __call__
    await wrap_app_handling_exceptions(self.app, conn)(scope, receive, send)
  File "/Users/sathishkesavan/Hackwell_AI/backend/venv/lib/python3.12/site-packages/starlette/_exception_handler.py", line 53, in wrapped_app
    raise exc
  File "/Users/sathishkesavan/Hackwell_AI/backend/venv/lib/python3.12/site-packages/starlette/_exception_handler.py", line 42, in wrapped_app
    await app(scope, receive, sender)
  File "/Users/sathishkesavan/Hackwell_AI/backend/venv/lib/python3.12/site-packages/starlette/routing.py", line 716, in __call__
    await self.middleware_stack(scope, receive, send)
  File "/Users/sathishkesavan/Hackwell_AI/backend/venv/lib/python3.12/site-packages/starlette/routing.py", line 736, in app
    await route.handle(scope, receive, send)
  File "/Users/sathishkesavan/Hackwell_AI/backend/venv/lib/python3.12/site-packages/starlette/routing.py", line 290, in handle
    await self.app(scope, receive, send)
  File "/Users/sathishkesavan/Hackwell_AI/backend/venv/lib/python3.12/site-packages/starlette/routing.py", line 78, in app
    await wrap_app_handling_exceptions(app, request)(scope, receive, send)
  File "/Users/sathishkesavan/Hackwell_AI/backend/venv/lib/python3.12/site-packages/starlette/_exception_handler.py", line 53, in wrapped_app
    raise exc
  File "/Users/sathishkesavan/Hackwell_AI/backend/venv/lib/python3.12/site-packages/starlette/_exception_handler.py", line 42, in wrapped_app
    await app(scope, receive, sender)
  File "/Users/sathishkesavan/Hackwell_AI/backend/venv/lib/python3.12/site-packages/starlette/routing.py", line 75, in app
    response = await f(request)
               ^^^^^^^^^^^^^^^^
  File "/Users/sathishkesavan/Hackwell_AI/backend/venv/lib/python3.12/site-packages/fastapi/routing.py", line 328, in app
    content = await serialize_response(
              ^^^^^^^^^^^^^^^^^^^^^^^^^
  File "/Users/sathishkesavan/Hackwell_AI/backend/venv/lib/python3.12/site-packages/fastapi/routing.py", line 177, in serialize_response
    raise ResponseValidationError(
fastapi.exceptions.ResponseValidationError: 1 validation errors:
  {'type': 'string_type', 'loc': ('response', 3, 'date_of_birth'), 'msg': 'Input should be a valid string', 'input': None}

INFO:     127.0.0.1:55401 - "GET /api/analytics/overview HTTP/1.1" 200 OK
INFO:     127.0.0.1:55403 - "GET /api/patients/?skip=0&limit=4 HTTP/1.1" 500 Internal Server Error
ERROR:    Exception in ASGI application
Traceback (most recent call last):
  File "/Users/sathishkesavan/Hackwell_AI/backend/venv/lib/python3.12/site-packages/uvicorn/protocols/http/h11_impl.py", line 403, in run_asgi
    result = await app(  # type: ignore[func-returns-value]
             ^^^^^^^^^^^^^^^^^^^^^^^^^^^^^^^^^^^^^^^^^^^^^^
  File "/Users/sathishkesavan/Hackwell_AI/backend/venv/lib/python3.12/site-packages/uvicorn/middleware/proxy_headers.py", line 60, in __call__
    return await self.app(scope, receive, send)
           ^^^^^^^^^^^^^^^^^^^^^^^^^^^^^^^^^^^^
  File "/Users/sathishkesavan/Hackwell_AI/backend/venv/lib/python3.12/site-packages/fastapi/applications.py", line 1054, in __call__
    await super().__call__(scope, receive, send)
  File "/Users/sathishkesavan/Hackwell_AI/backend/venv/lib/python3.12/site-packages/starlette/applications.py", line 113, in __call__
    await self.middleware_stack(scope, receive, send)
  File "/Users/sathishkesavan/Hackwell_AI/backend/venv/lib/python3.12/site-packages/starlette/middleware/errors.py", line 186, in __call__
    raise exc
  File "/Users/sathishkesavan/Hackwell_AI/backend/venv/lib/python3.12/site-packages/starlette/middleware/errors.py", line 164, in __call__
    await self.app(scope, receive, _send)
  File "/Users/sathishkesavan/Hackwell_AI/backend/venv/lib/python3.12/site-packages/starlette/middleware/cors.py", line 93, in __call__
    await self.simple_response(scope, receive, send, request_headers=headers)
  File "/Users/sathishkesavan/Hackwell_AI/backend/venv/lib/python3.12/site-packages/starlette/middleware/cors.py", line 144, in simple_response
    await self.app(scope, receive, send)
  File "/Users/sathishkesavan/Hackwell_AI/backend/venv/lib/python3.12/site-packages/starlette/middleware/exceptions.py", line 63, in __call__
    await wrap_app_handling_exceptions(self.app, conn)(scope, receive, send)
  File "/Users/sathishkesavan/Hackwell_AI/backend/venv/lib/python3.12/site-packages/starlette/_exception_handler.py", line 53, in wrapped_app
    raise exc
  File "/Users/sathishkesavan/Hackwell_AI/backend/venv/lib/python3.12/site-packages/starlette/_exception_handler.py", line 42, in wrapped_app
    await app(scope, receive, sender)
  File "/Users/sathishkesavan/Hackwell_AI/backend/venv/lib/python3.12/site-packages/starlette/routing.py", line 716, in __call__
    await self.middleware_stack(scope, receive, send)
  File "/Users/sathishkesavan/Hackwell_AI/backend/venv/lib/python3.12/site-packages/starlette/routing.py", line 736, in app
    await route.handle(scope, receive, send)
  File "/Users/sathishkesavan/Hackwell_AI/backend/venv/lib/python3.12/site-packages/starlette/routing.py", line 290, in handle
    await self.app(scope, receive, send)
  File "/Users/sathishkesavan/Hackwell_AI/backend/venv/lib/python3.12/site-packages/starlette/routing.py", line 78, in app
    await wrap_app_handling_exceptions(app, request)(scope, receive, send)
  File "/Users/sathishkesavan/Hackwell_AI/backend/venv/lib/python3.12/site-packages/starlette/_exception_handler.py", line 53, in wrapped_app
    raise exc
  File "/Users/sathishkesavan/Hackwell_AI/backend/venv/lib/python3.12/site-packages/starlette/_exception_handler.py", line 42, in wrapped_app
    await app(scope, receive, sender)
  File "/Users/sathishkesavan/Hackwell_AI/backend/venv/lib/python3.12/site-packages/starlette/routing.py", line 75, in app
    response = await f(request)
               ^^^^^^^^^^^^^^^^
  File "/Users/sathishkesavan/Hackwell_AI/backend/venv/lib/python3.12/site-packages/fastapi/routing.py", line 328, in app
    content = await serialize_response(
              ^^^^^^^^^^^^^^^^^^^^^^^^^
  File "/Users/sathishkesavan/Hackwell_AI/backend/venv/lib/python3.12/site-packages/fastapi/routing.py", line 177, in serialize_response
    raise ResponseValidationError(
fastapi.exceptions.ResponseValidationError: 1 validation errors:
  {'type': 'string_type', 'loc': ('response', 3, 'date_of_birth'), 'msg': 'Input should be a valid string', 'input': None}

INFO:     127.0.0.1:55401 - "GET /api/analytics/overview HTTP/1.1" 200 OK
INFO:     127.0.0.1:55407 - "GET /api/patients/?skip=0&limit=4 HTTP/1.1" 500 Internal Server Error
ERROR:    Exception in ASGI application
Traceback (most recent call last):
  File "/Users/sathishkesavan/Hackwell_AI/backend/venv/lib/python3.12/site-packages/uvicorn/protocols/http/h11_impl.py", line 403, in run_asgi
    result = await app(  # type: ignore[func-returns-value]
             ^^^^^^^^^^^^^^^^^^^^^^^^^^^^^^^^^^^^^^^^^^^^^^
  File "/Users/sathishkesavan/Hackwell_AI/backend/venv/lib/python3.12/site-packages/uvicorn/middleware/proxy_headers.py", line 60, in __call__
    return await self.app(scope, receive, send)
           ^^^^^^^^^^^^^^^^^^^^^^^^^^^^^^^^^^^^
  File "/Users/sathishkesavan/Hackwell_AI/backend/venv/lib/python3.12/site-packages/fastapi/applications.py", line 1054, in __call__
    await super().__call__(scope, receive, send)
  File "/Users/sathishkesavan/Hackwell_AI/backend/venv/lib/python3.12/site-packages/starlette/applications.py", line 113, in __call__
    await self.middleware_stack(scope, receive, send)
  File "/Users/sathishkesavan/Hackwell_AI/backend/venv/lib/python3.12/site-packages/starlette/middleware/errors.py", line 186, in __call__
    raise exc
  File "/Users/sathishkesavan/Hackwell_AI/backend/venv/lib/python3.12/site-packages/starlette/middleware/errors.py", line 164, in __call__
    await self.app(scope, receive, _send)
  File "/Users/sathishkesavan/Hackwell_AI/backend/venv/lib/python3.12/site-packages/starlette/middleware/cors.py", line 93, in __call__
    await self.simple_response(scope, receive, send, request_headers=headers)
  File "/Users/sathishkesavan/Hackwell_AI/backend/venv/lib/python3.12/site-packages/starlette/middleware/cors.py", line 144, in simple_response
    await self.app(scope, receive, send)
  File "/Users/sathishkesavan/Hackwell_AI/backend/venv/lib/python3.12/site-packages/starlette/middleware/exceptions.py", line 63, in __call__
    await wrap_app_handling_exceptions(self.app, conn)(scope, receive, send)
  File "/Users/sathishkesavan/Hackwell_AI/backend/venv/lib/python3.12/site-packages/starlette/_exception_handler.py", line 53, in wrapped_app
    raise exc
  File "/Users/sathishkesavan/Hackwell_AI/backend/venv/lib/python3.12/site-packages/starlette/_exception_handler.py", line 42, in wrapped_app
    await app(scope, receive, sender)
  File "/Users/sathishkesavan/Hackwell_AI/backend/venv/lib/python3.12/site-packages/starlette/routing.py", line 716, in __call__
    await self.middleware_stack(scope, receive, send)
  File "/Users/sathishkesavan/Hackwell_AI/backend/venv/lib/python3.12/site-packages/starlette/routing.py", line 736, in app
    await route.handle(scope, receive, send)
  File "/Users/sathishkesavan/Hackwell_AI/backend/venv/lib/python3.12/site-packages/starlette/routing.py", line 290, in handle
    await self.app(scope, receive, send)
  File "/Users/sathishkesavan/Hackwell_AI/backend/venv/lib/python3.12/site-packages/starlette/routing.py", line 78, in app
    await wrap_app_handling_exceptions(app, request)(scope, receive, send)
  File "/Users/sathishkesavan/Hackwell_AI/backend/venv/lib/python3.12/site-packages/starlette/_exception_handler.py", line 53, in wrapped_app
    raise exc
  File "/Users/sathishkesavan/Hackwell_AI/backend/venv/lib/python3.12/site-packages/starlette/_exception_handler.py", line 42, in wrapped_app
    await app(scope, receive, sender)
  File "/Users/sathishkesavan/Hackwell_AI/backend/venv/lib/python3.12/site-packages/starlette/routing.py", line 75, in app
    response = await f(request)
               ^^^^^^^^^^^^^^^^
  File "/Users/sathishkesavan/Hackwell_AI/backend/venv/lib/python3.12/site-packages/fastapi/routing.py", line 328, in app
    content = await serialize_response(
              ^^^^^^^^^^^^^^^^^^^^^^^^^
  File "/Users/sathishkesavan/Hackwell_AI/backend/venv/lib/python3.12/site-packages/fastapi/routing.py", line 177, in serialize_response
    raise ResponseValidationError(
fastapi.exceptions.ResponseValidationError: 1 validation errors:
  {'type': 'string_type', 'loc': ('response', 3, 'date_of_birth'), 'msg': 'Input should be a valid string', 'input': None}

INFO:     127.0.0.1:55435 - "POST /api/auth/login?username=demo_doctor&password=demo123 HTTP/1.1" 200 OK
INFO:     127.0.0.1:55460 - "OPTIONS /api/auth/login HTTP/1.1" 200 OK
INFO:     127.0.0.1:56824 - "OPTIONS /api/auth/login?username=doctor%40hackwell.ai&password=demo123 HTTP/1.1" 400 Bad Request
INFO:     127.0.0.1:56836 - "OPTIONS /api/auth/login?username=doctor%40hackwell.ai&password=demo123 HTTP/1.1" 400 Bad Request
INFO:     127.0.0.1:56974 - "GET /openapi.json HTTP/1.1" 200 OK
INFO:     127.0.0.1:57059 - "GET /openapi.json HTTP/1.1" 200 OK
INFO:     127.0.0.1:57070 - "GET /openapi.json HTTP/1.1" 200 OK
INFO:     127.0.0.1:57097 - "OPTIONS /api/analytics/overview HTTP/1.1" 200 OK
INFO:     127.0.0.1:57099 - "OPTIONS /api/patients?skip=0&limit=4 HTTP/1.1" 200 OK
INFO:     127.0.0.1:57101 - "OPTIONS /api/analytics/overview HTTP/1.1" 200 OK
INFO:     127.0.0.1:57102 - "OPTIONS /api/patients?skip=0&limit=4 HTTP/1.1" 200 OK
INFO:     127.0.0.1:57099 - "GET /api/patients?skip=0&limit=4 HTTP/1.1" 307 Temporary Redirect
INFO:     127.0.0.1:57102 - "GET /api/patients?skip=0&limit=4 HTTP/1.1" 307 Temporary Redirect
INFO:     127.0.0.1:57099 - "OPTIONS /api/patients/?skip=0&limit=4 HTTP/1.1" 200 OK
INFO:     127.0.0.1:57102 - "OPTIONS /api/patients/?skip=0&limit=4 HTTP/1.1" 200 OK
INFO:     127.0.0.1:57099 - "GET /api/patients/?skip=0&limit=4 HTTP/1.1" 500 Internal Server Error
ERROR:    Exception in ASGI application
Traceback (most recent call last):
  File "/Users/sathishkesavan/Hackwell_AI/backend/venv/lib/python3.12/site-packages/uvicorn/protocols/http/h11_impl.py", line 403, in run_asgi
    result = await app(  # type: ignore[func-returns-value]
             ^^^^^^^^^^^^^^^^^^^^^^^^^^^^^^^^^^^^^^^^^^^^^^
  File "/Users/sathishkesavan/Hackwell_AI/backend/venv/lib/python3.12/site-packages/uvicorn/middleware/proxy_headers.py", line 60, in __call__
    return await self.app(scope, receive, send)
           ^^^^^^^^^^^^^^^^^^^^^^^^^^^^^^^^^^^^
  File "/Users/sathishkesavan/Hackwell_AI/backend/venv/lib/python3.12/site-packages/fastapi/applications.py", line 1054, in __call__
    await super().__call__(scope, receive, send)
  File "/Users/sathishkesavan/Hackwell_AI/backend/venv/lib/python3.12/site-packages/starlette/applications.py", line 113, in __call__
    await self.middleware_stack(scope, receive, send)
  File "/Users/sathishkesavan/Hackwell_AI/backend/venv/lib/python3.12/site-packages/starlette/middleware/errors.py", line 186, in __call__
    raise exc
  File "/Users/sathishkesavan/Hackwell_AI/backend/venv/lib/python3.12/site-packages/starlette/middleware/errors.py", line 164, in __call__
    await self.app(scope, receive, _send)
  File "/Users/sathishkesavan/Hackwell_AI/backend/venv/lib/python3.12/site-packages/starlette/middleware/cors.py", line 93, in __call__
    await self.simple_response(scope, receive, send, request_headers=headers)
  File "/Users/sathishkesavan/Hackwell_AI/backend/venv/lib/python3.12/site-packages/starlette/middleware/cors.py", line 144, in simple_response
    await self.app(scope, receive, send)
  File "/Users/sathishkesavan/Hackwell_AI/backend/venv/lib/python3.12/site-packages/starlette/middleware/exceptions.py", line 63, in __call__
    await wrap_app_handling_exceptions(self.app, conn)(scope, receive, send)
  File "/Users/sathishkesavan/Hackwell_AI/backend/venv/lib/python3.12/site-packages/starlette/_exception_handler.py", line 53, in wrapped_app
    raise exc
  File "/Users/sathishkesavan/Hackwell_AI/backend/venv/lib/python3.12/site-packages/starlette/_exception_handler.py", line 42, in wrapped_app
    await app(scope, receive, sender)
  File "/Users/sathishkesavan/Hackwell_AI/backend/venv/lib/python3.12/site-packages/starlette/routing.py", line 716, in __call__
    await self.middleware_stack(scope, receive, send)
  File "/Users/sathishkesavan/Hackwell_AI/backend/venv/lib/python3.12/site-packages/starlette/routing.py", line 736, in app
    await route.handle(scope, receive, send)
  File "/Users/sathishkesavan/Hackwell_AI/backend/venv/lib/python3.12/site-packages/starlette/routing.py", line 290, in handle
    await self.app(scope, receive, send)
  File "/Users/sathishkesavan/Hackwell_AI/backend/venv/lib/python3.12/site-packages/starlette/routing.py", line 78, in app
    await wrap_app_handling_exceptions(app, request)(scope, receive, send)
  File "/Users/sathishkesavan/Hackwell_AI/backend/venv/lib/python3.12/site-packages/starlette/_exception_handler.py", line 53, in wrapped_app
    raise exc
  File "/Users/sathishkesavan/Hackwell_AI/backend/venv/lib/python3.12/site-packages/starlette/_exception_handler.py", line 42, in wrapped_app
    await app(scope, receive, sender)
  File "/Users/sathishkesavan/Hackwell_AI/backend/venv/lib/python3.12/site-packages/starlette/routing.py", line 75, in app
    response = await f(request)
               ^^^^^^^^^^^^^^^^
  File "/Users/sathishkesavan/Hackwell_AI/backend/venv/lib/python3.12/site-packages/fastapi/routing.py", line 328, in app
    content = await serialize_response(
              ^^^^^^^^^^^^^^^^^^^^^^^^^
  File "/Users/sathishkesavan/Hackwell_AI/backend/venv/lib/python3.12/site-packages/fastapi/routing.py", line 177, in serialize_response
    raise ResponseValidationError(
fastapi.exceptions.ResponseValidationError: 1 validation errors:
  {'type': 'string_type', 'loc': ('response', 3, 'date_of_birth'), 'msg': 'Input should be a valid string', 'input': None}

INFO:     127.0.0.1:57097 - "GET /api/analytics/overview HTTP/1.1" 200 OK
INFO:     127.0.0.1:57106 - "GET /api/patients/?skip=0&limit=4 HTTP/1.1" 500 Internal Server Error
ERROR:    Exception in ASGI application
Traceback (most recent call last):
  File "/Users/sathishkesavan/Hackwell_AI/backend/venv/lib/python3.12/site-packages/uvicorn/protocols/http/h11_impl.py", line 403, in run_asgi
    result = await app(  # type: ignore[func-returns-value]
             ^^^^^^^^^^^^^^^^^^^^^^^^^^^^^^^^^^^^^^^^^^^^^^
  File "/Users/sathishkesavan/Hackwell_AI/backend/venv/lib/python3.12/site-packages/uvicorn/middleware/proxy_headers.py", line 60, in __call__
    return await self.app(scope, receive, send)
           ^^^^^^^^^^^^^^^^^^^^^^^^^^^^^^^^^^^^
  File "/Users/sathishkesavan/Hackwell_AI/backend/venv/lib/python3.12/site-packages/fastapi/applications.py", line 1054, in __call__
    await super().__call__(scope, receive, send)
  File "/Users/sathishkesavan/Hackwell_AI/backend/venv/lib/python3.12/site-packages/starlette/applications.py", line 113, in __call__
    await self.middleware_stack(scope, receive, send)
  File "/Users/sathishkesavan/Hackwell_AI/backend/venv/lib/python3.12/site-packages/starlette/middleware/errors.py", line 186, in __call__
    raise exc
  File "/Users/sathishkesavan/Hackwell_AI/backend/venv/lib/python3.12/site-packages/starlette/middleware/errors.py", line 164, in __call__
    await self.app(scope, receive, _send)
  File "/Users/sathishkesavan/Hackwell_AI/backend/venv/lib/python3.12/site-packages/starlette/middleware/cors.py", line 93, in __call__
    await self.simple_response(scope, receive, send, request_headers=headers)
  File "/Users/sathishkesavan/Hackwell_AI/backend/venv/lib/python3.12/site-packages/starlette/middleware/cors.py", line 144, in simple_response
    await self.app(scope, receive, send)
  File "/Users/sathishkesavan/Hackwell_AI/backend/venv/lib/python3.12/site-packages/starlette/middleware/exceptions.py", line 63, in __call__
    await wrap_app_handling_exceptions(self.app, conn)(scope, receive, send)
  File "/Users/sathishkesavan/Hackwell_AI/backend/venv/lib/python3.12/site-packages/starlette/_exception_handler.py", line 53, in wrapped_app
    raise exc
  File "/Users/sathishkesavan/Hackwell_AI/backend/venv/lib/python3.12/site-packages/starlette/_exception_handler.py", line 42, in wrapped_app
    await app(scope, receive, sender)
  File "/Users/sathishkesavan/Hackwell_AI/backend/venv/lib/python3.12/site-packages/starlette/routing.py", line 716, in __call__
    await self.middleware_stack(scope, receive, send)
  File "/Users/sathishkesavan/Hackwell_AI/backend/venv/lib/python3.12/site-packages/starlette/routing.py", line 736, in app
    await route.handle(scope, receive, send)
  File "/Users/sathishkesavan/Hackwell_AI/backend/venv/lib/python3.12/site-packages/starlette/routing.py", line 290, in handle
    await self.app(scope, receive, send)
  File "/Users/sathishkesavan/Hackwell_AI/backend/venv/lib/python3.12/site-packages/starlette/routing.py", line 78, in app
    await wrap_app_handling_exceptions(app, request)(scope, receive, send)
  File "/Users/sathishkesavan/Hackwell_AI/backend/venv/lib/python3.12/site-packages/starlette/_exception_handler.py", line 53, in wrapped_app
    raise exc
  File "/Users/sathishkesavan/Hackwell_AI/backend/venv/lib/python3.12/site-packages/starlette/_exception_handler.py", line 42, in wrapped_app
    await app(scope, receive, sender)
  File "/Users/sathishkesavan/Hackwell_AI/backend/venv/lib/python3.12/site-packages/starlette/routing.py", line 75, in app
    response = await f(request)
               ^^^^^^^^^^^^^^^^
  File "/Users/sathishkesavan/Hackwell_AI/backend/venv/lib/python3.12/site-packages/fastapi/routing.py", line 328, in app
    content = await serialize_response(
              ^^^^^^^^^^^^^^^^^^^^^^^^^
  File "/Users/sathishkesavan/Hackwell_AI/backend/venv/lib/python3.12/site-packages/fastapi/routing.py", line 177, in serialize_response
    raise ResponseValidationError(
fastapi.exceptions.ResponseValidationError: 1 validation errors:
  {'type': 'string_type', 'loc': ('response', 3, 'date_of_birth'), 'msg': 'Input should be a valid string', 'input': None}

INFO:     127.0.0.1:57097 - "GET /api/analytics/overview HTTP/1.1" 200 OK
INFO:     127.0.0.1:57108 - "GET /api/patients/?skip=0&limit=4 HTTP/1.1" 500 Internal Server Error
ERROR:    Exception in ASGI application
Traceback (most recent call last):
  File "/Users/sathishkesavan/Hackwell_AI/backend/venv/lib/python3.12/site-packages/uvicorn/protocols/http/h11_impl.py", line 403, in run_asgi
    result = await app(  # type: ignore[func-returns-value]
             ^^^^^^^^^^^^^^^^^^^^^^^^^^^^^^^^^^^^^^^^^^^^^^
  File "/Users/sathishkesavan/Hackwell_AI/backend/venv/lib/python3.12/site-packages/uvicorn/middleware/proxy_headers.py", line 60, in __call__
    return await self.app(scope, receive, send)
           ^^^^^^^^^^^^^^^^^^^^^^^^^^^^^^^^^^^^
  File "/Users/sathishkesavan/Hackwell_AI/backend/venv/lib/python3.12/site-packages/fastapi/applications.py", line 1054, in __call__
    await super().__call__(scope, receive, send)
  File "/Users/sathishkesavan/Hackwell_AI/backend/venv/lib/python3.12/site-packages/starlette/applications.py", line 113, in __call__
    await self.middleware_stack(scope, receive, send)
  File "/Users/sathishkesavan/Hackwell_AI/backend/venv/lib/python3.12/site-packages/starlette/middleware/errors.py", line 186, in __call__
    raise exc
  File "/Users/sathishkesavan/Hackwell_AI/backend/venv/lib/python3.12/site-packages/starlette/middleware/errors.py", line 164, in __call__
    await self.app(scope, receive, _send)
  File "/Users/sathishkesavan/Hackwell_AI/backend/venv/lib/python3.12/site-packages/starlette/middleware/cors.py", line 93, in __call__
    await self.simple_response(scope, receive, send, request_headers=headers)
  File "/Users/sathishkesavan/Hackwell_AI/backend/venv/lib/python3.12/site-packages/starlette/middleware/cors.py", line 144, in simple_response
    await self.app(scope, receive, send)
  File "/Users/sathishkesavan/Hackwell_AI/backend/venv/lib/python3.12/site-packages/starlette/middleware/exceptions.py", line 63, in __call__
    await wrap_app_handling_exceptions(self.app, conn)(scope, receive, send)
  File "/Users/sathishkesavan/Hackwell_AI/backend/venv/lib/python3.12/site-packages/starlette/_exception_handler.py", line 53, in wrapped_app
    raise exc
  File "/Users/sathishkesavan/Hackwell_AI/backend/venv/lib/python3.12/site-packages/starlette/_exception_handler.py", line 42, in wrapped_app
    await app(scope, receive, sender)
  File "/Users/sathishkesavan/Hackwell_AI/backend/venv/lib/python3.12/site-packages/starlette/routing.py", line 716, in __call__
    await self.middleware_stack(scope, receive, send)
  File "/Users/sathishkesavan/Hackwell_AI/backend/venv/lib/python3.12/site-packages/starlette/routing.py", line 736, in app
    await route.handle(scope, receive, send)
  File "/Users/sathishkesavan/Hackwell_AI/backend/venv/lib/python3.12/site-packages/starlette/routing.py", line 290, in handle
    await self.app(scope, receive, send)
  File "/Users/sathishkesavan/Hackwell_AI/backend/venv/lib/python3.12/site-packages/starlette/routing.py", line 78, in app
    await wrap_app_handling_exceptions(app, request)(scope, receive, send)
  File "/Users/sathishkesavan/Hackwell_AI/backend/venv/lib/python3.12/site-packages/starlette/_exception_handler.py", line 53, in wrapped_app
    raise exc
  File "/Users/sathishkesavan/Hackwell_AI/backend/venv/lib/python3.12/site-packages/starlette/_exception_handler.py", line 42, in wrapped_app
    await app(scope, receive, sender)
  File "/Users/sathishkesavan/Hackwell_AI/backend/venv/lib/python3.12/site-packages/starlette/routing.py", line 75, in app
    response = await f(request)
               ^^^^^^^^^^^^^^^^
  File "/Users/sathishkesavan/Hackwell_AI/backend/venv/lib/python3.12/site-packages/fastapi/routing.py", line 328, in app
    content = await serialize_response(
              ^^^^^^^^^^^^^^^^^^^^^^^^^
  File "/Users/sathishkesavan/Hackwell_AI/backend/venv/lib/python3.12/site-packages/fastapi/routing.py", line 177, in serialize_response
    raise ResponseValidationError(
fastapi.exceptions.ResponseValidationError: 1 validation errors:
  {'type': 'string_type', 'loc': ('response', 3, 'date_of_birth'), 'msg': 'Input should be a valid string', 'input': None}

